[2022-08-19 18:04:19,445] {taskinstance.py:1179} INFO - Dependencies all met for <TaskInstance: Satellite_Data.stream_generator manual__2022-08-19T02:40:48.850961+00:00 [queued]>
[2022-08-19 18:04:19,456] {taskinstance.py:1179} INFO - Dependencies all met for <TaskInstance: Satellite_Data.stream_generator manual__2022-08-19T02:40:48.850961+00:00 [queued]>
[2022-08-19 18:04:19,456] {taskinstance.py:1376} INFO - 
--------------------------------------------------------------------------------
[2022-08-19 18:04:19,456] {taskinstance.py:1377} INFO - Starting attempt 2 of 2
[2022-08-19 18:04:19,456] {taskinstance.py:1378} INFO - 
--------------------------------------------------------------------------------
[2022-08-19 18:04:19,866] {taskinstance.py:1397} INFO - Executing <Task(BashOperator): stream_generator> on 2022-08-19 02:40:48.850961+00:00
[2022-08-19 18:04:19,873] {standard_task_runner.py:52} INFO - Started process 108 to run task
[2022-08-19 18:04:19,875] {standard_task_runner.py:79} INFO - Running: ['***', 'tasks', 'run', 'Satellite_Data', 'stream_generator', 'manual__2022-08-19T02:40:48.850961+00:00', '--job-id', '119', '--raw', '--subdir', 'DAGS_FOLDER/data_loader.py', '--cfg-path', '/tmp/tmpab17scma', '--error-file', '/tmp/tmpp0yreaaz']
[2022-08-19 18:04:19,875] {standard_task_runner.py:80} INFO - Job 119: Subtask stream_generator
[2022-08-19 18:04:20,111] {task_command.py:371} INFO - Running <TaskInstance: Satellite_Data.stream_generator manual__2022-08-19T02:40:48.850961+00:00 [running]> on host 3a5c2d0be6af
[2022-08-19 18:04:20,520] {taskinstance.py:1591} INFO - Exporting the following env vars:
AIRFLOW_CTX_DAG_OWNER=***
AIRFLOW_CTX_DAG_ID=Satellite_Data
AIRFLOW_CTX_TASK_ID=stream_generator
AIRFLOW_CTX_EXECUTION_DATE=2022-08-19T02:40:48.850961+00:00
AIRFLOW_CTX_TRY_NUMBER=2
AIRFLOW_CTX_DAG_RUN_ID=manual__2022-08-19T02:40:48.850961+00:00
[2022-08-19 18:04:20,521] {subprocess.py:62} INFO - Tmp dir root location: 
 /tmp
[2022-08-19 18:04:20,522] {subprocess.py:74} INFO - Running command: ['bash', '-c', 'python3 /home/L/Programming/dataEng/spaceApp/Streaming/streamGenerator.py']
[2022-08-19 18:04:20,540] {subprocess.py:85} INFO - Output:
[2022-08-19 18:04:20,926] {subprocess.py:92} INFO - python3: can't open file '/home/L/Programming/dataEng/spaceApp/Streaming/streamGenerator.py': [Errno 2] No such file or directory
[2022-08-19 18:04:20,929] {subprocess.py:96} INFO - Command exited with return code 2
[2022-08-19 18:04:20,947] {taskinstance.py:1909} ERROR - Task failed with exception
Traceback (most recent call last):
  File "/home/airflow/.local/lib/python3.7/site-packages/airflow/operators/bash.py", line 195, in execute
    f'Bash command failed. The command returned a non-zero exit code {result.exit_code}.'
airflow.exceptions.AirflowException: Bash command failed. The command returned a non-zero exit code 2.
[2022-08-19 18:04:20,951] {taskinstance.py:1420} INFO - Marking task as FAILED. dag_id=Satellite_Data, task_id=stream_generator, execution_date=20220819T024048, start_date=20220819T180419, end_date=20220819T180420
[2022-08-19 18:04:21,048] {standard_task_runner.py:97} ERROR - Failed to execute job 119 for task stream_generator (Bash command failed. The command returned a non-zero exit code 2.; 108)
[2022-08-19 18:04:21,090] {local_task_job.py:156} INFO - Task exited with return code 1
[2022-08-19 18:04:21,151] {local_task_job.py:273} INFO - 0 downstream tasks scheduled from follow-on schedule check
