[2022-08-19 18:04:19,252] {taskinstance.py:1179} INFO - Dependencies all met for <TaskInstance: Satellite_Data.stream_generator manual__2022-08-19T02:44:40.366905+00:00 [queued]>
[2022-08-19 18:04:19,262] {taskinstance.py:1179} INFO - Dependencies all met for <TaskInstance: Satellite_Data.stream_generator manual__2022-08-19T02:44:40.366905+00:00 [queued]>
[2022-08-19 18:04:19,262] {taskinstance.py:1376} INFO - 
--------------------------------------------------------------------------------
[2022-08-19 18:04:19,262] {taskinstance.py:1377} INFO - Starting attempt 2 of 2
[2022-08-19 18:04:19,262] {taskinstance.py:1378} INFO - 
--------------------------------------------------------------------------------
[2022-08-19 18:04:19,594] {taskinstance.py:1397} INFO - Executing <Task(BashOperator): stream_generator> on 2022-08-19 02:44:40.366905+00:00
[2022-08-19 18:04:19,743] {standard_task_runner.py:52} INFO - Started process 107 to run task
[2022-08-19 18:04:19,749] {standard_task_runner.py:79} INFO - Running: ['***', 'tasks', 'run', 'Satellite_Data', 'stream_generator', 'manual__2022-08-19T02:44:40.366905+00:00', '--job-id', '118', '--raw', '--subdir', 'DAGS_FOLDER/data_loader.py', '--cfg-path', '/tmp/tmpa054yxmb', '--error-file', '/tmp/tmppy4wxknv']
[2022-08-19 18:04:19,750] {standard_task_runner.py:80} INFO - Job 118: Subtask stream_generator
[2022-08-19 18:04:20,054] {task_command.py:371} INFO - Running <TaskInstance: Satellite_Data.stream_generator manual__2022-08-19T02:44:40.366905+00:00 [running]> on host 3a5c2d0be6af
[2022-08-19 18:04:20,340] {taskinstance.py:1591} INFO - Exporting the following env vars:
AIRFLOW_CTX_DAG_OWNER=***
AIRFLOW_CTX_DAG_ID=Satellite_Data
AIRFLOW_CTX_TASK_ID=stream_generator
AIRFLOW_CTX_EXECUTION_DATE=2022-08-19T02:44:40.366905+00:00
AIRFLOW_CTX_TRY_NUMBER=2
AIRFLOW_CTX_DAG_RUN_ID=manual__2022-08-19T02:44:40.366905+00:00
[2022-08-19 18:04:20,399] {subprocess.py:62} INFO - Tmp dir root location: 
 /tmp
[2022-08-19 18:04:20,400] {subprocess.py:74} INFO - Running command: ['bash', '-c', 'python3 /home/L/Programming/dataEng/spaceApp/Streaming/streamGenerator.py']
[2022-08-19 18:04:20,460] {subprocess.py:85} INFO - Output:
[2022-08-19 18:04:20,936] {subprocess.py:92} INFO - python3: can't open file '/home/L/Programming/dataEng/spaceApp/Streaming/streamGenerator.py': [Errno 2] No such file or directory
[2022-08-19 18:04:20,938] {subprocess.py:96} INFO - Command exited with return code 2
[2022-08-19 18:04:20,958] {taskinstance.py:1909} ERROR - Task failed with exception
Traceback (most recent call last):
  File "/home/airflow/.local/lib/python3.7/site-packages/airflow/operators/bash.py", line 195, in execute
    f'Bash command failed. The command returned a non-zero exit code {result.exit_code}.'
airflow.exceptions.AirflowException: Bash command failed. The command returned a non-zero exit code 2.
[2022-08-19 18:04:20,962] {taskinstance.py:1420} INFO - Marking task as FAILED. dag_id=Satellite_Data, task_id=stream_generator, execution_date=20220819T024440, start_date=20220819T180419, end_date=20220819T180420
[2022-08-19 18:04:21,061] {standard_task_runner.py:97} ERROR - Failed to execute job 118 for task stream_generator (Bash command failed. The command returned a non-zero exit code 2.; 107)
[2022-08-19 18:04:21,081] {local_task_job.py:156} INFO - Task exited with return code 1
[2022-08-19 18:04:21,143] {local_task_job.py:273} INFO - 0 downstream tasks scheduled from follow-on schedule check
