[2022-08-18 16:32:34,751] {taskinstance.py:1179} INFO - Dependencies all met for <TaskInstance: Satellite_Data.load_into_json scheduled__2022-08-17T16:32:25.188706+00:00 [queued]>
[2022-08-18 16:32:34,769] {taskinstance.py:1179} INFO - Dependencies all met for <TaskInstance: Satellite_Data.load_into_json scheduled__2022-08-17T16:32:25.188706+00:00 [queued]>
[2022-08-18 16:32:34,769] {taskinstance.py:1376} INFO - 
--------------------------------------------------------------------------------
[2022-08-18 16:32:34,769] {taskinstance.py:1377} INFO - Starting attempt 1 of 2
[2022-08-18 16:32:34,769] {taskinstance.py:1378} INFO - 
--------------------------------------------------------------------------------
[2022-08-18 16:32:34,806] {taskinstance.py:1397} INFO - Executing <Task(BashOperator): load_into_json> on 2022-08-17 16:32:25.188706+00:00
[2022-08-18 16:32:34,814] {standard_task_runner.py:52} INFO - Started process 1243 to run task
[2022-08-18 16:32:34,817] {standard_task_runner.py:79} INFO - Running: ['***', 'tasks', 'run', 'Satellite_Data', 'load_into_json', 'scheduled__2022-08-17T16:32:25.188706+00:00', '--job-id', '67', '--raw', '--subdir', 'DAGS_FOLDER/data_loader.py', '--cfg-path', '/tmp/tmpack1lk1b', '--error-file', '/tmp/tmphq70zgja']
[2022-08-18 16:32:34,818] {standard_task_runner.py:80} INFO - Job 67: Subtask load_into_json
[2022-08-18 16:32:34,936] {task_command.py:371} INFO - Running <TaskInstance: Satellite_Data.load_into_json scheduled__2022-08-17T16:32:25.188706+00:00 [running]> on host b4db7d4790c9
[2022-08-18 16:32:35,333] {taskinstance.py:1591} INFO - Exporting the following env vars:
AIRFLOW_CTX_DAG_OWNER=***
AIRFLOW_CTX_DAG_ID=Satellite_Data
AIRFLOW_CTX_TASK_ID=load_into_json
AIRFLOW_CTX_EXECUTION_DATE=2022-08-17T16:32:25.188706+00:00
AIRFLOW_CTX_TRY_NUMBER=1
AIRFLOW_CTX_DAG_RUN_ID=scheduled__2022-08-17T16:32:25.188706+00:00
[2022-08-18 16:32:35,334] {subprocess.py:62} INFO - Tmp dir root location: 
 /tmp
[2022-08-18 16:32:35,335] {subprocess.py:74} INFO - Running command: ['bash', '-c', 'python3 /opt/***/dags/satelliteTrack.py']
[2022-08-18 16:32:35,356] {subprocess.py:85} INFO - Output:
[2022-08-18 16:32:37,680] {subprocess.py:92} INFO - <Response [500]>
[2022-08-18 16:32:37,681] {subprocess.py:92} INFO - Traceback (most recent call last):
[2022-08-18 16:32:37,681] {subprocess.py:92} INFO -   File "/opt/***/dags/satelliteTrack.py", line 108, in <module>
[2022-08-18 16:32:37,681] {subprocess.py:92} INFO -     load_satellite_data()
[2022-08-18 16:32:37,681] {subprocess.py:92} INFO -   File "/opt/***/dags/satelliteTrack.py", line 88, in load_satellite_data
[2022-08-18 16:32:37,681] {subprocess.py:92} INFO -     data = api_call()
[2022-08-18 16:32:37,681] {subprocess.py:92} INFO -   File "/opt/***/dags/satelliteTrack.py", line 70, in api_call
[2022-08-18 16:32:37,682] {subprocess.py:92} INFO -     raise MyError(resp, "GET fail on request for Starlink satellites")
[2022-08-18 16:32:37,682] {subprocess.py:92} INFO - __main__.MyError: (<Response [500]>, 'GET fail on request for Starlink satellites')
[2022-08-18 16:32:38,051] {subprocess.py:96} INFO - Command exited with return code 1
[2022-08-18 16:32:38,409] {taskinstance.py:1909} ERROR - Task failed with exception
Traceback (most recent call last):
  File "/home/airflow/.local/lib/python3.7/site-packages/airflow/operators/bash.py", line 195, in execute
    f'Bash command failed. The command returned a non-zero exit code {result.exit_code}.'
airflow.exceptions.AirflowException: Bash command failed. The command returned a non-zero exit code 1.
[2022-08-18 16:32:38,429] {taskinstance.py:1420} INFO - Marking task as UP_FOR_RETRY. dag_id=Satellite_Data, task_id=load_into_json, execution_date=20220817T163225, start_date=20220818T163234, end_date=20220818T163238
[2022-08-18 16:32:38,482] {standard_task_runner.py:97} ERROR - Failed to execute job 67 for task load_into_json (Bash command failed. The command returned a non-zero exit code 1.; 1243)
[2022-08-18 16:32:38,520] {local_task_job.py:156} INFO - Task exited with return code 1
[2022-08-18 16:32:38,643] {local_task_job.py:273} INFO - 0 downstream tasks scheduled from follow-on schedule check
