[2022-08-18 16:42:53,027] {taskinstance.py:1179} INFO - Dependencies all met for <TaskInstance: Satellite_Data.load_data scheduled__2022-08-17T16:32:19.045525+00:00 [queued]>
[2022-08-18 16:42:53,036] {taskinstance.py:1179} INFO - Dependencies all met for <TaskInstance: Satellite_Data.load_data scheduled__2022-08-17T16:32:19.045525+00:00 [queued]>
[2022-08-18 16:42:53,036] {taskinstance.py:1376} INFO - 
--------------------------------------------------------------------------------
[2022-08-18 16:42:53,036] {taskinstance.py:1377} INFO - Starting attempt 2 of 2
[2022-08-18 16:42:53,037] {taskinstance.py:1378} INFO - 
--------------------------------------------------------------------------------
[2022-08-18 16:42:53,172] {taskinstance.py:1397} INFO - Executing <Task(PythonOperator): load_data> on 2022-08-17 16:32:19.045525+00:00
[2022-08-18 16:42:53,184] {standard_task_runner.py:52} INFO - Started process 1795 to run task
[2022-08-18 16:42:53,187] {standard_task_runner.py:79} INFO - Running: ['***', 'tasks', 'run', 'Satellite_Data', 'load_data', 'scheduled__2022-08-17T16:32:19.045525+00:00', '--job-id', '75', '--raw', '--subdir', 'DAGS_FOLDER/data_loader.py', '--cfg-path', '/tmp/tmprblhp8vj', '--error-file', '/tmp/tmpqzp97fml']
[2022-08-18 16:42:53,187] {standard_task_runner.py:80} INFO - Job 75: Subtask load_data
[2022-08-18 16:42:53,356] {task_command.py:371} INFO - Running <TaskInstance: Satellite_Data.load_data scheduled__2022-08-17T16:32:19.045525+00:00 [running]> on host b4db7d4790c9
[2022-08-18 16:42:53,530] {taskinstance.py:1591} INFO - Exporting the following env vars:
AIRFLOW_CTX_DAG_OWNER=***
AIRFLOW_CTX_DAG_ID=Satellite_Data
AIRFLOW_CTX_TASK_ID=load_data
AIRFLOW_CTX_EXECUTION_DATE=2022-08-17T16:32:19.045525+00:00
AIRFLOW_CTX_TRY_NUMBER=2
AIRFLOW_CTX_DAG_RUN_ID=scheduled__2022-08-17T16:32:19.045525+00:00
[2022-08-18 16:42:53,531] {taskinstance.py:1909} ERROR - Task failed with exception
Traceback (most recent call last):
  File "/home/airflow/.local/lib/python3.7/site-packages/airflow/operators/python.py", line 171, in execute
    return_value = self.execute_callable()
  File "/home/airflow/.local/lib/python3.7/site-packages/airflow/operators/python.py", line 189, in execute_callable
    return self.python_callable(*self.op_args, **self.op_kwargs)
TypeError: load_into_database() missing 1 required positional argument: 'data'
[2022-08-18 16:42:53,628] {taskinstance.py:1420} INFO - Marking task as FAILED. dag_id=Satellite_Data, task_id=load_data, execution_date=20220817T163219, start_date=20220818T164253, end_date=20220818T164253
[2022-08-18 16:42:53,740] {standard_task_runner.py:97} ERROR - Failed to execute job 75 for task load_data (load_into_database() missing 1 required positional argument: 'data'; 1795)
[2022-08-18 16:42:53,759] {local_task_job.py:156} INFO - Task exited with return code 1
[2022-08-18 16:42:53,897] {local_task_job.py:273} INFO - 0 downstream tasks scheduled from follow-on schedule check
