[2022-08-18 16:20:45,164] {processor.py:153} INFO - Started process (PID=55) to work on /opt/airflow/dags/dbConnector.py
[2022-08-18 16:20:45,165] {processor.py:641} INFO - Processing file /opt/airflow/dags/dbConnector.py for tasks to queue
[2022-08-18 16:20:45,165] {logging_mixin.py:115} INFO - [2022-08-18 16:20:45,165] {dagbag.py:508} INFO - Filling up the DagBag from /opt/airflow/dags/dbConnector.py
[2022-08-18 16:20:45,414] {processor.py:653} WARNING - No viable dags retrieved from /opt/airflow/dags/dbConnector.py
[2022-08-18 16:20:45,428] {processor.py:161} INFO - Processing /opt/airflow/dags/dbConnector.py took 0.268 seconds
[2022-08-18 16:21:15,516] {processor.py:153} INFO - Started process (PID=86) to work on /opt/airflow/dags/dbConnector.py
[2022-08-18 16:21:15,516] {processor.py:641} INFO - Processing file /opt/airflow/dags/dbConnector.py for tasks to queue
[2022-08-18 16:21:15,517] {logging_mixin.py:115} INFO - [2022-08-18 16:21:15,517] {dagbag.py:508} INFO - Filling up the DagBag from /opt/airflow/dags/dbConnector.py
[2022-08-18 16:21:15,756] {processor.py:653} WARNING - No viable dags retrieved from /opt/airflow/dags/dbConnector.py
[2022-08-18 16:21:15,768] {processor.py:161} INFO - Processing /opt/airflow/dags/dbConnector.py took 0.258 seconds
[2022-08-18 16:21:47,049] {processor.py:153} INFO - Started process (PID=114) to work on /opt/airflow/dags/dbConnector.py
[2022-08-18 16:21:47,117] {processor.py:641} INFO - Processing file /opt/airflow/dags/dbConnector.py for tasks to queue
[2022-08-18 16:21:47,242] {logging_mixin.py:115} INFO - [2022-08-18 16:21:47,242] {dagbag.py:508} INFO - Filling up the DagBag from /opt/airflow/dags/dbConnector.py
[2022-08-18 16:21:56,970] {processor.py:653} WARNING - No viable dags retrieved from /opt/airflow/dags/dbConnector.py
[2022-08-18 16:21:57,421] {processor.py:161} INFO - Processing /opt/airflow/dags/dbConnector.py took 10.375 seconds
[2022-08-18 16:22:27,663] {processor.py:153} INFO - Started process (PID=148) to work on /opt/airflow/dags/dbConnector.py
[2022-08-18 16:22:27,691] {processor.py:641} INFO - Processing file /opt/airflow/dags/dbConnector.py for tasks to queue
[2022-08-18 16:22:27,692] {logging_mixin.py:115} INFO - [2022-08-18 16:22:27,692] {dagbag.py:508} INFO - Filling up the DagBag from /opt/airflow/dags/dbConnector.py
[2022-08-18 16:22:27,906] {processor.py:653} WARNING - No viable dags retrieved from /opt/airflow/dags/dbConnector.py
[2022-08-18 16:22:27,918] {processor.py:161} INFO - Processing /opt/airflow/dags/dbConnector.py took 0.260 seconds
[2022-08-18 16:22:58,239] {processor.py:153} INFO - Started process (PID=171) to work on /opt/airflow/dags/dbConnector.py
[2022-08-18 16:22:58,249] {processor.py:641} INFO - Processing file /opt/airflow/dags/dbConnector.py for tasks to queue
[2022-08-18 16:22:58,249] {logging_mixin.py:115} INFO - [2022-08-18 16:22:58,249] {dagbag.py:508} INFO - Filling up the DagBag from /opt/airflow/dags/dbConnector.py
[2022-08-18 16:22:58,450] {processor.py:653} WARNING - No viable dags retrieved from /opt/airflow/dags/dbConnector.py
[2022-08-18 16:22:58,468] {processor.py:161} INFO - Processing /opt/airflow/dags/dbConnector.py took 0.234 seconds
[2022-08-18 16:23:29,343] {processor.py:153} INFO - Started process (PID=205) to work on /opt/airflow/dags/dbConnector.py
[2022-08-18 16:23:29,365] {processor.py:641} INFO - Processing file /opt/airflow/dags/dbConnector.py for tasks to queue
[2022-08-18 16:23:29,366] {logging_mixin.py:115} INFO - [2022-08-18 16:23:29,365] {dagbag.py:508} INFO - Filling up the DagBag from /opt/airflow/dags/dbConnector.py
[2022-08-18 16:23:29,572] {processor.py:653} WARNING - No viable dags retrieved from /opt/airflow/dags/dbConnector.py
[2022-08-18 16:23:29,588] {processor.py:161} INFO - Processing /opt/airflow/dags/dbConnector.py took 0.250 seconds
[2022-08-18 16:23:59,670] {processor.py:153} INFO - Started process (PID=239) to work on /opt/airflow/dags/dbConnector.py
[2022-08-18 16:23:59,681] {processor.py:641} INFO - Processing file /opt/airflow/dags/dbConnector.py for tasks to queue
[2022-08-18 16:23:59,682] {logging_mixin.py:115} INFO - [2022-08-18 16:23:59,682] {dagbag.py:508} INFO - Filling up the DagBag from /opt/airflow/dags/dbConnector.py
[2022-08-18 16:23:59,981] {processor.py:653} WARNING - No viable dags retrieved from /opt/airflow/dags/dbConnector.py
[2022-08-18 16:23:59,993] {processor.py:161} INFO - Processing /opt/airflow/dags/dbConnector.py took 0.325 seconds
[2022-08-18 16:24:30,076] {processor.py:153} INFO - Started process (PID=263) to work on /opt/airflow/dags/dbConnector.py
[2022-08-18 16:24:30,097] {processor.py:641} INFO - Processing file /opt/airflow/dags/dbConnector.py for tasks to queue
[2022-08-18 16:24:30,098] {logging_mixin.py:115} INFO - [2022-08-18 16:24:30,098] {dagbag.py:508} INFO - Filling up the DagBag from /opt/airflow/dags/dbConnector.py
[2022-08-18 16:24:30,346] {processor.py:653} WARNING - No viable dags retrieved from /opt/airflow/dags/dbConnector.py
[2022-08-18 16:24:30,363] {processor.py:161} INFO - Processing /opt/airflow/dags/dbConnector.py took 0.291 seconds
[2022-08-18 16:25:00,439] {processor.py:153} INFO - Started process (PID=294) to work on /opt/airflow/dags/dbConnector.py
[2022-08-18 16:25:00,439] {processor.py:641} INFO - Processing file /opt/airflow/dags/dbConnector.py for tasks to queue
[2022-08-18 16:25:00,440] {logging_mixin.py:115} INFO - [2022-08-18 16:25:00,440] {dagbag.py:508} INFO - Filling up the DagBag from /opt/airflow/dags/dbConnector.py
[2022-08-18 16:25:00,643] {processor.py:653} WARNING - No viable dags retrieved from /opt/airflow/dags/dbConnector.py
[2022-08-18 16:25:00,658] {processor.py:161} INFO - Processing /opt/airflow/dags/dbConnector.py took 0.224 seconds
[2022-08-18 16:25:31,053] {processor.py:153} INFO - Started process (PID=324) to work on /opt/airflow/dags/dbConnector.py
[2022-08-18 16:25:31,062] {processor.py:641} INFO - Processing file /opt/airflow/dags/dbConnector.py for tasks to queue
[2022-08-18 16:25:31,062] {logging_mixin.py:115} INFO - [2022-08-18 16:25:31,062] {dagbag.py:508} INFO - Filling up the DagBag from /opt/airflow/dags/dbConnector.py
[2022-08-18 16:25:31,273] {processor.py:653} WARNING - No viable dags retrieved from /opt/airflow/dags/dbConnector.py
[2022-08-18 16:25:31,285] {processor.py:161} INFO - Processing /opt/airflow/dags/dbConnector.py took 0.237 seconds
[2022-08-18 16:26:02,046] {processor.py:153} INFO - Started process (PID=351) to work on /opt/airflow/dags/dbConnector.py
[2022-08-18 16:26:02,053] {processor.py:641} INFO - Processing file /opt/airflow/dags/dbConnector.py for tasks to queue
[2022-08-18 16:26:02,054] {logging_mixin.py:115} INFO - [2022-08-18 16:26:02,054] {dagbag.py:508} INFO - Filling up the DagBag from /opt/airflow/dags/dbConnector.py
[2022-08-18 16:26:02,284] {processor.py:653} WARNING - No viable dags retrieved from /opt/airflow/dags/dbConnector.py
[2022-08-18 16:26:02,300] {processor.py:161} INFO - Processing /opt/airflow/dags/dbConnector.py took 0.259 seconds
[2022-08-18 16:26:32,385] {processor.py:153} INFO - Started process (PID=384) to work on /opt/airflow/dags/dbConnector.py
[2022-08-18 16:26:32,394] {processor.py:641} INFO - Processing file /opt/airflow/dags/dbConnector.py for tasks to queue
[2022-08-18 16:26:32,395] {logging_mixin.py:115} INFO - [2022-08-18 16:26:32,395] {dagbag.py:508} INFO - Filling up the DagBag from /opt/airflow/dags/dbConnector.py
[2022-08-18 16:26:32,623] {processor.py:653} WARNING - No viable dags retrieved from /opt/airflow/dags/dbConnector.py
[2022-08-18 16:26:32,640] {processor.py:161} INFO - Processing /opt/airflow/dags/dbConnector.py took 0.259 seconds
[2022-08-18 16:27:02,667] {processor.py:153} INFO - Started process (PID=426) to work on /opt/airflow/dags/dbConnector.py
[2022-08-18 16:27:02,677] {processor.py:641} INFO - Processing file /opt/airflow/dags/dbConnector.py for tasks to queue
[2022-08-18 16:27:02,678] {logging_mixin.py:115} INFO - [2022-08-18 16:27:02,678] {dagbag.py:508} INFO - Filling up the DagBag from /opt/airflow/dags/dbConnector.py
[2022-08-18 16:27:03,038] {processor.py:653} WARNING - No viable dags retrieved from /opt/airflow/dags/dbConnector.py
[2022-08-18 16:27:03,055] {processor.py:161} INFO - Processing /opt/airflow/dags/dbConnector.py took 0.392 seconds
[2022-08-18 16:27:33,168] {processor.py:153} INFO - Started process (PID=484) to work on /opt/airflow/dags/dbConnector.py
[2022-08-18 16:27:33,243] {processor.py:641} INFO - Processing file /opt/airflow/dags/dbConnector.py for tasks to queue
[2022-08-18 16:27:33,243] {logging_mixin.py:115} INFO - [2022-08-18 16:27:33,243] {dagbag.py:508} INFO - Filling up the DagBag from /opt/airflow/dags/dbConnector.py
[2022-08-18 16:27:33,526] {processor.py:653} WARNING - No viable dags retrieved from /opt/airflow/dags/dbConnector.py
[2022-08-18 16:27:33,539] {processor.py:161} INFO - Processing /opt/airflow/dags/dbConnector.py took 0.373 seconds
[2022-08-18 16:28:03,622] {processor.py:153} INFO - Started process (PID=520) to work on /opt/airflow/dags/dbConnector.py
[2022-08-18 16:28:03,634] {processor.py:641} INFO - Processing file /opt/airflow/dags/dbConnector.py for tasks to queue
[2022-08-18 16:28:03,635] {logging_mixin.py:115} INFO - [2022-08-18 16:28:03,635] {dagbag.py:508} INFO - Filling up the DagBag from /opt/airflow/dags/dbConnector.py
[2022-08-18 16:28:03,844] {processor.py:653} WARNING - No viable dags retrieved from /opt/airflow/dags/dbConnector.py
[2022-08-18 16:28:03,861] {processor.py:161} INFO - Processing /opt/airflow/dags/dbConnector.py took 0.243 seconds
[2022-08-18 16:28:33,952] {processor.py:153} INFO - Started process (PID=552) to work on /opt/airflow/dags/dbConnector.py
[2022-08-18 16:28:33,975] {processor.py:641} INFO - Processing file /opt/airflow/dags/dbConnector.py for tasks to queue
[2022-08-18 16:28:33,976] {logging_mixin.py:115} INFO - [2022-08-18 16:28:33,976] {dagbag.py:508} INFO - Filling up the DagBag from /opt/airflow/dags/dbConnector.py
[2022-08-18 16:28:34,216] {processor.py:653} WARNING - No viable dags retrieved from /opt/airflow/dags/dbConnector.py
[2022-08-18 16:28:34,233] {processor.py:161} INFO - Processing /opt/airflow/dags/dbConnector.py took 0.283 seconds
[2022-08-18 16:29:04,274] {processor.py:153} INFO - Started process (PID=589) to work on /opt/airflow/dags/dbConnector.py
[2022-08-18 16:29:04,283] {processor.py:641} INFO - Processing file /opt/airflow/dags/dbConnector.py for tasks to queue
[2022-08-18 16:29:04,284] {logging_mixin.py:115} INFO - [2022-08-18 16:29:04,284] {dagbag.py:508} INFO - Filling up the DagBag from /opt/airflow/dags/dbConnector.py
[2022-08-18 16:29:04,535] {processor.py:653} WARNING - No viable dags retrieved from /opt/airflow/dags/dbConnector.py
[2022-08-18 16:29:04,553] {processor.py:161} INFO - Processing /opt/airflow/dags/dbConnector.py took 0.283 seconds
[2022-08-18 16:29:35,435] {processor.py:153} INFO - Started process (PID=613) to work on /opt/airflow/dags/dbConnector.py
[2022-08-18 16:29:35,441] {processor.py:641} INFO - Processing file /opt/airflow/dags/dbConnector.py for tasks to queue
[2022-08-18 16:29:35,441] {logging_mixin.py:115} INFO - [2022-08-18 16:29:35,441] {dagbag.py:508} INFO - Filling up the DagBag from /opt/airflow/dags/dbConnector.py
[2022-08-18 16:29:35,660] {processor.py:653} WARNING - No viable dags retrieved from /opt/airflow/dags/dbConnector.py
[2022-08-18 16:29:35,674] {processor.py:161} INFO - Processing /opt/airflow/dags/dbConnector.py took 0.245 seconds
[2022-08-18 16:30:05,783] {processor.py:153} INFO - Started process (PID=645) to work on /opt/airflow/dags/dbConnector.py
[2022-08-18 16:30:05,790] {processor.py:641} INFO - Processing file /opt/airflow/dags/dbConnector.py for tasks to queue
[2022-08-18 16:30:05,790] {logging_mixin.py:115} INFO - [2022-08-18 16:30:05,790] {dagbag.py:508} INFO - Filling up the DagBag from /opt/airflow/dags/dbConnector.py
[2022-08-18 16:30:06,017] {processor.py:653} WARNING - No viable dags retrieved from /opt/airflow/dags/dbConnector.py
[2022-08-18 16:30:06,029] {processor.py:161} INFO - Processing /opt/airflow/dags/dbConnector.py took 0.250 seconds
[2022-08-18 16:30:36,166] {processor.py:153} INFO - Started process (PID=676) to work on /opt/airflow/dags/dbConnector.py
[2022-08-18 16:30:36,181] {processor.py:641} INFO - Processing file /opt/airflow/dags/dbConnector.py for tasks to queue
[2022-08-18 16:30:36,182] {logging_mixin.py:115} INFO - [2022-08-18 16:30:36,182] {dagbag.py:508} INFO - Filling up the DagBag from /opt/airflow/dags/dbConnector.py
[2022-08-18 16:30:36,395] {processor.py:653} WARNING - No viable dags retrieved from /opt/airflow/dags/dbConnector.py
[2022-08-18 16:30:36,411] {processor.py:161} INFO - Processing /opt/airflow/dags/dbConnector.py took 0.250 seconds
[2022-08-18 16:31:06,482] {processor.py:153} INFO - Started process (PID=702) to work on /opt/airflow/dags/dbConnector.py
[2022-08-18 16:31:06,483] {processor.py:641} INFO - Processing file /opt/airflow/dags/dbConnector.py for tasks to queue
[2022-08-18 16:31:06,483] {logging_mixin.py:115} INFO - [2022-08-18 16:31:06,483] {dagbag.py:508} INFO - Filling up the DagBag from /opt/airflow/dags/dbConnector.py
[2022-08-18 16:31:06,709] {processor.py:653} WARNING - No viable dags retrieved from /opt/airflow/dags/dbConnector.py
[2022-08-18 16:31:06,721] {processor.py:161} INFO - Processing /opt/airflow/dags/dbConnector.py took 0.243 seconds
[2022-08-18 16:31:36,814] {processor.py:153} INFO - Started process (PID=733) to work on /opt/airflow/dags/dbConnector.py
[2022-08-18 16:31:36,822] {processor.py:641} INFO - Processing file /opt/airflow/dags/dbConnector.py for tasks to queue
[2022-08-18 16:31:36,822] {logging_mixin.py:115} INFO - [2022-08-18 16:31:36,822] {dagbag.py:508} INFO - Filling up the DagBag from /opt/airflow/dags/dbConnector.py
[2022-08-18 16:31:37,053] {processor.py:653} WARNING - No viable dags retrieved from /opt/airflow/dags/dbConnector.py
[2022-08-18 16:31:37,070] {processor.py:161} INFO - Processing /opt/airflow/dags/dbConnector.py took 0.261 seconds
[2022-08-18 16:32:07,297] {processor.py:153} INFO - Started process (PID=757) to work on /opt/airflow/dags/dbConnector.py
[2022-08-18 16:32:07,363] {processor.py:641} INFO - Processing file /opt/airflow/dags/dbConnector.py for tasks to queue
[2022-08-18 16:32:07,364] {logging_mixin.py:115} INFO - [2022-08-18 16:32:07,364] {dagbag.py:508} INFO - Filling up the DagBag from /opt/airflow/dags/dbConnector.py
[2022-08-18 16:32:07,589] {processor.py:653} WARNING - No viable dags retrieved from /opt/airflow/dags/dbConnector.py
[2022-08-18 16:32:07,605] {processor.py:161} INFO - Processing /opt/airflow/dags/dbConnector.py took 0.312 seconds
[2022-08-18 16:32:37,685] {processor.py:153} INFO - Started process (PID=835) to work on /opt/airflow/dags/dbConnector.py
[2022-08-18 16:32:37,762] {processor.py:641} INFO - Processing file /opt/airflow/dags/dbConnector.py for tasks to queue
[2022-08-18 16:32:37,763] {logging_mixin.py:115} INFO - [2022-08-18 16:32:37,763] {dagbag.py:508} INFO - Filling up the DagBag from /opt/airflow/dags/dbConnector.py
[2022-08-18 16:32:38,238] {processor.py:653} WARNING - No viable dags retrieved from /opt/airflow/dags/dbConnector.py
[2022-08-18 16:32:38,261] {processor.py:161} INFO - Processing /opt/airflow/dags/dbConnector.py took 0.582 seconds
[2022-08-18 16:33:08,315] {processor.py:153} INFO - Started process (PID=871) to work on /opt/airflow/dags/dbConnector.py
[2022-08-18 16:33:08,320] {processor.py:641} INFO - Processing file /opt/airflow/dags/dbConnector.py for tasks to queue
[2022-08-18 16:33:08,320] {logging_mixin.py:115} INFO - [2022-08-18 16:33:08,320] {dagbag.py:508} INFO - Filling up the DagBag from /opt/airflow/dags/dbConnector.py
[2022-08-18 16:33:08,540] {processor.py:653} WARNING - No viable dags retrieved from /opt/airflow/dags/dbConnector.py
[2022-08-18 16:33:08,557] {processor.py:161} INFO - Processing /opt/airflow/dags/dbConnector.py took 0.247 seconds
[2022-08-18 16:33:38,643] {processor.py:153} INFO - Started process (PID=895) to work on /opt/airflow/dags/dbConnector.py
[2022-08-18 16:33:38,653] {processor.py:641} INFO - Processing file /opt/airflow/dags/dbConnector.py for tasks to queue
[2022-08-18 16:33:38,653] {logging_mixin.py:115} INFO - [2022-08-18 16:33:38,653] {dagbag.py:508} INFO - Filling up the DagBag from /opt/airflow/dags/dbConnector.py
[2022-08-18 16:33:38,903] {processor.py:653} WARNING - No viable dags retrieved from /opt/airflow/dags/dbConnector.py
[2022-08-18 16:33:38,917] {processor.py:161} INFO - Processing /opt/airflow/dags/dbConnector.py took 0.278 seconds
[2022-08-18 16:34:09,157] {processor.py:153} INFO - Started process (PID=928) to work on /opt/airflow/dags/dbConnector.py
[2022-08-18 16:34:09,166] {processor.py:641} INFO - Processing file /opt/airflow/dags/dbConnector.py for tasks to queue
[2022-08-18 16:34:09,167] {logging_mixin.py:115} INFO - [2022-08-18 16:34:09,166] {dagbag.py:508} INFO - Filling up the DagBag from /opt/airflow/dags/dbConnector.py
[2022-08-18 16:34:09,408] {processor.py:653} WARNING - No viable dags retrieved from /opt/airflow/dags/dbConnector.py
[2022-08-18 16:34:09,426] {processor.py:161} INFO - Processing /opt/airflow/dags/dbConnector.py took 0.273 seconds
[2022-08-18 16:34:14,460] {processor.py:153} INFO - Started process (PID=930) to work on /opt/airflow/dags/dbConnector.py
[2022-08-18 16:34:14,461] {processor.py:641} INFO - Processing file /opt/airflow/dags/dbConnector.py for tasks to queue
[2022-08-18 16:34:14,461] {logging_mixin.py:115} INFO - [2022-08-18 16:34:14,461] {dagbag.py:508} INFO - Filling up the DagBag from /opt/airflow/dags/dbConnector.py
[2022-08-18 16:34:14,700] {processor.py:653} WARNING - No viable dags retrieved from /opt/airflow/dags/dbConnector.py
[2022-08-18 16:34:14,719] {processor.py:161} INFO - Processing /opt/airflow/dags/dbConnector.py took 0.263 seconds
[2022-08-18 16:34:27,499] {processor.py:153} INFO - Started process (PID=943) to work on /opt/airflow/dags/dbConnector.py
[2022-08-18 16:34:27,508] {processor.py:641} INFO - Processing file /opt/airflow/dags/dbConnector.py for tasks to queue
[2022-08-18 16:34:27,509] {logging_mixin.py:115} INFO - [2022-08-18 16:34:27,508] {dagbag.py:508} INFO - Filling up the DagBag from /opt/airflow/dags/dbConnector.py
[2022-08-18 16:34:28,362] {logging_mixin.py:115} INFO - [2022-08-18 16:34:28,357] {dagbag.py:321} ERROR - Failed to import: /opt/airflow/dags/dbConnector.py
Traceback (most recent call last):
  File "/home/airflow/.local/lib/python3.7/site-packages/sqlalchemy/engine/base.py", line 3243, in _wrap_pool_connect
    return fn()
  File "/home/airflow/.local/lib/python3.7/site-packages/sqlalchemy/pool/base.py", line 310, in connect
    return _ConnectionFairy._checkout(self)
  File "/home/airflow/.local/lib/python3.7/site-packages/sqlalchemy/pool/base.py", line 868, in _checkout
    fairy = _ConnectionRecord.checkout(pool)
  File "/home/airflow/.local/lib/python3.7/site-packages/sqlalchemy/pool/base.py", line 476, in checkout
    rec = pool._do_get()
  File "/home/airflow/.local/lib/python3.7/site-packages/sqlalchemy/pool/impl.py", line 146, in _do_get
    self._dec_overflow()
  File "/home/airflow/.local/lib/python3.7/site-packages/sqlalchemy/util/langhelpers.py", line 72, in __exit__
    with_traceback=exc_tb,
  File "/home/airflow/.local/lib/python3.7/site-packages/sqlalchemy/util/compat.py", line 207, in raise_
    raise exception
  File "/home/airflow/.local/lib/python3.7/site-packages/sqlalchemy/pool/impl.py", line 143, in _do_get
    return self._create_connection()
  File "/home/airflow/.local/lib/python3.7/site-packages/sqlalchemy/pool/base.py", line 256, in _create_connection
    return _ConnectionRecord(self)
  File "/home/airflow/.local/lib/python3.7/site-packages/sqlalchemy/pool/base.py", line 371, in __init__
    self.__connect()
  File "/home/airflow/.local/lib/python3.7/site-packages/sqlalchemy/pool/base.py", line 666, in __connect
    pool.logger.debug("Error on connect(): %s", e)
  File "/home/airflow/.local/lib/python3.7/site-packages/sqlalchemy/util/langhelpers.py", line 72, in __exit__
    with_traceback=exc_tb,
  File "/home/airflow/.local/lib/python3.7/site-packages/sqlalchemy/util/compat.py", line 207, in raise_
    raise exception
  File "/home/airflow/.local/lib/python3.7/site-packages/sqlalchemy/pool/base.py", line 661, in __connect
    self.dbapi_connection = connection = pool._invoke_creator(self)
  File "/home/airflow/.local/lib/python3.7/site-packages/sqlalchemy/engine/create.py", line 590, in connect
    return dialect.connect(*cargs, **cparams)
  File "/home/airflow/.local/lib/python3.7/site-packages/sqlalchemy/engine/default.py", line 584, in connect
    return self.dbapi.connect(*cargs, **cparams)
  File "/home/airflow/.local/lib/python3.7/site-packages/psycopg2/__init__.py", line 122, in connect
    conn = _connect(dsn, connection_factory=connection_factory, **kwasync)
psycopg2.OperationalError: connection to server at "localhost" (127.0.0.1), port 5432 failed: Connection refused
	Is the server running on that host and accepting TCP/IP connections?
connection to server at "localhost" (::1), port 5432 failed: Cannot assign requested address
	Is the server running on that host and accepting TCP/IP connections?


The above exception was the direct cause of the following exception:

Traceback (most recent call last):
  File "/home/airflow/.local/lib/python3.7/site-packages/airflow/models/dagbag.py", line 318, in parse
    loader.exec_module(new_module)
  File "<frozen importlib._bootstrap_external>", line 728, in exec_module
  File "<frozen importlib._bootstrap>", line 219, in _call_with_frames_removed
  File "/opt/airflow/dags/dbConnector.py", line 21, in <module>
    load_into_database()
  File "/opt/airflow/dags/dbConnector.py", line 10, in load_into_database
    data.to_sql('satellitedata', engine, index=False, if_exists='append')
  File "/home/airflow/.local/lib/python3.7/site-packages/pandas/core/generic.py", line 2882, in to_sql
    method=method,
  File "/home/airflow/.local/lib/python3.7/site-packages/pandas/io/sql.py", line 728, in to_sql
    **engine_kwargs,
  File "/home/airflow/.local/lib/python3.7/site-packages/pandas/io/sql.py", line 1758, in to_sql
    dtype=dtype,
  File "/home/airflow/.local/lib/python3.7/site-packages/pandas/io/sql.py", line 1650, in prep_table
    table.create()
  File "/home/airflow/.local/lib/python3.7/site-packages/pandas/io/sql.py", line 856, in create
    if self.exists():
  File "/home/airflow/.local/lib/python3.7/site-packages/pandas/io/sql.py", line 840, in exists
    return self.pd_sql.has_table(self.name, self.schema)
  File "/home/airflow/.local/lib/python3.7/site-packages/pandas/io/sql.py", line 1783, in has_table
    insp = sa.inspect(self.connectable)
  File "/home/airflow/.local/lib/python3.7/site-packages/sqlalchemy/inspection.py", line 64, in inspect
    ret = reg(subject)
  File "/home/airflow/.local/lib/python3.7/site-packages/sqlalchemy/engine/reflection.py", line 182, in _engine_insp
    return Inspector._construct(Inspector._init_engine, bind)
  File "/home/airflow/.local/lib/python3.7/site-packages/sqlalchemy/engine/reflection.py", line 117, in _construct
    init(self, bind)
  File "/home/airflow/.local/lib/python3.7/site-packages/sqlalchemy/engine/reflection.py", line 128, in _init_engine
    engine.connect().close()
  File "/home/airflow/.local/lib/python3.7/site-packages/sqlalchemy/engine/base.py", line 3197, in connect
    return self._connection_cls(self, close_with_result=close_with_result)
  File "/home/airflow/.local/lib/python3.7/site-packages/sqlalchemy/engine/base.py", line 96, in __init__
    else engine.raw_connection()
  File "/home/airflow/.local/lib/python3.7/site-packages/sqlalchemy/engine/base.py", line 3276, in raw_connection
    return self._wrap_pool_connect(self.pool.connect, _connection)
  File "/home/airflow/.local/lib/python3.7/site-packages/sqlalchemy/engine/base.py", line 3247, in _wrap_pool_connect
    e, dialect, self
  File "/home/airflow/.local/lib/python3.7/site-packages/sqlalchemy/engine/base.py", line 2101, in _handle_dbapi_exception_noconnection
    sqlalchemy_exception, with_traceback=exc_info[2], from_=e
  File "/home/airflow/.local/lib/python3.7/site-packages/sqlalchemy/util/compat.py", line 207, in raise_
    raise exception
  File "/home/airflow/.local/lib/python3.7/site-packages/sqlalchemy/engine/base.py", line 3243, in _wrap_pool_connect
    return fn()
  File "/home/airflow/.local/lib/python3.7/site-packages/sqlalchemy/pool/base.py", line 310, in connect
    return _ConnectionFairy._checkout(self)
  File "/home/airflow/.local/lib/python3.7/site-packages/sqlalchemy/pool/base.py", line 868, in _checkout
    fairy = _ConnectionRecord.checkout(pool)
  File "/home/airflow/.local/lib/python3.7/site-packages/sqlalchemy/pool/base.py", line 476, in checkout
    rec = pool._do_get()
  File "/home/airflow/.local/lib/python3.7/site-packages/sqlalchemy/pool/impl.py", line 146, in _do_get
    self._dec_overflow()
  File "/home/airflow/.local/lib/python3.7/site-packages/sqlalchemy/util/langhelpers.py", line 72, in __exit__
    with_traceback=exc_tb,
  File "/home/airflow/.local/lib/python3.7/site-packages/sqlalchemy/util/compat.py", line 207, in raise_
    raise exception
  File "/home/airflow/.local/lib/python3.7/site-packages/sqlalchemy/pool/impl.py", line 143, in _do_get
    return self._create_connection()
  File "/home/airflow/.local/lib/python3.7/site-packages/sqlalchemy/pool/base.py", line 256, in _create_connection
    return _ConnectionRecord(self)
  File "/home/airflow/.local/lib/python3.7/site-packages/sqlalchemy/pool/base.py", line 371, in __init__
    self.__connect()
  File "/home/airflow/.local/lib/python3.7/site-packages/sqlalchemy/pool/base.py", line 666, in __connect
    pool.logger.debug("Error on connect(): %s", e)
  File "/home/airflow/.local/lib/python3.7/site-packages/sqlalchemy/util/langhelpers.py", line 72, in __exit__
    with_traceback=exc_tb,
  File "/home/airflow/.local/lib/python3.7/site-packages/sqlalchemy/util/compat.py", line 207, in raise_
    raise exception
  File "/home/airflow/.local/lib/python3.7/site-packages/sqlalchemy/pool/base.py", line 661, in __connect
    self.dbapi_connection = connection = pool._invoke_creator(self)
  File "/home/airflow/.local/lib/python3.7/site-packages/sqlalchemy/engine/create.py", line 590, in connect
    return dialect.connect(*cargs, **cparams)
  File "/home/airflow/.local/lib/python3.7/site-packages/sqlalchemy/engine/default.py", line 584, in connect
    return self.dbapi.connect(*cargs, **cparams)
  File "/home/airflow/.local/lib/python3.7/site-packages/psycopg2/__init__.py", line 122, in connect
    conn = _connect(dsn, connection_factory=connection_factory, **kwasync)
sqlalchemy.exc.OperationalError: (psycopg2.OperationalError) connection to server at "localhost" (127.0.0.1), port 5432 failed: Connection refused
	Is the server running on that host and accepting TCP/IP connections?
connection to server at "localhost" (::1), port 5432 failed: Cannot assign requested address
	Is the server running on that host and accepting TCP/IP connections?

(Background on this error at: https://sqlalche.me/e/14/e3q8)
[2022-08-18 16:34:28,362] {processor.py:653} WARNING - No viable dags retrieved from /opt/airflow/dags/dbConnector.py
[2022-08-18 16:34:28,392] {processor.py:161} INFO - Processing /opt/airflow/dags/dbConnector.py took 0.897 seconds
[2022-08-18 16:34:58,694] {processor.py:153} INFO - Started process (PID=976) to work on /opt/airflow/dags/dbConnector.py
[2022-08-18 16:34:58,719] {processor.py:641} INFO - Processing file /opt/airflow/dags/dbConnector.py for tasks to queue
[2022-08-18 16:34:58,720] {logging_mixin.py:115} INFO - [2022-08-18 16:34:58,720] {dagbag.py:508} INFO - Filling up the DagBag from /opt/airflow/dags/dbConnector.py
[2022-08-18 16:34:59,470] {logging_mixin.py:115} INFO - [2022-08-18 16:34:59,465] {dagbag.py:321} ERROR - Failed to import: /opt/airflow/dags/dbConnector.py
Traceback (most recent call last):
  File "/home/airflow/.local/lib/python3.7/site-packages/sqlalchemy/engine/base.py", line 3243, in _wrap_pool_connect
    return fn()
  File "/home/airflow/.local/lib/python3.7/site-packages/sqlalchemy/pool/base.py", line 310, in connect
    return _ConnectionFairy._checkout(self)
  File "/home/airflow/.local/lib/python3.7/site-packages/sqlalchemy/pool/base.py", line 868, in _checkout
    fairy = _ConnectionRecord.checkout(pool)
  File "/home/airflow/.local/lib/python3.7/site-packages/sqlalchemy/pool/base.py", line 476, in checkout
    rec = pool._do_get()
  File "/home/airflow/.local/lib/python3.7/site-packages/sqlalchemy/pool/impl.py", line 146, in _do_get
    self._dec_overflow()
  File "/home/airflow/.local/lib/python3.7/site-packages/sqlalchemy/util/langhelpers.py", line 72, in __exit__
    with_traceback=exc_tb,
  File "/home/airflow/.local/lib/python3.7/site-packages/sqlalchemy/util/compat.py", line 207, in raise_
    raise exception
  File "/home/airflow/.local/lib/python3.7/site-packages/sqlalchemy/pool/impl.py", line 143, in _do_get
    return self._create_connection()
  File "/home/airflow/.local/lib/python3.7/site-packages/sqlalchemy/pool/base.py", line 256, in _create_connection
    return _ConnectionRecord(self)
  File "/home/airflow/.local/lib/python3.7/site-packages/sqlalchemy/pool/base.py", line 371, in __init__
    self.__connect()
  File "/home/airflow/.local/lib/python3.7/site-packages/sqlalchemy/pool/base.py", line 666, in __connect
    pool.logger.debug("Error on connect(): %s", e)
  File "/home/airflow/.local/lib/python3.7/site-packages/sqlalchemy/util/langhelpers.py", line 72, in __exit__
    with_traceback=exc_tb,
  File "/home/airflow/.local/lib/python3.7/site-packages/sqlalchemy/util/compat.py", line 207, in raise_
    raise exception
  File "/home/airflow/.local/lib/python3.7/site-packages/sqlalchemy/pool/base.py", line 661, in __connect
    self.dbapi_connection = connection = pool._invoke_creator(self)
  File "/home/airflow/.local/lib/python3.7/site-packages/sqlalchemy/engine/create.py", line 590, in connect
    return dialect.connect(*cargs, **cparams)
  File "/home/airflow/.local/lib/python3.7/site-packages/sqlalchemy/engine/default.py", line 584, in connect
    return self.dbapi.connect(*cargs, **cparams)
  File "/home/airflow/.local/lib/python3.7/site-packages/psycopg2/__init__.py", line 122, in connect
    conn = _connect(dsn, connection_factory=connection_factory, **kwasync)
psycopg2.OperationalError: connection to server at "localhost" (127.0.0.1), port 5432 failed: Connection refused
	Is the server running on that host and accepting TCP/IP connections?
connection to server at "localhost" (::1), port 5432 failed: Cannot assign requested address
	Is the server running on that host and accepting TCP/IP connections?


The above exception was the direct cause of the following exception:

Traceback (most recent call last):
  File "/home/airflow/.local/lib/python3.7/site-packages/airflow/models/dagbag.py", line 318, in parse
    loader.exec_module(new_module)
  File "<frozen importlib._bootstrap_external>", line 728, in exec_module
  File "<frozen importlib._bootstrap>", line 219, in _call_with_frames_removed
  File "/opt/airflow/dags/dbConnector.py", line 21, in <module>
    load_into_database()
  File "/opt/airflow/dags/dbConnector.py", line 10, in load_into_database
    data.to_sql('satellitedata', engine, index=False, if_exists='append')
  File "/home/airflow/.local/lib/python3.7/site-packages/pandas/core/generic.py", line 2882, in to_sql
    method=method,
  File "/home/airflow/.local/lib/python3.7/site-packages/pandas/io/sql.py", line 728, in to_sql
    **engine_kwargs,
  File "/home/airflow/.local/lib/python3.7/site-packages/pandas/io/sql.py", line 1758, in to_sql
    dtype=dtype,
  File "/home/airflow/.local/lib/python3.7/site-packages/pandas/io/sql.py", line 1650, in prep_table
    table.create()
  File "/home/airflow/.local/lib/python3.7/site-packages/pandas/io/sql.py", line 856, in create
    if self.exists():
  File "/home/airflow/.local/lib/python3.7/site-packages/pandas/io/sql.py", line 840, in exists
    return self.pd_sql.has_table(self.name, self.schema)
  File "/home/airflow/.local/lib/python3.7/site-packages/pandas/io/sql.py", line 1783, in has_table
    insp = sa.inspect(self.connectable)
  File "/home/airflow/.local/lib/python3.7/site-packages/sqlalchemy/inspection.py", line 64, in inspect
    ret = reg(subject)
  File "/home/airflow/.local/lib/python3.7/site-packages/sqlalchemy/engine/reflection.py", line 182, in _engine_insp
    return Inspector._construct(Inspector._init_engine, bind)
  File "/home/airflow/.local/lib/python3.7/site-packages/sqlalchemy/engine/reflection.py", line 117, in _construct
    init(self, bind)
  File "/home/airflow/.local/lib/python3.7/site-packages/sqlalchemy/engine/reflection.py", line 128, in _init_engine
    engine.connect().close()
  File "/home/airflow/.local/lib/python3.7/site-packages/sqlalchemy/engine/base.py", line 3197, in connect
    return self._connection_cls(self, close_with_result=close_with_result)
  File "/home/airflow/.local/lib/python3.7/site-packages/sqlalchemy/engine/base.py", line 96, in __init__
    else engine.raw_connection()
  File "/home/airflow/.local/lib/python3.7/site-packages/sqlalchemy/engine/base.py", line 3276, in raw_connection
    return self._wrap_pool_connect(self.pool.connect, _connection)
  File "/home/airflow/.local/lib/python3.7/site-packages/sqlalchemy/engine/base.py", line 3247, in _wrap_pool_connect
    e, dialect, self
  File "/home/airflow/.local/lib/python3.7/site-packages/sqlalchemy/engine/base.py", line 2101, in _handle_dbapi_exception_noconnection
    sqlalchemy_exception, with_traceback=exc_info[2], from_=e
  File "/home/airflow/.local/lib/python3.7/site-packages/sqlalchemy/util/compat.py", line 207, in raise_
    raise exception
  File "/home/airflow/.local/lib/python3.7/site-packages/sqlalchemy/engine/base.py", line 3243, in _wrap_pool_connect
    return fn()
  File "/home/airflow/.local/lib/python3.7/site-packages/sqlalchemy/pool/base.py", line 310, in connect
    return _ConnectionFairy._checkout(self)
  File "/home/airflow/.local/lib/python3.7/site-packages/sqlalchemy/pool/base.py", line 868, in _checkout
    fairy = _ConnectionRecord.checkout(pool)
  File "/home/airflow/.local/lib/python3.7/site-packages/sqlalchemy/pool/base.py", line 476, in checkout
    rec = pool._do_get()
  File "/home/airflow/.local/lib/python3.7/site-packages/sqlalchemy/pool/impl.py", line 146, in _do_get
    self._dec_overflow()
  File "/home/airflow/.local/lib/python3.7/site-packages/sqlalchemy/util/langhelpers.py", line 72, in __exit__
    with_traceback=exc_tb,
  File "/home/airflow/.local/lib/python3.7/site-packages/sqlalchemy/util/compat.py", line 207, in raise_
    raise exception
  File "/home/airflow/.local/lib/python3.7/site-packages/sqlalchemy/pool/impl.py", line 143, in _do_get
    return self._create_connection()
  File "/home/airflow/.local/lib/python3.7/site-packages/sqlalchemy/pool/base.py", line 256, in _create_connection
    return _ConnectionRecord(self)
  File "/home/airflow/.local/lib/python3.7/site-packages/sqlalchemy/pool/base.py", line 371, in __init__
    self.__connect()
  File "/home/airflow/.local/lib/python3.7/site-packages/sqlalchemy/pool/base.py", line 666, in __connect
    pool.logger.debug("Error on connect(): %s", e)
  File "/home/airflow/.local/lib/python3.7/site-packages/sqlalchemy/util/langhelpers.py", line 72, in __exit__
    with_traceback=exc_tb,
  File "/home/airflow/.local/lib/python3.7/site-packages/sqlalchemy/util/compat.py", line 207, in raise_
    raise exception
  File "/home/airflow/.local/lib/python3.7/site-packages/sqlalchemy/pool/base.py", line 661, in __connect
    self.dbapi_connection = connection = pool._invoke_creator(self)
  File "/home/airflow/.local/lib/python3.7/site-packages/sqlalchemy/engine/create.py", line 590, in connect
    return dialect.connect(*cargs, **cparams)
  File "/home/airflow/.local/lib/python3.7/site-packages/sqlalchemy/engine/default.py", line 584, in connect
    return self.dbapi.connect(*cargs, **cparams)
  File "/home/airflow/.local/lib/python3.7/site-packages/psycopg2/__init__.py", line 122, in connect
    conn = _connect(dsn, connection_factory=connection_factory, **kwasync)
sqlalchemy.exc.OperationalError: (psycopg2.OperationalError) connection to server at "localhost" (127.0.0.1), port 5432 failed: Connection refused
	Is the server running on that host and accepting TCP/IP connections?
connection to server at "localhost" (::1), port 5432 failed: Cannot assign requested address
	Is the server running on that host and accepting TCP/IP connections?

(Background on this error at: https://sqlalche.me/e/14/e3q8)
[2022-08-18 16:34:59,470] {processor.py:653} WARNING - No viable dags retrieved from /opt/airflow/dags/dbConnector.py
[2022-08-18 16:34:59,526] {processor.py:161} INFO - Processing /opt/airflow/dags/dbConnector.py took 0.836 seconds
[2022-08-18 16:35:29,872] {processor.py:153} INFO - Started process (PID=1009) to work on /opt/airflow/dags/dbConnector.py
[2022-08-18 16:35:29,888] {processor.py:641} INFO - Processing file /opt/airflow/dags/dbConnector.py for tasks to queue
[2022-08-18 16:35:29,889] {logging_mixin.py:115} INFO - [2022-08-18 16:35:29,888] {dagbag.py:508} INFO - Filling up the DagBag from /opt/airflow/dags/dbConnector.py
[2022-08-18 16:35:30,650] {logging_mixin.py:115} INFO - [2022-08-18 16:35:30,646] {dagbag.py:321} ERROR - Failed to import: /opt/airflow/dags/dbConnector.py
Traceback (most recent call last):
  File "/home/airflow/.local/lib/python3.7/site-packages/sqlalchemy/engine/base.py", line 3243, in _wrap_pool_connect
    return fn()
  File "/home/airflow/.local/lib/python3.7/site-packages/sqlalchemy/pool/base.py", line 310, in connect
    return _ConnectionFairy._checkout(self)
  File "/home/airflow/.local/lib/python3.7/site-packages/sqlalchemy/pool/base.py", line 868, in _checkout
    fairy = _ConnectionRecord.checkout(pool)
  File "/home/airflow/.local/lib/python3.7/site-packages/sqlalchemy/pool/base.py", line 476, in checkout
    rec = pool._do_get()
  File "/home/airflow/.local/lib/python3.7/site-packages/sqlalchemy/pool/impl.py", line 146, in _do_get
    self._dec_overflow()
  File "/home/airflow/.local/lib/python3.7/site-packages/sqlalchemy/util/langhelpers.py", line 72, in __exit__
    with_traceback=exc_tb,
  File "/home/airflow/.local/lib/python3.7/site-packages/sqlalchemy/util/compat.py", line 207, in raise_
    raise exception
  File "/home/airflow/.local/lib/python3.7/site-packages/sqlalchemy/pool/impl.py", line 143, in _do_get
    return self._create_connection()
  File "/home/airflow/.local/lib/python3.7/site-packages/sqlalchemy/pool/base.py", line 256, in _create_connection
    return _ConnectionRecord(self)
  File "/home/airflow/.local/lib/python3.7/site-packages/sqlalchemy/pool/base.py", line 371, in __init__
    self.__connect()
  File "/home/airflow/.local/lib/python3.7/site-packages/sqlalchemy/pool/base.py", line 666, in __connect
    pool.logger.debug("Error on connect(): %s", e)
  File "/home/airflow/.local/lib/python3.7/site-packages/sqlalchemy/util/langhelpers.py", line 72, in __exit__
    with_traceback=exc_tb,
  File "/home/airflow/.local/lib/python3.7/site-packages/sqlalchemy/util/compat.py", line 207, in raise_
    raise exception
  File "/home/airflow/.local/lib/python3.7/site-packages/sqlalchemy/pool/base.py", line 661, in __connect
    self.dbapi_connection = connection = pool._invoke_creator(self)
  File "/home/airflow/.local/lib/python3.7/site-packages/sqlalchemy/engine/create.py", line 590, in connect
    return dialect.connect(*cargs, **cparams)
  File "/home/airflow/.local/lib/python3.7/site-packages/sqlalchemy/engine/default.py", line 584, in connect
    return self.dbapi.connect(*cargs, **cparams)
  File "/home/airflow/.local/lib/python3.7/site-packages/psycopg2/__init__.py", line 122, in connect
    conn = _connect(dsn, connection_factory=connection_factory, **kwasync)
psycopg2.OperationalError: connection to server at "localhost" (127.0.0.1), port 5432 failed: Connection refused
	Is the server running on that host and accepting TCP/IP connections?
connection to server at "localhost" (::1), port 5432 failed: Cannot assign requested address
	Is the server running on that host and accepting TCP/IP connections?


The above exception was the direct cause of the following exception:

Traceback (most recent call last):
  File "/home/airflow/.local/lib/python3.7/site-packages/airflow/models/dagbag.py", line 318, in parse
    loader.exec_module(new_module)
  File "<frozen importlib._bootstrap_external>", line 728, in exec_module
  File "<frozen importlib._bootstrap>", line 219, in _call_with_frames_removed
  File "/opt/airflow/dags/dbConnector.py", line 21, in <module>
    load_into_database()
  File "/opt/airflow/dags/dbConnector.py", line 10, in load_into_database
    data.to_sql('satellitedata', engine, index=False, if_exists='append')
  File "/home/airflow/.local/lib/python3.7/site-packages/pandas/core/generic.py", line 2882, in to_sql
    method=method,
  File "/home/airflow/.local/lib/python3.7/site-packages/pandas/io/sql.py", line 728, in to_sql
    **engine_kwargs,
  File "/home/airflow/.local/lib/python3.7/site-packages/pandas/io/sql.py", line 1758, in to_sql
    dtype=dtype,
  File "/home/airflow/.local/lib/python3.7/site-packages/pandas/io/sql.py", line 1650, in prep_table
    table.create()
  File "/home/airflow/.local/lib/python3.7/site-packages/pandas/io/sql.py", line 856, in create
    if self.exists():
  File "/home/airflow/.local/lib/python3.7/site-packages/pandas/io/sql.py", line 840, in exists
    return self.pd_sql.has_table(self.name, self.schema)
  File "/home/airflow/.local/lib/python3.7/site-packages/pandas/io/sql.py", line 1783, in has_table
    insp = sa.inspect(self.connectable)
  File "/home/airflow/.local/lib/python3.7/site-packages/sqlalchemy/inspection.py", line 64, in inspect
    ret = reg(subject)
  File "/home/airflow/.local/lib/python3.7/site-packages/sqlalchemy/engine/reflection.py", line 182, in _engine_insp
    return Inspector._construct(Inspector._init_engine, bind)
  File "/home/airflow/.local/lib/python3.7/site-packages/sqlalchemy/engine/reflection.py", line 117, in _construct
    init(self, bind)
  File "/home/airflow/.local/lib/python3.7/site-packages/sqlalchemy/engine/reflection.py", line 128, in _init_engine
    engine.connect().close()
  File "/home/airflow/.local/lib/python3.7/site-packages/sqlalchemy/engine/base.py", line 3197, in connect
    return self._connection_cls(self, close_with_result=close_with_result)
  File "/home/airflow/.local/lib/python3.7/site-packages/sqlalchemy/engine/base.py", line 96, in __init__
    else engine.raw_connection()
  File "/home/airflow/.local/lib/python3.7/site-packages/sqlalchemy/engine/base.py", line 3276, in raw_connection
    return self._wrap_pool_connect(self.pool.connect, _connection)
  File "/home/airflow/.local/lib/python3.7/site-packages/sqlalchemy/engine/base.py", line 3247, in _wrap_pool_connect
    e, dialect, self
  File "/home/airflow/.local/lib/python3.7/site-packages/sqlalchemy/engine/base.py", line 2101, in _handle_dbapi_exception_noconnection
    sqlalchemy_exception, with_traceback=exc_info[2], from_=e
  File "/home/airflow/.local/lib/python3.7/site-packages/sqlalchemy/util/compat.py", line 207, in raise_
    raise exception
  File "/home/airflow/.local/lib/python3.7/site-packages/sqlalchemy/engine/base.py", line 3243, in _wrap_pool_connect
    return fn()
  File "/home/airflow/.local/lib/python3.7/site-packages/sqlalchemy/pool/base.py", line 310, in connect
    return _ConnectionFairy._checkout(self)
  File "/home/airflow/.local/lib/python3.7/site-packages/sqlalchemy/pool/base.py", line 868, in _checkout
    fairy = _ConnectionRecord.checkout(pool)
  File "/home/airflow/.local/lib/python3.7/site-packages/sqlalchemy/pool/base.py", line 476, in checkout
    rec = pool._do_get()
  File "/home/airflow/.local/lib/python3.7/site-packages/sqlalchemy/pool/impl.py", line 146, in _do_get
    self._dec_overflow()
  File "/home/airflow/.local/lib/python3.7/site-packages/sqlalchemy/util/langhelpers.py", line 72, in __exit__
    with_traceback=exc_tb,
  File "/home/airflow/.local/lib/python3.7/site-packages/sqlalchemy/util/compat.py", line 207, in raise_
    raise exception
  File "/home/airflow/.local/lib/python3.7/site-packages/sqlalchemy/pool/impl.py", line 143, in _do_get
    return self._create_connection()
  File "/home/airflow/.local/lib/python3.7/site-packages/sqlalchemy/pool/base.py", line 256, in _create_connection
    return _ConnectionRecord(self)
  File "/home/airflow/.local/lib/python3.7/site-packages/sqlalchemy/pool/base.py", line 371, in __init__
    self.__connect()
  File "/home/airflow/.local/lib/python3.7/site-packages/sqlalchemy/pool/base.py", line 666, in __connect
    pool.logger.debug("Error on connect(): %s", e)
  File "/home/airflow/.local/lib/python3.7/site-packages/sqlalchemy/util/langhelpers.py", line 72, in __exit__
    with_traceback=exc_tb,
  File "/home/airflow/.local/lib/python3.7/site-packages/sqlalchemy/util/compat.py", line 207, in raise_
    raise exception
  File "/home/airflow/.local/lib/python3.7/site-packages/sqlalchemy/pool/base.py", line 661, in __connect
    self.dbapi_connection = connection = pool._invoke_creator(self)
  File "/home/airflow/.local/lib/python3.7/site-packages/sqlalchemy/engine/create.py", line 590, in connect
    return dialect.connect(*cargs, **cparams)
  File "/home/airflow/.local/lib/python3.7/site-packages/sqlalchemy/engine/default.py", line 584, in connect
    return self.dbapi.connect(*cargs, **cparams)
  File "/home/airflow/.local/lib/python3.7/site-packages/psycopg2/__init__.py", line 122, in connect
    conn = _connect(dsn, connection_factory=connection_factory, **kwasync)
sqlalchemy.exc.OperationalError: (psycopg2.OperationalError) connection to server at "localhost" (127.0.0.1), port 5432 failed: Connection refused
	Is the server running on that host and accepting TCP/IP connections?
connection to server at "localhost" (::1), port 5432 failed: Cannot assign requested address
	Is the server running on that host and accepting TCP/IP connections?

(Background on this error at: https://sqlalche.me/e/14/e3q8)
[2022-08-18 16:35:30,650] {processor.py:653} WARNING - No viable dags retrieved from /opt/airflow/dags/dbConnector.py
[2022-08-18 16:35:30,685] {processor.py:161} INFO - Processing /opt/airflow/dags/dbConnector.py took 0.817 seconds
[2022-08-18 16:36:00,826] {processor.py:153} INFO - Started process (PID=1031) to work on /opt/airflow/dags/dbConnector.py
[2022-08-18 16:36:00,835] {processor.py:641} INFO - Processing file /opt/airflow/dags/dbConnector.py for tasks to queue
[2022-08-18 16:36:00,836] {logging_mixin.py:115} INFO - [2022-08-18 16:36:00,836] {dagbag.py:508} INFO - Filling up the DagBag from /opt/airflow/dags/dbConnector.py
[2022-08-18 16:36:01,655] {logging_mixin.py:115} INFO - [2022-08-18 16:36:01,650] {dagbag.py:321} ERROR - Failed to import: /opt/airflow/dags/dbConnector.py
Traceback (most recent call last):
  File "/home/airflow/.local/lib/python3.7/site-packages/sqlalchemy/engine/base.py", line 3243, in _wrap_pool_connect
    return fn()
  File "/home/airflow/.local/lib/python3.7/site-packages/sqlalchemy/pool/base.py", line 310, in connect
    return _ConnectionFairy._checkout(self)
  File "/home/airflow/.local/lib/python3.7/site-packages/sqlalchemy/pool/base.py", line 868, in _checkout
    fairy = _ConnectionRecord.checkout(pool)
  File "/home/airflow/.local/lib/python3.7/site-packages/sqlalchemy/pool/base.py", line 476, in checkout
    rec = pool._do_get()
  File "/home/airflow/.local/lib/python3.7/site-packages/sqlalchemy/pool/impl.py", line 146, in _do_get
    self._dec_overflow()
  File "/home/airflow/.local/lib/python3.7/site-packages/sqlalchemy/util/langhelpers.py", line 72, in __exit__
    with_traceback=exc_tb,
  File "/home/airflow/.local/lib/python3.7/site-packages/sqlalchemy/util/compat.py", line 207, in raise_
    raise exception
  File "/home/airflow/.local/lib/python3.7/site-packages/sqlalchemy/pool/impl.py", line 143, in _do_get
    return self._create_connection()
  File "/home/airflow/.local/lib/python3.7/site-packages/sqlalchemy/pool/base.py", line 256, in _create_connection
    return _ConnectionRecord(self)
  File "/home/airflow/.local/lib/python3.7/site-packages/sqlalchemy/pool/base.py", line 371, in __init__
    self.__connect()
  File "/home/airflow/.local/lib/python3.7/site-packages/sqlalchemy/pool/base.py", line 666, in __connect
    pool.logger.debug("Error on connect(): %s", e)
  File "/home/airflow/.local/lib/python3.7/site-packages/sqlalchemy/util/langhelpers.py", line 72, in __exit__
    with_traceback=exc_tb,
  File "/home/airflow/.local/lib/python3.7/site-packages/sqlalchemy/util/compat.py", line 207, in raise_
    raise exception
  File "/home/airflow/.local/lib/python3.7/site-packages/sqlalchemy/pool/base.py", line 661, in __connect
    self.dbapi_connection = connection = pool._invoke_creator(self)
  File "/home/airflow/.local/lib/python3.7/site-packages/sqlalchemy/engine/create.py", line 590, in connect
    return dialect.connect(*cargs, **cparams)
  File "/home/airflow/.local/lib/python3.7/site-packages/sqlalchemy/engine/default.py", line 584, in connect
    return self.dbapi.connect(*cargs, **cparams)
  File "/home/airflow/.local/lib/python3.7/site-packages/psycopg2/__init__.py", line 122, in connect
    conn = _connect(dsn, connection_factory=connection_factory, **kwasync)
psycopg2.OperationalError: connection to server at "localhost" (127.0.0.1), port 5432 failed: Connection refused
	Is the server running on that host and accepting TCP/IP connections?
connection to server at "localhost" (::1), port 5432 failed: Cannot assign requested address
	Is the server running on that host and accepting TCP/IP connections?


The above exception was the direct cause of the following exception:

Traceback (most recent call last):
  File "/home/airflow/.local/lib/python3.7/site-packages/airflow/models/dagbag.py", line 318, in parse
    loader.exec_module(new_module)
  File "<frozen importlib._bootstrap_external>", line 728, in exec_module
  File "<frozen importlib._bootstrap>", line 219, in _call_with_frames_removed
  File "/opt/airflow/dags/dbConnector.py", line 21, in <module>
    load_into_database()
  File "/opt/airflow/dags/dbConnector.py", line 10, in load_into_database
    data.to_sql('satellitedata', engine, index=False, if_exists='append')
  File "/home/airflow/.local/lib/python3.7/site-packages/pandas/core/generic.py", line 2882, in to_sql
    method=method,
  File "/home/airflow/.local/lib/python3.7/site-packages/pandas/io/sql.py", line 728, in to_sql
    **engine_kwargs,
  File "/home/airflow/.local/lib/python3.7/site-packages/pandas/io/sql.py", line 1758, in to_sql
    dtype=dtype,
  File "/home/airflow/.local/lib/python3.7/site-packages/pandas/io/sql.py", line 1650, in prep_table
    table.create()
  File "/home/airflow/.local/lib/python3.7/site-packages/pandas/io/sql.py", line 856, in create
    if self.exists():
  File "/home/airflow/.local/lib/python3.7/site-packages/pandas/io/sql.py", line 840, in exists
    return self.pd_sql.has_table(self.name, self.schema)
  File "/home/airflow/.local/lib/python3.7/site-packages/pandas/io/sql.py", line 1783, in has_table
    insp = sa.inspect(self.connectable)
  File "/home/airflow/.local/lib/python3.7/site-packages/sqlalchemy/inspection.py", line 64, in inspect
    ret = reg(subject)
  File "/home/airflow/.local/lib/python3.7/site-packages/sqlalchemy/engine/reflection.py", line 182, in _engine_insp
    return Inspector._construct(Inspector._init_engine, bind)
  File "/home/airflow/.local/lib/python3.7/site-packages/sqlalchemy/engine/reflection.py", line 117, in _construct
    init(self, bind)
  File "/home/airflow/.local/lib/python3.7/site-packages/sqlalchemy/engine/reflection.py", line 128, in _init_engine
    engine.connect().close()
  File "/home/airflow/.local/lib/python3.7/site-packages/sqlalchemy/engine/base.py", line 3197, in connect
    return self._connection_cls(self, close_with_result=close_with_result)
  File "/home/airflow/.local/lib/python3.7/site-packages/sqlalchemy/engine/base.py", line 96, in __init__
    else engine.raw_connection()
  File "/home/airflow/.local/lib/python3.7/site-packages/sqlalchemy/engine/base.py", line 3276, in raw_connection
    return self._wrap_pool_connect(self.pool.connect, _connection)
  File "/home/airflow/.local/lib/python3.7/site-packages/sqlalchemy/engine/base.py", line 3247, in _wrap_pool_connect
    e, dialect, self
  File "/home/airflow/.local/lib/python3.7/site-packages/sqlalchemy/engine/base.py", line 2101, in _handle_dbapi_exception_noconnection
    sqlalchemy_exception, with_traceback=exc_info[2], from_=e
  File "/home/airflow/.local/lib/python3.7/site-packages/sqlalchemy/util/compat.py", line 207, in raise_
    raise exception
  File "/home/airflow/.local/lib/python3.7/site-packages/sqlalchemy/engine/base.py", line 3243, in _wrap_pool_connect
    return fn()
  File "/home/airflow/.local/lib/python3.7/site-packages/sqlalchemy/pool/base.py", line 310, in connect
    return _ConnectionFairy._checkout(self)
  File "/home/airflow/.local/lib/python3.7/site-packages/sqlalchemy/pool/base.py", line 868, in _checkout
    fairy = _ConnectionRecord.checkout(pool)
  File "/home/airflow/.local/lib/python3.7/site-packages/sqlalchemy/pool/base.py", line 476, in checkout
    rec = pool._do_get()
  File "/home/airflow/.local/lib/python3.7/site-packages/sqlalchemy/pool/impl.py", line 146, in _do_get
    self._dec_overflow()
  File "/home/airflow/.local/lib/python3.7/site-packages/sqlalchemy/util/langhelpers.py", line 72, in __exit__
    with_traceback=exc_tb,
  File "/home/airflow/.local/lib/python3.7/site-packages/sqlalchemy/util/compat.py", line 207, in raise_
    raise exception
  File "/home/airflow/.local/lib/python3.7/site-packages/sqlalchemy/pool/impl.py", line 143, in _do_get
    return self._create_connection()
  File "/home/airflow/.local/lib/python3.7/site-packages/sqlalchemy/pool/base.py", line 256, in _create_connection
    return _ConnectionRecord(self)
  File "/home/airflow/.local/lib/python3.7/site-packages/sqlalchemy/pool/base.py", line 371, in __init__
    self.__connect()
  File "/home/airflow/.local/lib/python3.7/site-packages/sqlalchemy/pool/base.py", line 666, in __connect
    pool.logger.debug("Error on connect(): %s", e)
  File "/home/airflow/.local/lib/python3.7/site-packages/sqlalchemy/util/langhelpers.py", line 72, in __exit__
    with_traceback=exc_tb,
  File "/home/airflow/.local/lib/python3.7/site-packages/sqlalchemy/util/compat.py", line 207, in raise_
    raise exception
  File "/home/airflow/.local/lib/python3.7/site-packages/sqlalchemy/pool/base.py", line 661, in __connect
    self.dbapi_connection = connection = pool._invoke_creator(self)
  File "/home/airflow/.local/lib/python3.7/site-packages/sqlalchemy/engine/create.py", line 590, in connect
    return dialect.connect(*cargs, **cparams)
  File "/home/airflow/.local/lib/python3.7/site-packages/sqlalchemy/engine/default.py", line 584, in connect
    return self.dbapi.connect(*cargs, **cparams)
  File "/home/airflow/.local/lib/python3.7/site-packages/psycopg2/__init__.py", line 122, in connect
    conn = _connect(dsn, connection_factory=connection_factory, **kwasync)
sqlalchemy.exc.OperationalError: (psycopg2.OperationalError) connection to server at "localhost" (127.0.0.1), port 5432 failed: Connection refused
	Is the server running on that host and accepting TCP/IP connections?
connection to server at "localhost" (::1), port 5432 failed: Cannot assign requested address
	Is the server running on that host and accepting TCP/IP connections?

(Background on this error at: https://sqlalche.me/e/14/e3q8)
[2022-08-18 16:36:01,655] {processor.py:653} WARNING - No viable dags retrieved from /opt/airflow/dags/dbConnector.py
[2022-08-18 16:36:01,685] {processor.py:161} INFO - Processing /opt/airflow/dags/dbConnector.py took 0.861 seconds
[2022-08-18 16:36:03,712] {processor.py:153} INFO - Started process (PID=1042) to work on /opt/airflow/dags/dbConnector.py
[2022-08-18 16:36:03,713] {processor.py:641} INFO - Processing file /opt/airflow/dags/dbConnector.py for tasks to queue
[2022-08-18 16:36:03,713] {logging_mixin.py:115} INFO - [2022-08-18 16:36:03,713] {dagbag.py:508} INFO - Filling up the DagBag from /opt/airflow/dags/dbConnector.py
[2022-08-18 16:36:04,556] {logging_mixin.py:115} INFO - [2022-08-18 16:36:04,552] {dagbag.py:321} ERROR - Failed to import: /opt/airflow/dags/dbConnector.py
Traceback (most recent call last):
  File "/home/airflow/.local/lib/python3.7/site-packages/sqlalchemy/engine/base.py", line 3243, in _wrap_pool_connect
    return fn()
  File "/home/airflow/.local/lib/python3.7/site-packages/sqlalchemy/pool/base.py", line 310, in connect
    return _ConnectionFairy._checkout(self)
  File "/home/airflow/.local/lib/python3.7/site-packages/sqlalchemy/pool/base.py", line 868, in _checkout
    fairy = _ConnectionRecord.checkout(pool)
  File "/home/airflow/.local/lib/python3.7/site-packages/sqlalchemy/pool/base.py", line 476, in checkout
    rec = pool._do_get()
  File "/home/airflow/.local/lib/python3.7/site-packages/sqlalchemy/pool/impl.py", line 146, in _do_get
    self._dec_overflow()
  File "/home/airflow/.local/lib/python3.7/site-packages/sqlalchemy/util/langhelpers.py", line 72, in __exit__
    with_traceback=exc_tb,
  File "/home/airflow/.local/lib/python3.7/site-packages/sqlalchemy/util/compat.py", line 207, in raise_
    raise exception
  File "/home/airflow/.local/lib/python3.7/site-packages/sqlalchemy/pool/impl.py", line 143, in _do_get
    return self._create_connection()
  File "/home/airflow/.local/lib/python3.7/site-packages/sqlalchemy/pool/base.py", line 256, in _create_connection
    return _ConnectionRecord(self)
  File "/home/airflow/.local/lib/python3.7/site-packages/sqlalchemy/pool/base.py", line 371, in __init__
    self.__connect()
  File "/home/airflow/.local/lib/python3.7/site-packages/sqlalchemy/pool/base.py", line 666, in __connect
    pool.logger.debug("Error on connect(): %s", e)
  File "/home/airflow/.local/lib/python3.7/site-packages/sqlalchemy/util/langhelpers.py", line 72, in __exit__
    with_traceback=exc_tb,
  File "/home/airflow/.local/lib/python3.7/site-packages/sqlalchemy/util/compat.py", line 207, in raise_
    raise exception
  File "/home/airflow/.local/lib/python3.7/site-packages/sqlalchemy/pool/base.py", line 661, in __connect
    self.dbapi_connection = connection = pool._invoke_creator(self)
  File "/home/airflow/.local/lib/python3.7/site-packages/sqlalchemy/engine/create.py", line 590, in connect
    return dialect.connect(*cargs, **cparams)
  File "/home/airflow/.local/lib/python3.7/site-packages/sqlalchemy/engine/default.py", line 584, in connect
    return self.dbapi.connect(*cargs, **cparams)
  File "/home/airflow/.local/lib/python3.7/site-packages/psycopg2/__init__.py", line 122, in connect
    conn = _connect(dsn, connection_factory=connection_factory, **kwasync)
psycopg2.OperationalError: connection to server at "localhost" (127.0.0.1), port 5432 failed: Connection refused
	Is the server running on that host and accepting TCP/IP connections?
connection to server at "localhost" (::1), port 5432 failed: Cannot assign requested address
	Is the server running on that host and accepting TCP/IP connections?


The above exception was the direct cause of the following exception:

Traceback (most recent call last):
  File "/home/airflow/.local/lib/python3.7/site-packages/airflow/models/dagbag.py", line 318, in parse
    loader.exec_module(new_module)
  File "<frozen importlib._bootstrap_external>", line 728, in exec_module
  File "<frozen importlib._bootstrap>", line 219, in _call_with_frames_removed
  File "/opt/airflow/dags/dbConnector.py", line 21, in <module>
    load_into_database()
  File "/opt/airflow/dags/dbConnector.py", line 10, in load_into_database
    data.to_sql('satellitedata', engine, index=False, if_exists='append')
  File "/home/airflow/.local/lib/python3.7/site-packages/pandas/core/generic.py", line 2882, in to_sql
    method=method,
  File "/home/airflow/.local/lib/python3.7/site-packages/pandas/io/sql.py", line 728, in to_sql
    **engine_kwargs,
  File "/home/airflow/.local/lib/python3.7/site-packages/pandas/io/sql.py", line 1758, in to_sql
    dtype=dtype,
  File "/home/airflow/.local/lib/python3.7/site-packages/pandas/io/sql.py", line 1650, in prep_table
    table.create()
  File "/home/airflow/.local/lib/python3.7/site-packages/pandas/io/sql.py", line 856, in create
    if self.exists():
  File "/home/airflow/.local/lib/python3.7/site-packages/pandas/io/sql.py", line 840, in exists
    return self.pd_sql.has_table(self.name, self.schema)
  File "/home/airflow/.local/lib/python3.7/site-packages/pandas/io/sql.py", line 1783, in has_table
    insp = sa.inspect(self.connectable)
  File "/home/airflow/.local/lib/python3.7/site-packages/sqlalchemy/inspection.py", line 64, in inspect
    ret = reg(subject)
  File "/home/airflow/.local/lib/python3.7/site-packages/sqlalchemy/engine/reflection.py", line 182, in _engine_insp
    return Inspector._construct(Inspector._init_engine, bind)
  File "/home/airflow/.local/lib/python3.7/site-packages/sqlalchemy/engine/reflection.py", line 117, in _construct
    init(self, bind)
  File "/home/airflow/.local/lib/python3.7/site-packages/sqlalchemy/engine/reflection.py", line 128, in _init_engine
    engine.connect().close()
  File "/home/airflow/.local/lib/python3.7/site-packages/sqlalchemy/engine/base.py", line 3197, in connect
    return self._connection_cls(self, close_with_result=close_with_result)
  File "/home/airflow/.local/lib/python3.7/site-packages/sqlalchemy/engine/base.py", line 96, in __init__
    else engine.raw_connection()
  File "/home/airflow/.local/lib/python3.7/site-packages/sqlalchemy/engine/base.py", line 3276, in raw_connection
    return self._wrap_pool_connect(self.pool.connect, _connection)
  File "/home/airflow/.local/lib/python3.7/site-packages/sqlalchemy/engine/base.py", line 3247, in _wrap_pool_connect
    e, dialect, self
  File "/home/airflow/.local/lib/python3.7/site-packages/sqlalchemy/engine/base.py", line 2101, in _handle_dbapi_exception_noconnection
    sqlalchemy_exception, with_traceback=exc_info[2], from_=e
  File "/home/airflow/.local/lib/python3.7/site-packages/sqlalchemy/util/compat.py", line 207, in raise_
    raise exception
  File "/home/airflow/.local/lib/python3.7/site-packages/sqlalchemy/engine/base.py", line 3243, in _wrap_pool_connect
    return fn()
  File "/home/airflow/.local/lib/python3.7/site-packages/sqlalchemy/pool/base.py", line 310, in connect
    return _ConnectionFairy._checkout(self)
  File "/home/airflow/.local/lib/python3.7/site-packages/sqlalchemy/pool/base.py", line 868, in _checkout
    fairy = _ConnectionRecord.checkout(pool)
  File "/home/airflow/.local/lib/python3.7/site-packages/sqlalchemy/pool/base.py", line 476, in checkout
    rec = pool._do_get()
  File "/home/airflow/.local/lib/python3.7/site-packages/sqlalchemy/pool/impl.py", line 146, in _do_get
    self._dec_overflow()
  File "/home/airflow/.local/lib/python3.7/site-packages/sqlalchemy/util/langhelpers.py", line 72, in __exit__
    with_traceback=exc_tb,
  File "/home/airflow/.local/lib/python3.7/site-packages/sqlalchemy/util/compat.py", line 207, in raise_
    raise exception
  File "/home/airflow/.local/lib/python3.7/site-packages/sqlalchemy/pool/impl.py", line 143, in _do_get
    return self._create_connection()
  File "/home/airflow/.local/lib/python3.7/site-packages/sqlalchemy/pool/base.py", line 256, in _create_connection
    return _ConnectionRecord(self)
  File "/home/airflow/.local/lib/python3.7/site-packages/sqlalchemy/pool/base.py", line 371, in __init__
    self.__connect()
  File "/home/airflow/.local/lib/python3.7/site-packages/sqlalchemy/pool/base.py", line 666, in __connect
    pool.logger.debug("Error on connect(): %s", e)
  File "/home/airflow/.local/lib/python3.7/site-packages/sqlalchemy/util/langhelpers.py", line 72, in __exit__
    with_traceback=exc_tb,
  File "/home/airflow/.local/lib/python3.7/site-packages/sqlalchemy/util/compat.py", line 207, in raise_
    raise exception
  File "/home/airflow/.local/lib/python3.7/site-packages/sqlalchemy/pool/base.py", line 661, in __connect
    self.dbapi_connection = connection = pool._invoke_creator(self)
  File "/home/airflow/.local/lib/python3.7/site-packages/sqlalchemy/engine/create.py", line 590, in connect
    return dialect.connect(*cargs, **cparams)
  File "/home/airflow/.local/lib/python3.7/site-packages/sqlalchemy/engine/default.py", line 584, in connect
    return self.dbapi.connect(*cargs, **cparams)
  File "/home/airflow/.local/lib/python3.7/site-packages/psycopg2/__init__.py", line 122, in connect
    conn = _connect(dsn, connection_factory=connection_factory, **kwasync)
sqlalchemy.exc.OperationalError: (psycopg2.OperationalError) connection to server at "localhost" (127.0.0.1), port 5432 failed: Connection refused
	Is the server running on that host and accepting TCP/IP connections?
connection to server at "localhost" (::1), port 5432 failed: Cannot assign requested address
	Is the server running on that host and accepting TCP/IP connections?

(Background on this error at: https://sqlalche.me/e/14/e3q8)
[2022-08-18 16:36:04,556] {processor.py:653} WARNING - No viable dags retrieved from /opt/airflow/dags/dbConnector.py
[2022-08-18 16:36:04,585] {processor.py:161} INFO - Processing /opt/airflow/dags/dbConnector.py took 0.876 seconds
[2022-08-18 16:36:34,753] {processor.py:153} INFO - Started process (PID=1066) to work on /opt/airflow/dags/dbConnector.py
[2022-08-18 16:36:34,770] {processor.py:641} INFO - Processing file /opt/airflow/dags/dbConnector.py for tasks to queue
[2022-08-18 16:36:34,770] {logging_mixin.py:115} INFO - [2022-08-18 16:36:34,770] {dagbag.py:508} INFO - Filling up the DagBag from /opt/airflow/dags/dbConnector.py
[2022-08-18 16:36:35,595] {logging_mixin.py:115} INFO - [2022-08-18 16:36:35,590] {dagbag.py:321} ERROR - Failed to import: /opt/airflow/dags/dbConnector.py
Traceback (most recent call last):
  File "/home/airflow/.local/lib/python3.7/site-packages/sqlalchemy/engine/base.py", line 3243, in _wrap_pool_connect
    return fn()
  File "/home/airflow/.local/lib/python3.7/site-packages/sqlalchemy/pool/base.py", line 310, in connect
    return _ConnectionFairy._checkout(self)
  File "/home/airflow/.local/lib/python3.7/site-packages/sqlalchemy/pool/base.py", line 868, in _checkout
    fairy = _ConnectionRecord.checkout(pool)
  File "/home/airflow/.local/lib/python3.7/site-packages/sqlalchemy/pool/base.py", line 476, in checkout
    rec = pool._do_get()
  File "/home/airflow/.local/lib/python3.7/site-packages/sqlalchemy/pool/impl.py", line 146, in _do_get
    self._dec_overflow()
  File "/home/airflow/.local/lib/python3.7/site-packages/sqlalchemy/util/langhelpers.py", line 72, in __exit__
    with_traceback=exc_tb,
  File "/home/airflow/.local/lib/python3.7/site-packages/sqlalchemy/util/compat.py", line 207, in raise_
    raise exception
  File "/home/airflow/.local/lib/python3.7/site-packages/sqlalchemy/pool/impl.py", line 143, in _do_get
    return self._create_connection()
  File "/home/airflow/.local/lib/python3.7/site-packages/sqlalchemy/pool/base.py", line 256, in _create_connection
    return _ConnectionRecord(self)
  File "/home/airflow/.local/lib/python3.7/site-packages/sqlalchemy/pool/base.py", line 371, in __init__
    self.__connect()
  File "/home/airflow/.local/lib/python3.7/site-packages/sqlalchemy/pool/base.py", line 666, in __connect
    pool.logger.debug("Error on connect(): %s", e)
  File "/home/airflow/.local/lib/python3.7/site-packages/sqlalchemy/util/langhelpers.py", line 72, in __exit__
    with_traceback=exc_tb,
  File "/home/airflow/.local/lib/python3.7/site-packages/sqlalchemy/util/compat.py", line 207, in raise_
    raise exception
  File "/home/airflow/.local/lib/python3.7/site-packages/sqlalchemy/pool/base.py", line 661, in __connect
    self.dbapi_connection = connection = pool._invoke_creator(self)
  File "/home/airflow/.local/lib/python3.7/site-packages/sqlalchemy/engine/create.py", line 590, in connect
    return dialect.connect(*cargs, **cparams)
  File "/home/airflow/.local/lib/python3.7/site-packages/sqlalchemy/engine/default.py", line 584, in connect
    return self.dbapi.connect(*cargs, **cparams)
  File "/home/airflow/.local/lib/python3.7/site-packages/psycopg2/__init__.py", line 122, in connect
    conn = _connect(dsn, connection_factory=connection_factory, **kwasync)
psycopg2.OperationalError: connection to server at "localhost" (127.0.0.1), port 5432 failed: Connection refused
	Is the server running on that host and accepting TCP/IP connections?
connection to server at "localhost" (::1), port 5432 failed: Cannot assign requested address
	Is the server running on that host and accepting TCP/IP connections?


The above exception was the direct cause of the following exception:

Traceback (most recent call last):
  File "/home/airflow/.local/lib/python3.7/site-packages/airflow/models/dagbag.py", line 318, in parse
    loader.exec_module(new_module)
  File "<frozen importlib._bootstrap_external>", line 728, in exec_module
  File "<frozen importlib._bootstrap>", line 219, in _call_with_frames_removed
  File "/opt/airflow/dags/dbConnector.py", line 21, in <module>
    load_into_database()
  File "/opt/airflow/dags/dbConnector.py", line 10, in load_into_database
    data.to_sql('satellitedata', engine, index=False, if_exists='append')
  File "/home/airflow/.local/lib/python3.7/site-packages/pandas/core/generic.py", line 2882, in to_sql
    method=method,
  File "/home/airflow/.local/lib/python3.7/site-packages/pandas/io/sql.py", line 728, in to_sql
    **engine_kwargs,
  File "/home/airflow/.local/lib/python3.7/site-packages/pandas/io/sql.py", line 1758, in to_sql
    dtype=dtype,
  File "/home/airflow/.local/lib/python3.7/site-packages/pandas/io/sql.py", line 1650, in prep_table
    table.create()
  File "/home/airflow/.local/lib/python3.7/site-packages/pandas/io/sql.py", line 856, in create
    if self.exists():
  File "/home/airflow/.local/lib/python3.7/site-packages/pandas/io/sql.py", line 840, in exists
    return self.pd_sql.has_table(self.name, self.schema)
  File "/home/airflow/.local/lib/python3.7/site-packages/pandas/io/sql.py", line 1783, in has_table
    insp = sa.inspect(self.connectable)
  File "/home/airflow/.local/lib/python3.7/site-packages/sqlalchemy/inspection.py", line 64, in inspect
    ret = reg(subject)
  File "/home/airflow/.local/lib/python3.7/site-packages/sqlalchemy/engine/reflection.py", line 182, in _engine_insp
    return Inspector._construct(Inspector._init_engine, bind)
  File "/home/airflow/.local/lib/python3.7/site-packages/sqlalchemy/engine/reflection.py", line 117, in _construct
    init(self, bind)
  File "/home/airflow/.local/lib/python3.7/site-packages/sqlalchemy/engine/reflection.py", line 128, in _init_engine
    engine.connect().close()
  File "/home/airflow/.local/lib/python3.7/site-packages/sqlalchemy/engine/base.py", line 3197, in connect
    return self._connection_cls(self, close_with_result=close_with_result)
  File "/home/airflow/.local/lib/python3.7/site-packages/sqlalchemy/engine/base.py", line 96, in __init__
    else engine.raw_connection()
  File "/home/airflow/.local/lib/python3.7/site-packages/sqlalchemy/engine/base.py", line 3276, in raw_connection
    return self._wrap_pool_connect(self.pool.connect, _connection)
  File "/home/airflow/.local/lib/python3.7/site-packages/sqlalchemy/engine/base.py", line 3247, in _wrap_pool_connect
    e, dialect, self
  File "/home/airflow/.local/lib/python3.7/site-packages/sqlalchemy/engine/base.py", line 2101, in _handle_dbapi_exception_noconnection
    sqlalchemy_exception, with_traceback=exc_info[2], from_=e
  File "/home/airflow/.local/lib/python3.7/site-packages/sqlalchemy/util/compat.py", line 207, in raise_
    raise exception
  File "/home/airflow/.local/lib/python3.7/site-packages/sqlalchemy/engine/base.py", line 3243, in _wrap_pool_connect
    return fn()
  File "/home/airflow/.local/lib/python3.7/site-packages/sqlalchemy/pool/base.py", line 310, in connect
    return _ConnectionFairy._checkout(self)
  File "/home/airflow/.local/lib/python3.7/site-packages/sqlalchemy/pool/base.py", line 868, in _checkout
    fairy = _ConnectionRecord.checkout(pool)
  File "/home/airflow/.local/lib/python3.7/site-packages/sqlalchemy/pool/base.py", line 476, in checkout
    rec = pool._do_get()
  File "/home/airflow/.local/lib/python3.7/site-packages/sqlalchemy/pool/impl.py", line 146, in _do_get
    self._dec_overflow()
  File "/home/airflow/.local/lib/python3.7/site-packages/sqlalchemy/util/langhelpers.py", line 72, in __exit__
    with_traceback=exc_tb,
  File "/home/airflow/.local/lib/python3.7/site-packages/sqlalchemy/util/compat.py", line 207, in raise_
    raise exception
  File "/home/airflow/.local/lib/python3.7/site-packages/sqlalchemy/pool/impl.py", line 143, in _do_get
    return self._create_connection()
  File "/home/airflow/.local/lib/python3.7/site-packages/sqlalchemy/pool/base.py", line 256, in _create_connection
    return _ConnectionRecord(self)
  File "/home/airflow/.local/lib/python3.7/site-packages/sqlalchemy/pool/base.py", line 371, in __init__
    self.__connect()
  File "/home/airflow/.local/lib/python3.7/site-packages/sqlalchemy/pool/base.py", line 666, in __connect
    pool.logger.debug("Error on connect(): %s", e)
  File "/home/airflow/.local/lib/python3.7/site-packages/sqlalchemy/util/langhelpers.py", line 72, in __exit__
    with_traceback=exc_tb,
  File "/home/airflow/.local/lib/python3.7/site-packages/sqlalchemy/util/compat.py", line 207, in raise_
    raise exception
  File "/home/airflow/.local/lib/python3.7/site-packages/sqlalchemy/pool/base.py", line 661, in __connect
    self.dbapi_connection = connection = pool._invoke_creator(self)
  File "/home/airflow/.local/lib/python3.7/site-packages/sqlalchemy/engine/create.py", line 590, in connect
    return dialect.connect(*cargs, **cparams)
  File "/home/airflow/.local/lib/python3.7/site-packages/sqlalchemy/engine/default.py", line 584, in connect
    return self.dbapi.connect(*cargs, **cparams)
  File "/home/airflow/.local/lib/python3.7/site-packages/psycopg2/__init__.py", line 122, in connect
    conn = _connect(dsn, connection_factory=connection_factory, **kwasync)
sqlalchemy.exc.OperationalError: (psycopg2.OperationalError) connection to server at "localhost" (127.0.0.1), port 5432 failed: Connection refused
	Is the server running on that host and accepting TCP/IP connections?
connection to server at "localhost" (::1), port 5432 failed: Cannot assign requested address
	Is the server running on that host and accepting TCP/IP connections?

(Background on this error at: https://sqlalche.me/e/14/e3q8)
[2022-08-18 16:36:35,595] {processor.py:653} WARNING - No viable dags retrieved from /opt/airflow/dags/dbConnector.py
[2022-08-18 16:36:35,643] {processor.py:161} INFO - Processing /opt/airflow/dags/dbConnector.py took 0.894 seconds
[2022-08-18 16:37:05,743] {processor.py:153} INFO - Started process (PID=1098) to work on /opt/airflow/dags/dbConnector.py
[2022-08-18 16:37:05,749] {processor.py:641} INFO - Processing file /opt/airflow/dags/dbConnector.py for tasks to queue
[2022-08-18 16:37:05,749] {logging_mixin.py:115} INFO - [2022-08-18 16:37:05,749] {dagbag.py:508} INFO - Filling up the DagBag from /opt/airflow/dags/dbConnector.py
[2022-08-18 16:37:06,583] {logging_mixin.py:115} INFO - [2022-08-18 16:37:06,579] {dagbag.py:321} ERROR - Failed to import: /opt/airflow/dags/dbConnector.py
Traceback (most recent call last):
  File "/home/airflow/.local/lib/python3.7/site-packages/sqlalchemy/engine/base.py", line 3243, in _wrap_pool_connect
    return fn()
  File "/home/airflow/.local/lib/python3.7/site-packages/sqlalchemy/pool/base.py", line 310, in connect
    return _ConnectionFairy._checkout(self)
  File "/home/airflow/.local/lib/python3.7/site-packages/sqlalchemy/pool/base.py", line 868, in _checkout
    fairy = _ConnectionRecord.checkout(pool)
  File "/home/airflow/.local/lib/python3.7/site-packages/sqlalchemy/pool/base.py", line 476, in checkout
    rec = pool._do_get()
  File "/home/airflow/.local/lib/python3.7/site-packages/sqlalchemy/pool/impl.py", line 146, in _do_get
    self._dec_overflow()
  File "/home/airflow/.local/lib/python3.7/site-packages/sqlalchemy/util/langhelpers.py", line 72, in __exit__
    with_traceback=exc_tb,
  File "/home/airflow/.local/lib/python3.7/site-packages/sqlalchemy/util/compat.py", line 207, in raise_
    raise exception
  File "/home/airflow/.local/lib/python3.7/site-packages/sqlalchemy/pool/impl.py", line 143, in _do_get
    return self._create_connection()
  File "/home/airflow/.local/lib/python3.7/site-packages/sqlalchemy/pool/base.py", line 256, in _create_connection
    return _ConnectionRecord(self)
  File "/home/airflow/.local/lib/python3.7/site-packages/sqlalchemy/pool/base.py", line 371, in __init__
    self.__connect()
  File "/home/airflow/.local/lib/python3.7/site-packages/sqlalchemy/pool/base.py", line 666, in __connect
    pool.logger.debug("Error on connect(): %s", e)
  File "/home/airflow/.local/lib/python3.7/site-packages/sqlalchemy/util/langhelpers.py", line 72, in __exit__
    with_traceback=exc_tb,
  File "/home/airflow/.local/lib/python3.7/site-packages/sqlalchemy/util/compat.py", line 207, in raise_
    raise exception
  File "/home/airflow/.local/lib/python3.7/site-packages/sqlalchemy/pool/base.py", line 661, in __connect
    self.dbapi_connection = connection = pool._invoke_creator(self)
  File "/home/airflow/.local/lib/python3.7/site-packages/sqlalchemy/engine/create.py", line 590, in connect
    return dialect.connect(*cargs, **cparams)
  File "/home/airflow/.local/lib/python3.7/site-packages/sqlalchemy/engine/default.py", line 584, in connect
    return self.dbapi.connect(*cargs, **cparams)
  File "/home/airflow/.local/lib/python3.7/site-packages/psycopg2/__init__.py", line 122, in connect
    conn = _connect(dsn, connection_factory=connection_factory, **kwasync)
psycopg2.OperationalError: connection to server at "localhost" (127.0.0.1), port 5432 failed: Connection refused
	Is the server running on that host and accepting TCP/IP connections?
connection to server at "localhost" (::1), port 5432 failed: Cannot assign requested address
	Is the server running on that host and accepting TCP/IP connections?


The above exception was the direct cause of the following exception:

Traceback (most recent call last):
  File "/home/airflow/.local/lib/python3.7/site-packages/airflow/models/dagbag.py", line 318, in parse
    loader.exec_module(new_module)
  File "<frozen importlib._bootstrap_external>", line 728, in exec_module
  File "<frozen importlib._bootstrap>", line 219, in _call_with_frames_removed
  File "/opt/airflow/dags/dbConnector.py", line 21, in <module>
    load_into_database()
  File "/opt/airflow/dags/dbConnector.py", line 10, in load_into_database
    data.to_sql('satellitedata', engine, index=False, if_exists='append')
  File "/home/airflow/.local/lib/python3.7/site-packages/pandas/core/generic.py", line 2882, in to_sql
    method=method,
  File "/home/airflow/.local/lib/python3.7/site-packages/pandas/io/sql.py", line 728, in to_sql
    **engine_kwargs,
  File "/home/airflow/.local/lib/python3.7/site-packages/pandas/io/sql.py", line 1758, in to_sql
    dtype=dtype,
  File "/home/airflow/.local/lib/python3.7/site-packages/pandas/io/sql.py", line 1650, in prep_table
    table.create()
  File "/home/airflow/.local/lib/python3.7/site-packages/pandas/io/sql.py", line 856, in create
    if self.exists():
  File "/home/airflow/.local/lib/python3.7/site-packages/pandas/io/sql.py", line 840, in exists
    return self.pd_sql.has_table(self.name, self.schema)
  File "/home/airflow/.local/lib/python3.7/site-packages/pandas/io/sql.py", line 1783, in has_table
    insp = sa.inspect(self.connectable)
  File "/home/airflow/.local/lib/python3.7/site-packages/sqlalchemy/inspection.py", line 64, in inspect
    ret = reg(subject)
  File "/home/airflow/.local/lib/python3.7/site-packages/sqlalchemy/engine/reflection.py", line 182, in _engine_insp
    return Inspector._construct(Inspector._init_engine, bind)
  File "/home/airflow/.local/lib/python3.7/site-packages/sqlalchemy/engine/reflection.py", line 117, in _construct
    init(self, bind)
  File "/home/airflow/.local/lib/python3.7/site-packages/sqlalchemy/engine/reflection.py", line 128, in _init_engine
    engine.connect().close()
  File "/home/airflow/.local/lib/python3.7/site-packages/sqlalchemy/engine/base.py", line 3197, in connect
    return self._connection_cls(self, close_with_result=close_with_result)
  File "/home/airflow/.local/lib/python3.7/site-packages/sqlalchemy/engine/base.py", line 96, in __init__
    else engine.raw_connection()
  File "/home/airflow/.local/lib/python3.7/site-packages/sqlalchemy/engine/base.py", line 3276, in raw_connection
    return self._wrap_pool_connect(self.pool.connect, _connection)
  File "/home/airflow/.local/lib/python3.7/site-packages/sqlalchemy/engine/base.py", line 3247, in _wrap_pool_connect
    e, dialect, self
  File "/home/airflow/.local/lib/python3.7/site-packages/sqlalchemy/engine/base.py", line 2101, in _handle_dbapi_exception_noconnection
    sqlalchemy_exception, with_traceback=exc_info[2], from_=e
  File "/home/airflow/.local/lib/python3.7/site-packages/sqlalchemy/util/compat.py", line 207, in raise_
    raise exception
  File "/home/airflow/.local/lib/python3.7/site-packages/sqlalchemy/engine/base.py", line 3243, in _wrap_pool_connect
    return fn()
  File "/home/airflow/.local/lib/python3.7/site-packages/sqlalchemy/pool/base.py", line 310, in connect
    return _ConnectionFairy._checkout(self)
  File "/home/airflow/.local/lib/python3.7/site-packages/sqlalchemy/pool/base.py", line 868, in _checkout
    fairy = _ConnectionRecord.checkout(pool)
  File "/home/airflow/.local/lib/python3.7/site-packages/sqlalchemy/pool/base.py", line 476, in checkout
    rec = pool._do_get()
  File "/home/airflow/.local/lib/python3.7/site-packages/sqlalchemy/pool/impl.py", line 146, in _do_get
    self._dec_overflow()
  File "/home/airflow/.local/lib/python3.7/site-packages/sqlalchemy/util/langhelpers.py", line 72, in __exit__
    with_traceback=exc_tb,
  File "/home/airflow/.local/lib/python3.7/site-packages/sqlalchemy/util/compat.py", line 207, in raise_
    raise exception
  File "/home/airflow/.local/lib/python3.7/site-packages/sqlalchemy/pool/impl.py", line 143, in _do_get
    return self._create_connection()
  File "/home/airflow/.local/lib/python3.7/site-packages/sqlalchemy/pool/base.py", line 256, in _create_connection
    return _ConnectionRecord(self)
  File "/home/airflow/.local/lib/python3.7/site-packages/sqlalchemy/pool/base.py", line 371, in __init__
    self.__connect()
  File "/home/airflow/.local/lib/python3.7/site-packages/sqlalchemy/pool/base.py", line 666, in __connect
    pool.logger.debug("Error on connect(): %s", e)
  File "/home/airflow/.local/lib/python3.7/site-packages/sqlalchemy/util/langhelpers.py", line 72, in __exit__
    with_traceback=exc_tb,
  File "/home/airflow/.local/lib/python3.7/site-packages/sqlalchemy/util/compat.py", line 207, in raise_
    raise exception
  File "/home/airflow/.local/lib/python3.7/site-packages/sqlalchemy/pool/base.py", line 661, in __connect
    self.dbapi_connection = connection = pool._invoke_creator(self)
  File "/home/airflow/.local/lib/python3.7/site-packages/sqlalchemy/engine/create.py", line 590, in connect
    return dialect.connect(*cargs, **cparams)
  File "/home/airflow/.local/lib/python3.7/site-packages/sqlalchemy/engine/default.py", line 584, in connect
    return self.dbapi.connect(*cargs, **cparams)
  File "/home/airflow/.local/lib/python3.7/site-packages/psycopg2/__init__.py", line 122, in connect
    conn = _connect(dsn, connection_factory=connection_factory, **kwasync)
sqlalchemy.exc.OperationalError: (psycopg2.OperationalError) connection to server at "localhost" (127.0.0.1), port 5432 failed: Connection refused
	Is the server running on that host and accepting TCP/IP connections?
connection to server at "localhost" (::1), port 5432 failed: Cannot assign requested address
	Is the server running on that host and accepting TCP/IP connections?

(Background on this error at: https://sqlalche.me/e/14/e3q8)
[2022-08-18 16:37:06,583] {processor.py:653} WARNING - No viable dags retrieved from /opt/airflow/dags/dbConnector.py
[2022-08-18 16:37:06,649] {processor.py:161} INFO - Processing /opt/airflow/dags/dbConnector.py took 0.910 seconds
[2022-08-18 16:37:36,769] {processor.py:153} INFO - Started process (PID=1129) to work on /opt/airflow/dags/dbConnector.py
[2022-08-18 16:37:36,791] {processor.py:641} INFO - Processing file /opt/airflow/dags/dbConnector.py for tasks to queue
[2022-08-18 16:37:36,792] {logging_mixin.py:115} INFO - [2022-08-18 16:37:36,791] {dagbag.py:508} INFO - Filling up the DagBag from /opt/airflow/dags/dbConnector.py
[2022-08-18 16:37:37,642] {logging_mixin.py:115} INFO - [2022-08-18 16:37:37,637] {dagbag.py:321} ERROR - Failed to import: /opt/airflow/dags/dbConnector.py
Traceback (most recent call last):
  File "/home/airflow/.local/lib/python3.7/site-packages/sqlalchemy/engine/base.py", line 3243, in _wrap_pool_connect
    return fn()
  File "/home/airflow/.local/lib/python3.7/site-packages/sqlalchemy/pool/base.py", line 310, in connect
    return _ConnectionFairy._checkout(self)
  File "/home/airflow/.local/lib/python3.7/site-packages/sqlalchemy/pool/base.py", line 868, in _checkout
    fairy = _ConnectionRecord.checkout(pool)
  File "/home/airflow/.local/lib/python3.7/site-packages/sqlalchemy/pool/base.py", line 476, in checkout
    rec = pool._do_get()
  File "/home/airflow/.local/lib/python3.7/site-packages/sqlalchemy/pool/impl.py", line 146, in _do_get
    self._dec_overflow()
  File "/home/airflow/.local/lib/python3.7/site-packages/sqlalchemy/util/langhelpers.py", line 72, in __exit__
    with_traceback=exc_tb,
  File "/home/airflow/.local/lib/python3.7/site-packages/sqlalchemy/util/compat.py", line 207, in raise_
    raise exception
  File "/home/airflow/.local/lib/python3.7/site-packages/sqlalchemy/pool/impl.py", line 143, in _do_get
    return self._create_connection()
  File "/home/airflow/.local/lib/python3.7/site-packages/sqlalchemy/pool/base.py", line 256, in _create_connection
    return _ConnectionRecord(self)
  File "/home/airflow/.local/lib/python3.7/site-packages/sqlalchemy/pool/base.py", line 371, in __init__
    self.__connect()
  File "/home/airflow/.local/lib/python3.7/site-packages/sqlalchemy/pool/base.py", line 666, in __connect
    pool.logger.debug("Error on connect(): %s", e)
  File "/home/airflow/.local/lib/python3.7/site-packages/sqlalchemy/util/langhelpers.py", line 72, in __exit__
    with_traceback=exc_tb,
  File "/home/airflow/.local/lib/python3.7/site-packages/sqlalchemy/util/compat.py", line 207, in raise_
    raise exception
  File "/home/airflow/.local/lib/python3.7/site-packages/sqlalchemy/pool/base.py", line 661, in __connect
    self.dbapi_connection = connection = pool._invoke_creator(self)
  File "/home/airflow/.local/lib/python3.7/site-packages/sqlalchemy/engine/create.py", line 590, in connect
    return dialect.connect(*cargs, **cparams)
  File "/home/airflow/.local/lib/python3.7/site-packages/sqlalchemy/engine/default.py", line 584, in connect
    return self.dbapi.connect(*cargs, **cparams)
  File "/home/airflow/.local/lib/python3.7/site-packages/psycopg2/__init__.py", line 122, in connect
    conn = _connect(dsn, connection_factory=connection_factory, **kwasync)
psycopg2.OperationalError: connection to server at "localhost" (127.0.0.1), port 5432 failed: Connection refused
	Is the server running on that host and accepting TCP/IP connections?
connection to server at "localhost" (::1), port 5432 failed: Cannot assign requested address
	Is the server running on that host and accepting TCP/IP connections?


The above exception was the direct cause of the following exception:

Traceback (most recent call last):
  File "/home/airflow/.local/lib/python3.7/site-packages/airflow/models/dagbag.py", line 318, in parse
    loader.exec_module(new_module)
  File "<frozen importlib._bootstrap_external>", line 728, in exec_module
  File "<frozen importlib._bootstrap>", line 219, in _call_with_frames_removed
  File "/opt/airflow/dags/dbConnector.py", line 21, in <module>
    load_into_database()
  File "/opt/airflow/dags/dbConnector.py", line 10, in load_into_database
    data.to_sql('satellitedata', engine, index=False, if_exists='append')
  File "/home/airflow/.local/lib/python3.7/site-packages/pandas/core/generic.py", line 2882, in to_sql
    method=method,
  File "/home/airflow/.local/lib/python3.7/site-packages/pandas/io/sql.py", line 728, in to_sql
    **engine_kwargs,
  File "/home/airflow/.local/lib/python3.7/site-packages/pandas/io/sql.py", line 1758, in to_sql
    dtype=dtype,
  File "/home/airflow/.local/lib/python3.7/site-packages/pandas/io/sql.py", line 1650, in prep_table
    table.create()
  File "/home/airflow/.local/lib/python3.7/site-packages/pandas/io/sql.py", line 856, in create
    if self.exists():
  File "/home/airflow/.local/lib/python3.7/site-packages/pandas/io/sql.py", line 840, in exists
    return self.pd_sql.has_table(self.name, self.schema)
  File "/home/airflow/.local/lib/python3.7/site-packages/pandas/io/sql.py", line 1783, in has_table
    insp = sa.inspect(self.connectable)
  File "/home/airflow/.local/lib/python3.7/site-packages/sqlalchemy/inspection.py", line 64, in inspect
    ret = reg(subject)
  File "/home/airflow/.local/lib/python3.7/site-packages/sqlalchemy/engine/reflection.py", line 182, in _engine_insp
    return Inspector._construct(Inspector._init_engine, bind)
  File "/home/airflow/.local/lib/python3.7/site-packages/sqlalchemy/engine/reflection.py", line 117, in _construct
    init(self, bind)
  File "/home/airflow/.local/lib/python3.7/site-packages/sqlalchemy/engine/reflection.py", line 128, in _init_engine
    engine.connect().close()
  File "/home/airflow/.local/lib/python3.7/site-packages/sqlalchemy/engine/base.py", line 3197, in connect
    return self._connection_cls(self, close_with_result=close_with_result)
  File "/home/airflow/.local/lib/python3.7/site-packages/sqlalchemy/engine/base.py", line 96, in __init__
    else engine.raw_connection()
  File "/home/airflow/.local/lib/python3.7/site-packages/sqlalchemy/engine/base.py", line 3276, in raw_connection
    return self._wrap_pool_connect(self.pool.connect, _connection)
  File "/home/airflow/.local/lib/python3.7/site-packages/sqlalchemy/engine/base.py", line 3247, in _wrap_pool_connect
    e, dialect, self
  File "/home/airflow/.local/lib/python3.7/site-packages/sqlalchemy/engine/base.py", line 2101, in _handle_dbapi_exception_noconnection
    sqlalchemy_exception, with_traceback=exc_info[2], from_=e
  File "/home/airflow/.local/lib/python3.7/site-packages/sqlalchemy/util/compat.py", line 207, in raise_
    raise exception
  File "/home/airflow/.local/lib/python3.7/site-packages/sqlalchemy/engine/base.py", line 3243, in _wrap_pool_connect
    return fn()
  File "/home/airflow/.local/lib/python3.7/site-packages/sqlalchemy/pool/base.py", line 310, in connect
    return _ConnectionFairy._checkout(self)
  File "/home/airflow/.local/lib/python3.7/site-packages/sqlalchemy/pool/base.py", line 868, in _checkout
    fairy = _ConnectionRecord.checkout(pool)
  File "/home/airflow/.local/lib/python3.7/site-packages/sqlalchemy/pool/base.py", line 476, in checkout
    rec = pool._do_get()
  File "/home/airflow/.local/lib/python3.7/site-packages/sqlalchemy/pool/impl.py", line 146, in _do_get
    self._dec_overflow()
  File "/home/airflow/.local/lib/python3.7/site-packages/sqlalchemy/util/langhelpers.py", line 72, in __exit__
    with_traceback=exc_tb,
  File "/home/airflow/.local/lib/python3.7/site-packages/sqlalchemy/util/compat.py", line 207, in raise_
    raise exception
  File "/home/airflow/.local/lib/python3.7/site-packages/sqlalchemy/pool/impl.py", line 143, in _do_get
    return self._create_connection()
  File "/home/airflow/.local/lib/python3.7/site-packages/sqlalchemy/pool/base.py", line 256, in _create_connection
    return _ConnectionRecord(self)
  File "/home/airflow/.local/lib/python3.7/site-packages/sqlalchemy/pool/base.py", line 371, in __init__
    self.__connect()
  File "/home/airflow/.local/lib/python3.7/site-packages/sqlalchemy/pool/base.py", line 666, in __connect
    pool.logger.debug("Error on connect(): %s", e)
  File "/home/airflow/.local/lib/python3.7/site-packages/sqlalchemy/util/langhelpers.py", line 72, in __exit__
    with_traceback=exc_tb,
  File "/home/airflow/.local/lib/python3.7/site-packages/sqlalchemy/util/compat.py", line 207, in raise_
    raise exception
  File "/home/airflow/.local/lib/python3.7/site-packages/sqlalchemy/pool/base.py", line 661, in __connect
    self.dbapi_connection = connection = pool._invoke_creator(self)
  File "/home/airflow/.local/lib/python3.7/site-packages/sqlalchemy/engine/create.py", line 590, in connect
    return dialect.connect(*cargs, **cparams)
  File "/home/airflow/.local/lib/python3.7/site-packages/sqlalchemy/engine/default.py", line 584, in connect
    return self.dbapi.connect(*cargs, **cparams)
  File "/home/airflow/.local/lib/python3.7/site-packages/psycopg2/__init__.py", line 122, in connect
    conn = _connect(dsn, connection_factory=connection_factory, **kwasync)
sqlalchemy.exc.OperationalError: (psycopg2.OperationalError) connection to server at "localhost" (127.0.0.1), port 5432 failed: Connection refused
	Is the server running on that host and accepting TCP/IP connections?
connection to server at "localhost" (::1), port 5432 failed: Cannot assign requested address
	Is the server running on that host and accepting TCP/IP connections?

(Background on this error at: https://sqlalche.me/e/14/e3q8)
[2022-08-18 16:37:37,642] {processor.py:653} WARNING - No viable dags retrieved from /opt/airflow/dags/dbConnector.py
[2022-08-18 16:37:37,743] {processor.py:161} INFO - Processing /opt/airflow/dags/dbConnector.py took 0.979 seconds
[2022-08-18 16:37:47,888] {processor.py:153} INFO - Started process (PID=1142) to work on /opt/airflow/dags/dbConnector.py
[2022-08-18 16:37:47,903] {processor.py:641} INFO - Processing file /opt/airflow/dags/dbConnector.py for tasks to queue
[2022-08-18 16:37:47,904] {logging_mixin.py:115} INFO - [2022-08-18 16:37:47,904] {dagbag.py:508} INFO - Filling up the DagBag from /opt/airflow/dags/dbConnector.py
[2022-08-18 16:37:48,797] {logging_mixin.py:115} INFO - [2022-08-18 16:37:48,793] {dagbag.py:321} ERROR - Failed to import: /opt/airflow/dags/dbConnector.py
Traceback (most recent call last):
  File "/home/airflow/.local/lib/python3.7/site-packages/sqlalchemy/engine/base.py", line 3243, in _wrap_pool_connect
    return fn()
  File "/home/airflow/.local/lib/python3.7/site-packages/sqlalchemy/pool/base.py", line 310, in connect
    return _ConnectionFairy._checkout(self)
  File "/home/airflow/.local/lib/python3.7/site-packages/sqlalchemy/pool/base.py", line 868, in _checkout
    fairy = _ConnectionRecord.checkout(pool)
  File "/home/airflow/.local/lib/python3.7/site-packages/sqlalchemy/pool/base.py", line 476, in checkout
    rec = pool._do_get()
  File "/home/airflow/.local/lib/python3.7/site-packages/sqlalchemy/pool/impl.py", line 146, in _do_get
    self._dec_overflow()
  File "/home/airflow/.local/lib/python3.7/site-packages/sqlalchemy/util/langhelpers.py", line 72, in __exit__
    with_traceback=exc_tb,
  File "/home/airflow/.local/lib/python3.7/site-packages/sqlalchemy/util/compat.py", line 207, in raise_
    raise exception
  File "/home/airflow/.local/lib/python3.7/site-packages/sqlalchemy/pool/impl.py", line 143, in _do_get
    return self._create_connection()
  File "/home/airflow/.local/lib/python3.7/site-packages/sqlalchemy/pool/base.py", line 256, in _create_connection
    return _ConnectionRecord(self)
  File "/home/airflow/.local/lib/python3.7/site-packages/sqlalchemy/pool/base.py", line 371, in __init__
    self.__connect()
  File "/home/airflow/.local/lib/python3.7/site-packages/sqlalchemy/pool/base.py", line 666, in __connect
    pool.logger.debug("Error on connect(): %s", e)
  File "/home/airflow/.local/lib/python3.7/site-packages/sqlalchemy/util/langhelpers.py", line 72, in __exit__
    with_traceback=exc_tb,
  File "/home/airflow/.local/lib/python3.7/site-packages/sqlalchemy/util/compat.py", line 207, in raise_
    raise exception
  File "/home/airflow/.local/lib/python3.7/site-packages/sqlalchemy/pool/base.py", line 661, in __connect
    self.dbapi_connection = connection = pool._invoke_creator(self)
  File "/home/airflow/.local/lib/python3.7/site-packages/sqlalchemy/engine/create.py", line 590, in connect
    return dialect.connect(*cargs, **cparams)
  File "/home/airflow/.local/lib/python3.7/site-packages/sqlalchemy/engine/default.py", line 584, in connect
    return self.dbapi.connect(*cargs, **cparams)
  File "/home/airflow/.local/lib/python3.7/site-packages/psycopg2/__init__.py", line 122, in connect
    conn = _connect(dsn, connection_factory=connection_factory, **kwasync)
psycopg2.OperationalError: connection to server at "localhost" (127.0.0.1), port 5432 failed: Connection refused
	Is the server running on that host and accepting TCP/IP connections?
connection to server at "localhost" (::1), port 5432 failed: Cannot assign requested address
	Is the server running on that host and accepting TCP/IP connections?


The above exception was the direct cause of the following exception:

Traceback (most recent call last):
  File "/home/airflow/.local/lib/python3.7/site-packages/airflow/models/dagbag.py", line 318, in parse
    loader.exec_module(new_module)
  File "<frozen importlib._bootstrap_external>", line 728, in exec_module
  File "<frozen importlib._bootstrap>", line 219, in _call_with_frames_removed
  File "/opt/airflow/dags/dbConnector.py", line 22, in <module>
    load_into_database(data)
  File "/opt/airflow/dags/dbConnector.py", line 10, in load_into_database
    data.to_sql('satellitedata', engine, index=False, if_exists='append')
  File "/home/airflow/.local/lib/python3.7/site-packages/pandas/core/generic.py", line 2882, in to_sql
    method=method,
  File "/home/airflow/.local/lib/python3.7/site-packages/pandas/io/sql.py", line 728, in to_sql
    **engine_kwargs,
  File "/home/airflow/.local/lib/python3.7/site-packages/pandas/io/sql.py", line 1758, in to_sql
    dtype=dtype,
  File "/home/airflow/.local/lib/python3.7/site-packages/pandas/io/sql.py", line 1650, in prep_table
    table.create()
  File "/home/airflow/.local/lib/python3.7/site-packages/pandas/io/sql.py", line 856, in create
    if self.exists():
  File "/home/airflow/.local/lib/python3.7/site-packages/pandas/io/sql.py", line 840, in exists
    return self.pd_sql.has_table(self.name, self.schema)
  File "/home/airflow/.local/lib/python3.7/site-packages/pandas/io/sql.py", line 1783, in has_table
    insp = sa.inspect(self.connectable)
  File "/home/airflow/.local/lib/python3.7/site-packages/sqlalchemy/inspection.py", line 64, in inspect
    ret = reg(subject)
  File "/home/airflow/.local/lib/python3.7/site-packages/sqlalchemy/engine/reflection.py", line 182, in _engine_insp
    return Inspector._construct(Inspector._init_engine, bind)
  File "/home/airflow/.local/lib/python3.7/site-packages/sqlalchemy/engine/reflection.py", line 117, in _construct
    init(self, bind)
  File "/home/airflow/.local/lib/python3.7/site-packages/sqlalchemy/engine/reflection.py", line 128, in _init_engine
    engine.connect().close()
  File "/home/airflow/.local/lib/python3.7/site-packages/sqlalchemy/engine/base.py", line 3197, in connect
    return self._connection_cls(self, close_with_result=close_with_result)
  File "/home/airflow/.local/lib/python3.7/site-packages/sqlalchemy/engine/base.py", line 96, in __init__
    else engine.raw_connection()
  File "/home/airflow/.local/lib/python3.7/site-packages/sqlalchemy/engine/base.py", line 3276, in raw_connection
    return self._wrap_pool_connect(self.pool.connect, _connection)
  File "/home/airflow/.local/lib/python3.7/site-packages/sqlalchemy/engine/base.py", line 3247, in _wrap_pool_connect
    e, dialect, self
  File "/home/airflow/.local/lib/python3.7/site-packages/sqlalchemy/engine/base.py", line 2101, in _handle_dbapi_exception_noconnection
    sqlalchemy_exception, with_traceback=exc_info[2], from_=e
  File "/home/airflow/.local/lib/python3.7/site-packages/sqlalchemy/util/compat.py", line 207, in raise_
    raise exception
  File "/home/airflow/.local/lib/python3.7/site-packages/sqlalchemy/engine/base.py", line 3243, in _wrap_pool_connect
    return fn()
  File "/home/airflow/.local/lib/python3.7/site-packages/sqlalchemy/pool/base.py", line 310, in connect
    return _ConnectionFairy._checkout(self)
  File "/home/airflow/.local/lib/python3.7/site-packages/sqlalchemy/pool/base.py", line 868, in _checkout
    fairy = _ConnectionRecord.checkout(pool)
  File "/home/airflow/.local/lib/python3.7/site-packages/sqlalchemy/pool/base.py", line 476, in checkout
    rec = pool._do_get()
  File "/home/airflow/.local/lib/python3.7/site-packages/sqlalchemy/pool/impl.py", line 146, in _do_get
    self._dec_overflow()
  File "/home/airflow/.local/lib/python3.7/site-packages/sqlalchemy/util/langhelpers.py", line 72, in __exit__
    with_traceback=exc_tb,
  File "/home/airflow/.local/lib/python3.7/site-packages/sqlalchemy/util/compat.py", line 207, in raise_
    raise exception
  File "/home/airflow/.local/lib/python3.7/site-packages/sqlalchemy/pool/impl.py", line 143, in _do_get
    return self._create_connection()
  File "/home/airflow/.local/lib/python3.7/site-packages/sqlalchemy/pool/base.py", line 256, in _create_connection
    return _ConnectionRecord(self)
  File "/home/airflow/.local/lib/python3.7/site-packages/sqlalchemy/pool/base.py", line 371, in __init__
    self.__connect()
  File "/home/airflow/.local/lib/python3.7/site-packages/sqlalchemy/pool/base.py", line 666, in __connect
    pool.logger.debug("Error on connect(): %s", e)
  File "/home/airflow/.local/lib/python3.7/site-packages/sqlalchemy/util/langhelpers.py", line 72, in __exit__
    with_traceback=exc_tb,
  File "/home/airflow/.local/lib/python3.7/site-packages/sqlalchemy/util/compat.py", line 207, in raise_
    raise exception
  File "/home/airflow/.local/lib/python3.7/site-packages/sqlalchemy/pool/base.py", line 661, in __connect
    self.dbapi_connection = connection = pool._invoke_creator(self)
  File "/home/airflow/.local/lib/python3.7/site-packages/sqlalchemy/engine/create.py", line 590, in connect
    return dialect.connect(*cargs, **cparams)
  File "/home/airflow/.local/lib/python3.7/site-packages/sqlalchemy/engine/default.py", line 584, in connect
    return self.dbapi.connect(*cargs, **cparams)
  File "/home/airflow/.local/lib/python3.7/site-packages/psycopg2/__init__.py", line 122, in connect
    conn = _connect(dsn, connection_factory=connection_factory, **kwasync)
sqlalchemy.exc.OperationalError: (psycopg2.OperationalError) connection to server at "localhost" (127.0.0.1), port 5432 failed: Connection refused
	Is the server running on that host and accepting TCP/IP connections?
connection to server at "localhost" (::1), port 5432 failed: Cannot assign requested address
	Is the server running on that host and accepting TCP/IP connections?

(Background on this error at: https://sqlalche.me/e/14/e3q8)
[2022-08-18 16:37:48,798] {processor.py:653} WARNING - No viable dags retrieved from /opt/airflow/dags/dbConnector.py
[2022-08-18 16:37:48,852] {processor.py:161} INFO - Processing /opt/airflow/dags/dbConnector.py took 0.968 seconds
[2022-08-18 16:38:18,940] {processor.py:153} INFO - Started process (PID=1166) to work on /opt/airflow/dags/dbConnector.py
[2022-08-18 16:38:18,946] {processor.py:641} INFO - Processing file /opt/airflow/dags/dbConnector.py for tasks to queue
[2022-08-18 16:38:18,946] {logging_mixin.py:115} INFO - [2022-08-18 16:38:18,946] {dagbag.py:508} INFO - Filling up the DagBag from /opt/airflow/dags/dbConnector.py
[2022-08-18 16:38:19,842] {logging_mixin.py:115} INFO - [2022-08-18 16:38:19,838] {dagbag.py:321} ERROR - Failed to import: /opt/airflow/dags/dbConnector.py
Traceback (most recent call last):
  File "/home/airflow/.local/lib/python3.7/site-packages/sqlalchemy/engine/base.py", line 3243, in _wrap_pool_connect
    return fn()
  File "/home/airflow/.local/lib/python3.7/site-packages/sqlalchemy/pool/base.py", line 310, in connect
    return _ConnectionFairy._checkout(self)
  File "/home/airflow/.local/lib/python3.7/site-packages/sqlalchemy/pool/base.py", line 868, in _checkout
    fairy = _ConnectionRecord.checkout(pool)
  File "/home/airflow/.local/lib/python3.7/site-packages/sqlalchemy/pool/base.py", line 476, in checkout
    rec = pool._do_get()
  File "/home/airflow/.local/lib/python3.7/site-packages/sqlalchemy/pool/impl.py", line 146, in _do_get
    self._dec_overflow()
  File "/home/airflow/.local/lib/python3.7/site-packages/sqlalchemy/util/langhelpers.py", line 72, in __exit__
    with_traceback=exc_tb,
  File "/home/airflow/.local/lib/python3.7/site-packages/sqlalchemy/util/compat.py", line 207, in raise_
    raise exception
  File "/home/airflow/.local/lib/python3.7/site-packages/sqlalchemy/pool/impl.py", line 143, in _do_get
    return self._create_connection()
  File "/home/airflow/.local/lib/python3.7/site-packages/sqlalchemy/pool/base.py", line 256, in _create_connection
    return _ConnectionRecord(self)
  File "/home/airflow/.local/lib/python3.7/site-packages/sqlalchemy/pool/base.py", line 371, in __init__
    self.__connect()
  File "/home/airflow/.local/lib/python3.7/site-packages/sqlalchemy/pool/base.py", line 666, in __connect
    pool.logger.debug("Error on connect(): %s", e)
  File "/home/airflow/.local/lib/python3.7/site-packages/sqlalchemy/util/langhelpers.py", line 72, in __exit__
    with_traceback=exc_tb,
  File "/home/airflow/.local/lib/python3.7/site-packages/sqlalchemy/util/compat.py", line 207, in raise_
    raise exception
  File "/home/airflow/.local/lib/python3.7/site-packages/sqlalchemy/pool/base.py", line 661, in __connect
    self.dbapi_connection = connection = pool._invoke_creator(self)
  File "/home/airflow/.local/lib/python3.7/site-packages/sqlalchemy/engine/create.py", line 590, in connect
    return dialect.connect(*cargs, **cparams)
  File "/home/airflow/.local/lib/python3.7/site-packages/sqlalchemy/engine/default.py", line 584, in connect
    return self.dbapi.connect(*cargs, **cparams)
  File "/home/airflow/.local/lib/python3.7/site-packages/psycopg2/__init__.py", line 122, in connect
    conn = _connect(dsn, connection_factory=connection_factory, **kwasync)
psycopg2.OperationalError: connection to server at "localhost" (127.0.0.1), port 5432 failed: Connection refused
	Is the server running on that host and accepting TCP/IP connections?
connection to server at "localhost" (::1), port 5432 failed: Cannot assign requested address
	Is the server running on that host and accepting TCP/IP connections?


The above exception was the direct cause of the following exception:

Traceback (most recent call last):
  File "/home/airflow/.local/lib/python3.7/site-packages/airflow/models/dagbag.py", line 318, in parse
    loader.exec_module(new_module)
  File "<frozen importlib._bootstrap_external>", line 728, in exec_module
  File "<frozen importlib._bootstrap>", line 219, in _call_with_frames_removed
  File "/opt/airflow/dags/dbConnector.py", line 22, in <module>
    load_into_database(data)
  File "/opt/airflow/dags/dbConnector.py", line 10, in load_into_database
    data.to_sql('satellitedata', engine, index=False, if_exists='append')
  File "/home/airflow/.local/lib/python3.7/site-packages/pandas/core/generic.py", line 2882, in to_sql
    method=method,
  File "/home/airflow/.local/lib/python3.7/site-packages/pandas/io/sql.py", line 728, in to_sql
    **engine_kwargs,
  File "/home/airflow/.local/lib/python3.7/site-packages/pandas/io/sql.py", line 1758, in to_sql
    dtype=dtype,
  File "/home/airflow/.local/lib/python3.7/site-packages/pandas/io/sql.py", line 1650, in prep_table
    table.create()
  File "/home/airflow/.local/lib/python3.7/site-packages/pandas/io/sql.py", line 856, in create
    if self.exists():
  File "/home/airflow/.local/lib/python3.7/site-packages/pandas/io/sql.py", line 840, in exists
    return self.pd_sql.has_table(self.name, self.schema)
  File "/home/airflow/.local/lib/python3.7/site-packages/pandas/io/sql.py", line 1783, in has_table
    insp = sa.inspect(self.connectable)
  File "/home/airflow/.local/lib/python3.7/site-packages/sqlalchemy/inspection.py", line 64, in inspect
    ret = reg(subject)
  File "/home/airflow/.local/lib/python3.7/site-packages/sqlalchemy/engine/reflection.py", line 182, in _engine_insp
    return Inspector._construct(Inspector._init_engine, bind)
  File "/home/airflow/.local/lib/python3.7/site-packages/sqlalchemy/engine/reflection.py", line 117, in _construct
    init(self, bind)
  File "/home/airflow/.local/lib/python3.7/site-packages/sqlalchemy/engine/reflection.py", line 128, in _init_engine
    engine.connect().close()
  File "/home/airflow/.local/lib/python3.7/site-packages/sqlalchemy/engine/base.py", line 3197, in connect
    return self._connection_cls(self, close_with_result=close_with_result)
  File "/home/airflow/.local/lib/python3.7/site-packages/sqlalchemy/engine/base.py", line 96, in __init__
    else engine.raw_connection()
  File "/home/airflow/.local/lib/python3.7/site-packages/sqlalchemy/engine/base.py", line 3276, in raw_connection
    return self._wrap_pool_connect(self.pool.connect, _connection)
  File "/home/airflow/.local/lib/python3.7/site-packages/sqlalchemy/engine/base.py", line 3247, in _wrap_pool_connect
    e, dialect, self
  File "/home/airflow/.local/lib/python3.7/site-packages/sqlalchemy/engine/base.py", line 2101, in _handle_dbapi_exception_noconnection
    sqlalchemy_exception, with_traceback=exc_info[2], from_=e
  File "/home/airflow/.local/lib/python3.7/site-packages/sqlalchemy/util/compat.py", line 207, in raise_
    raise exception
  File "/home/airflow/.local/lib/python3.7/site-packages/sqlalchemy/engine/base.py", line 3243, in _wrap_pool_connect
    return fn()
  File "/home/airflow/.local/lib/python3.7/site-packages/sqlalchemy/pool/base.py", line 310, in connect
    return _ConnectionFairy._checkout(self)
  File "/home/airflow/.local/lib/python3.7/site-packages/sqlalchemy/pool/base.py", line 868, in _checkout
    fairy = _ConnectionRecord.checkout(pool)
  File "/home/airflow/.local/lib/python3.7/site-packages/sqlalchemy/pool/base.py", line 476, in checkout
    rec = pool._do_get()
  File "/home/airflow/.local/lib/python3.7/site-packages/sqlalchemy/pool/impl.py", line 146, in _do_get
    self._dec_overflow()
  File "/home/airflow/.local/lib/python3.7/site-packages/sqlalchemy/util/langhelpers.py", line 72, in __exit__
    with_traceback=exc_tb,
  File "/home/airflow/.local/lib/python3.7/site-packages/sqlalchemy/util/compat.py", line 207, in raise_
    raise exception
  File "/home/airflow/.local/lib/python3.7/site-packages/sqlalchemy/pool/impl.py", line 143, in _do_get
    return self._create_connection()
  File "/home/airflow/.local/lib/python3.7/site-packages/sqlalchemy/pool/base.py", line 256, in _create_connection
    return _ConnectionRecord(self)
  File "/home/airflow/.local/lib/python3.7/site-packages/sqlalchemy/pool/base.py", line 371, in __init__
    self.__connect()
  File "/home/airflow/.local/lib/python3.7/site-packages/sqlalchemy/pool/base.py", line 666, in __connect
    pool.logger.debug("Error on connect(): %s", e)
  File "/home/airflow/.local/lib/python3.7/site-packages/sqlalchemy/util/langhelpers.py", line 72, in __exit__
    with_traceback=exc_tb,
  File "/home/airflow/.local/lib/python3.7/site-packages/sqlalchemy/util/compat.py", line 207, in raise_
    raise exception
  File "/home/airflow/.local/lib/python3.7/site-packages/sqlalchemy/pool/base.py", line 661, in __connect
    self.dbapi_connection = connection = pool._invoke_creator(self)
  File "/home/airflow/.local/lib/python3.7/site-packages/sqlalchemy/engine/create.py", line 590, in connect
    return dialect.connect(*cargs, **cparams)
  File "/home/airflow/.local/lib/python3.7/site-packages/sqlalchemy/engine/default.py", line 584, in connect
    return self.dbapi.connect(*cargs, **cparams)
  File "/home/airflow/.local/lib/python3.7/site-packages/psycopg2/__init__.py", line 122, in connect
    conn = _connect(dsn, connection_factory=connection_factory, **kwasync)
sqlalchemy.exc.OperationalError: (psycopg2.OperationalError) connection to server at "localhost" (127.0.0.1), port 5432 failed: Connection refused
	Is the server running on that host and accepting TCP/IP connections?
connection to server at "localhost" (::1), port 5432 failed: Cannot assign requested address
	Is the server running on that host and accepting TCP/IP connections?

(Background on this error at: https://sqlalche.me/e/14/e3q8)
[2022-08-18 16:38:19,843] {processor.py:653} WARNING - No viable dags retrieved from /opt/airflow/dags/dbConnector.py
[2022-08-18 16:38:19,875] {processor.py:161} INFO - Processing /opt/airflow/dags/dbConnector.py took 0.940 seconds
[2022-08-18 16:38:50,305] {processor.py:153} INFO - Started process (PID=1200) to work on /opt/airflow/dags/dbConnector.py
[2022-08-18 16:38:50,306] {processor.py:641} INFO - Processing file /opt/airflow/dags/dbConnector.py for tasks to queue
[2022-08-18 16:38:50,307] {logging_mixin.py:115} INFO - [2022-08-18 16:38:50,306] {dagbag.py:508} INFO - Filling up the DagBag from /opt/airflow/dags/dbConnector.py
[2022-08-18 16:38:51,100] {logging_mixin.py:115} INFO - [2022-08-18 16:38:51,096] {dagbag.py:321} ERROR - Failed to import: /opt/airflow/dags/dbConnector.py
Traceback (most recent call last):
  File "/home/airflow/.local/lib/python3.7/site-packages/sqlalchemy/engine/base.py", line 3243, in _wrap_pool_connect
    return fn()
  File "/home/airflow/.local/lib/python3.7/site-packages/sqlalchemy/pool/base.py", line 310, in connect
    return _ConnectionFairy._checkout(self)
  File "/home/airflow/.local/lib/python3.7/site-packages/sqlalchemy/pool/base.py", line 868, in _checkout
    fairy = _ConnectionRecord.checkout(pool)
  File "/home/airflow/.local/lib/python3.7/site-packages/sqlalchemy/pool/base.py", line 476, in checkout
    rec = pool._do_get()
  File "/home/airflow/.local/lib/python3.7/site-packages/sqlalchemy/pool/impl.py", line 146, in _do_get
    self._dec_overflow()
  File "/home/airflow/.local/lib/python3.7/site-packages/sqlalchemy/util/langhelpers.py", line 72, in __exit__
    with_traceback=exc_tb,
  File "/home/airflow/.local/lib/python3.7/site-packages/sqlalchemy/util/compat.py", line 207, in raise_
    raise exception
  File "/home/airflow/.local/lib/python3.7/site-packages/sqlalchemy/pool/impl.py", line 143, in _do_get
    return self._create_connection()
  File "/home/airflow/.local/lib/python3.7/site-packages/sqlalchemy/pool/base.py", line 256, in _create_connection
    return _ConnectionRecord(self)
  File "/home/airflow/.local/lib/python3.7/site-packages/sqlalchemy/pool/base.py", line 371, in __init__
    self.__connect()
  File "/home/airflow/.local/lib/python3.7/site-packages/sqlalchemy/pool/base.py", line 666, in __connect
    pool.logger.debug("Error on connect(): %s", e)
  File "/home/airflow/.local/lib/python3.7/site-packages/sqlalchemy/util/langhelpers.py", line 72, in __exit__
    with_traceback=exc_tb,
  File "/home/airflow/.local/lib/python3.7/site-packages/sqlalchemy/util/compat.py", line 207, in raise_
    raise exception
  File "/home/airflow/.local/lib/python3.7/site-packages/sqlalchemy/pool/base.py", line 661, in __connect
    self.dbapi_connection = connection = pool._invoke_creator(self)
  File "/home/airflow/.local/lib/python3.7/site-packages/sqlalchemy/engine/create.py", line 590, in connect
    return dialect.connect(*cargs, **cparams)
  File "/home/airflow/.local/lib/python3.7/site-packages/sqlalchemy/engine/default.py", line 584, in connect
    return self.dbapi.connect(*cargs, **cparams)
  File "/home/airflow/.local/lib/python3.7/site-packages/psycopg2/__init__.py", line 122, in connect
    conn = _connect(dsn, connection_factory=connection_factory, **kwasync)
psycopg2.OperationalError: connection to server at "localhost" (127.0.0.1), port 5432 failed: Connection refused
	Is the server running on that host and accepting TCP/IP connections?
connection to server at "localhost" (::1), port 5432 failed: Cannot assign requested address
	Is the server running on that host and accepting TCP/IP connections?


The above exception was the direct cause of the following exception:

Traceback (most recent call last):
  File "/home/airflow/.local/lib/python3.7/site-packages/airflow/models/dagbag.py", line 318, in parse
    loader.exec_module(new_module)
  File "<frozen importlib._bootstrap_external>", line 728, in exec_module
  File "<frozen importlib._bootstrap>", line 219, in _call_with_frames_removed
  File "/opt/airflow/dags/dbConnector.py", line 22, in <module>
    load_into_database(data)
  File "/opt/airflow/dags/dbConnector.py", line 10, in load_into_database
    data.to_sql('satellitedata', engine, index=False, if_exists='append')
  File "/home/airflow/.local/lib/python3.7/site-packages/pandas/core/generic.py", line 2882, in to_sql
    method=method,
  File "/home/airflow/.local/lib/python3.7/site-packages/pandas/io/sql.py", line 728, in to_sql
    **engine_kwargs,
  File "/home/airflow/.local/lib/python3.7/site-packages/pandas/io/sql.py", line 1758, in to_sql
    dtype=dtype,
  File "/home/airflow/.local/lib/python3.7/site-packages/pandas/io/sql.py", line 1650, in prep_table
    table.create()
  File "/home/airflow/.local/lib/python3.7/site-packages/pandas/io/sql.py", line 856, in create
    if self.exists():
  File "/home/airflow/.local/lib/python3.7/site-packages/pandas/io/sql.py", line 840, in exists
    return self.pd_sql.has_table(self.name, self.schema)
  File "/home/airflow/.local/lib/python3.7/site-packages/pandas/io/sql.py", line 1783, in has_table
    insp = sa.inspect(self.connectable)
  File "/home/airflow/.local/lib/python3.7/site-packages/sqlalchemy/inspection.py", line 64, in inspect
    ret = reg(subject)
  File "/home/airflow/.local/lib/python3.7/site-packages/sqlalchemy/engine/reflection.py", line 182, in _engine_insp
    return Inspector._construct(Inspector._init_engine, bind)
  File "/home/airflow/.local/lib/python3.7/site-packages/sqlalchemy/engine/reflection.py", line 117, in _construct
    init(self, bind)
  File "/home/airflow/.local/lib/python3.7/site-packages/sqlalchemy/engine/reflection.py", line 128, in _init_engine
    engine.connect().close()
  File "/home/airflow/.local/lib/python3.7/site-packages/sqlalchemy/engine/base.py", line 3197, in connect
    return self._connection_cls(self, close_with_result=close_with_result)
  File "/home/airflow/.local/lib/python3.7/site-packages/sqlalchemy/engine/base.py", line 96, in __init__
    else engine.raw_connection()
  File "/home/airflow/.local/lib/python3.7/site-packages/sqlalchemy/engine/base.py", line 3276, in raw_connection
    return self._wrap_pool_connect(self.pool.connect, _connection)
  File "/home/airflow/.local/lib/python3.7/site-packages/sqlalchemy/engine/base.py", line 3247, in _wrap_pool_connect
    e, dialect, self
  File "/home/airflow/.local/lib/python3.7/site-packages/sqlalchemy/engine/base.py", line 2101, in _handle_dbapi_exception_noconnection
    sqlalchemy_exception, with_traceback=exc_info[2], from_=e
  File "/home/airflow/.local/lib/python3.7/site-packages/sqlalchemy/util/compat.py", line 207, in raise_
    raise exception
  File "/home/airflow/.local/lib/python3.7/site-packages/sqlalchemy/engine/base.py", line 3243, in _wrap_pool_connect
    return fn()
  File "/home/airflow/.local/lib/python3.7/site-packages/sqlalchemy/pool/base.py", line 310, in connect
    return _ConnectionFairy._checkout(self)
  File "/home/airflow/.local/lib/python3.7/site-packages/sqlalchemy/pool/base.py", line 868, in _checkout
    fairy = _ConnectionRecord.checkout(pool)
  File "/home/airflow/.local/lib/python3.7/site-packages/sqlalchemy/pool/base.py", line 476, in checkout
    rec = pool._do_get()
  File "/home/airflow/.local/lib/python3.7/site-packages/sqlalchemy/pool/impl.py", line 146, in _do_get
    self._dec_overflow()
  File "/home/airflow/.local/lib/python3.7/site-packages/sqlalchemy/util/langhelpers.py", line 72, in __exit__
    with_traceback=exc_tb,
  File "/home/airflow/.local/lib/python3.7/site-packages/sqlalchemy/util/compat.py", line 207, in raise_
    raise exception
  File "/home/airflow/.local/lib/python3.7/site-packages/sqlalchemy/pool/impl.py", line 143, in _do_get
    return self._create_connection()
  File "/home/airflow/.local/lib/python3.7/site-packages/sqlalchemy/pool/base.py", line 256, in _create_connection
    return _ConnectionRecord(self)
  File "/home/airflow/.local/lib/python3.7/site-packages/sqlalchemy/pool/base.py", line 371, in __init__
    self.__connect()
  File "/home/airflow/.local/lib/python3.7/site-packages/sqlalchemy/pool/base.py", line 666, in __connect
    pool.logger.debug("Error on connect(): %s", e)
  File "/home/airflow/.local/lib/python3.7/site-packages/sqlalchemy/util/langhelpers.py", line 72, in __exit__
    with_traceback=exc_tb,
  File "/home/airflow/.local/lib/python3.7/site-packages/sqlalchemy/util/compat.py", line 207, in raise_
    raise exception
  File "/home/airflow/.local/lib/python3.7/site-packages/sqlalchemy/pool/base.py", line 661, in __connect
    self.dbapi_connection = connection = pool._invoke_creator(self)
  File "/home/airflow/.local/lib/python3.7/site-packages/sqlalchemy/engine/create.py", line 590, in connect
    return dialect.connect(*cargs, **cparams)
  File "/home/airflow/.local/lib/python3.7/site-packages/sqlalchemy/engine/default.py", line 584, in connect
    return self.dbapi.connect(*cargs, **cparams)
  File "/home/airflow/.local/lib/python3.7/site-packages/psycopg2/__init__.py", line 122, in connect
    conn = _connect(dsn, connection_factory=connection_factory, **kwasync)
sqlalchemy.exc.OperationalError: (psycopg2.OperationalError) connection to server at "localhost" (127.0.0.1), port 5432 failed: Connection refused
	Is the server running on that host and accepting TCP/IP connections?
connection to server at "localhost" (::1), port 5432 failed: Cannot assign requested address
	Is the server running on that host and accepting TCP/IP connections?

(Background on this error at: https://sqlalche.me/e/14/e3q8)
[2022-08-18 16:38:51,101] {processor.py:653} WARNING - No viable dags retrieved from /opt/airflow/dags/dbConnector.py
[2022-08-18 16:38:51,133] {processor.py:161} INFO - Processing /opt/airflow/dags/dbConnector.py took 0.832 seconds
[2022-08-18 16:39:21,864] {processor.py:153} INFO - Started process (PID=1231) to work on /opt/airflow/dags/dbConnector.py
[2022-08-18 16:39:21,885] {processor.py:641} INFO - Processing file /opt/airflow/dags/dbConnector.py for tasks to queue
[2022-08-18 16:39:21,886] {logging_mixin.py:115} INFO - [2022-08-18 16:39:21,885] {dagbag.py:508} INFO - Filling up the DagBag from /opt/airflow/dags/dbConnector.py
[2022-08-18 16:39:22,182] {logging_mixin.py:115} INFO - [2022-08-18 16:39:22,181] {dagbag.py:321} ERROR - Failed to import: /opt/airflow/dags/dbConnector.py
Traceback (most recent call last):
  File "/home/airflow/.local/lib/python3.7/site-packages/airflow/models/dagbag.py", line 318, in parse
    loader.exec_module(new_module)
  File "<frozen importlib._bootstrap_external>", line 728, in exec_module
  File "<frozen importlib._bootstrap>", line 219, in _call_with_frames_removed
  File "/opt/airflow/dags/dbConnector.py", line 23, in <module>
    data = pd.read_json('/home/L/Programming/dataEng/spaceApp/airflow/dags/tempSatelliteData.json')
  File "/home/airflow/.local/lib/python3.7/site-packages/pandas/util/_decorators.py", line 207, in wrapper
    return func(*args, **kwargs)
  File "/home/airflow/.local/lib/python3.7/site-packages/pandas/util/_decorators.py", line 311, in wrapper
    return func(*args, **kwargs)
  File "/home/airflow/.local/lib/python3.7/site-packages/pandas/io/json/_json.py", line 614, in read_json
    return json_reader.read()
  File "/home/airflow/.local/lib/python3.7/site-packages/pandas/io/json/_json.py", line 748, in read
    obj = self._get_object_parser(self.data)
  File "/home/airflow/.local/lib/python3.7/site-packages/pandas/io/json/_json.py", line 770, in _get_object_parser
    obj = FrameParser(json, **kwargs).parse()
  File "/home/airflow/.local/lib/python3.7/site-packages/pandas/io/json/_json.py", line 885, in parse
    self._parse_no_numpy()
  File "/home/airflow/.local/lib/python3.7/site-packages/pandas/io/json/_json.py", line 1140, in _parse_no_numpy
    loads(json, precise_float=self.precise_float), dtype=None
ValueError: Expected object or value
[2022-08-18 16:39:22,183] {processor.py:653} WARNING - No viable dags retrieved from /opt/airflow/dags/dbConnector.py
[2022-08-18 16:39:22,224] {processor.py:161} INFO - Processing /opt/airflow/dags/dbConnector.py took 0.386 seconds
[2022-08-18 16:39:53,014] {processor.py:153} INFO - Started process (PID=1255) to work on /opt/airflow/dags/dbConnector.py
[2022-08-18 16:39:53,026] {processor.py:641} INFO - Processing file /opt/airflow/dags/dbConnector.py for tasks to queue
[2022-08-18 16:39:53,026] {logging_mixin.py:115} INFO - [2022-08-18 16:39:53,026] {dagbag.py:508} INFO - Filling up the DagBag from /opt/airflow/dags/dbConnector.py
[2022-08-18 16:39:53,250] {logging_mixin.py:115} INFO - [2022-08-18 16:39:53,249] {dagbag.py:321} ERROR - Failed to import: /opt/airflow/dags/dbConnector.py
Traceback (most recent call last):
  File "/home/airflow/.local/lib/python3.7/site-packages/airflow/models/dagbag.py", line 318, in parse
    loader.exec_module(new_module)
  File "<frozen importlib._bootstrap_external>", line 728, in exec_module
  File "<frozen importlib._bootstrap>", line 219, in _call_with_frames_removed
  File "/opt/airflow/dags/dbConnector.py", line 23, in <module>
    data = pd.read_json('/home/L/Programming/dataEng/spaceApp/airflow/dags/tempSatelliteData.json')
  File "/home/airflow/.local/lib/python3.7/site-packages/pandas/util/_decorators.py", line 207, in wrapper
    return func(*args, **kwargs)
  File "/home/airflow/.local/lib/python3.7/site-packages/pandas/util/_decorators.py", line 311, in wrapper
    return func(*args, **kwargs)
  File "/home/airflow/.local/lib/python3.7/site-packages/pandas/io/json/_json.py", line 614, in read_json
    return json_reader.read()
  File "/home/airflow/.local/lib/python3.7/site-packages/pandas/io/json/_json.py", line 748, in read
    obj = self._get_object_parser(self.data)
  File "/home/airflow/.local/lib/python3.7/site-packages/pandas/io/json/_json.py", line 770, in _get_object_parser
    obj = FrameParser(json, **kwargs).parse()
  File "/home/airflow/.local/lib/python3.7/site-packages/pandas/io/json/_json.py", line 885, in parse
    self._parse_no_numpy()
  File "/home/airflow/.local/lib/python3.7/site-packages/pandas/io/json/_json.py", line 1140, in _parse_no_numpy
    loads(json, precise_float=self.precise_float), dtype=None
ValueError: Expected object or value
[2022-08-18 16:39:53,251] {processor.py:653} WARNING - No viable dags retrieved from /opt/airflow/dags/dbConnector.py
[2022-08-18 16:39:53,273] {processor.py:161} INFO - Processing /opt/airflow/dags/dbConnector.py took 0.264 seconds
[2022-08-18 16:40:23,521] {processor.py:153} INFO - Started process (PID=1288) to work on /opt/airflow/dags/dbConnector.py
[2022-08-18 16:40:23,522] {processor.py:641} INFO - Processing file /opt/airflow/dags/dbConnector.py for tasks to queue
[2022-08-18 16:40:23,523] {logging_mixin.py:115} INFO - [2022-08-18 16:40:23,523] {dagbag.py:508} INFO - Filling up the DagBag from /opt/airflow/dags/dbConnector.py
[2022-08-18 16:40:23,720] {logging_mixin.py:115} INFO - [2022-08-18 16:40:23,719] {dagbag.py:321} ERROR - Failed to import: /opt/airflow/dags/dbConnector.py
Traceback (most recent call last):
  File "/home/airflow/.local/lib/python3.7/site-packages/airflow/models/dagbag.py", line 318, in parse
    loader.exec_module(new_module)
  File "<frozen importlib._bootstrap_external>", line 728, in exec_module
  File "<frozen importlib._bootstrap>", line 219, in _call_with_frames_removed
  File "/opt/airflow/dags/dbConnector.py", line 23, in <module>
    data = pd.read_json('/home/L/Programming/dataEng/spaceApp/airflow/dags/tempSatelliteData.json')
  File "/home/airflow/.local/lib/python3.7/site-packages/pandas/util/_decorators.py", line 207, in wrapper
    return func(*args, **kwargs)
  File "/home/airflow/.local/lib/python3.7/site-packages/pandas/util/_decorators.py", line 311, in wrapper
    return func(*args, **kwargs)
  File "/home/airflow/.local/lib/python3.7/site-packages/pandas/io/json/_json.py", line 614, in read_json
    return json_reader.read()
  File "/home/airflow/.local/lib/python3.7/site-packages/pandas/io/json/_json.py", line 748, in read
    obj = self._get_object_parser(self.data)
  File "/home/airflow/.local/lib/python3.7/site-packages/pandas/io/json/_json.py", line 770, in _get_object_parser
    obj = FrameParser(json, **kwargs).parse()
  File "/home/airflow/.local/lib/python3.7/site-packages/pandas/io/json/_json.py", line 885, in parse
    self._parse_no_numpy()
  File "/home/airflow/.local/lib/python3.7/site-packages/pandas/io/json/_json.py", line 1140, in _parse_no_numpy
    loads(json, precise_float=self.precise_float), dtype=None
ValueError: Expected object or value
[2022-08-18 16:40:23,720] {processor.py:653} WARNING - No viable dags retrieved from /opt/airflow/dags/dbConnector.py
[2022-08-18 16:40:23,748] {processor.py:161} INFO - Processing /opt/airflow/dags/dbConnector.py took 0.231 seconds
[2022-08-18 16:40:54,028] {processor.py:153} INFO - Started process (PID=1322) to work on /opt/airflow/dags/dbConnector.py
[2022-08-18 16:40:54,050] {processor.py:641} INFO - Processing file /opt/airflow/dags/dbConnector.py for tasks to queue
[2022-08-18 16:40:54,051] {logging_mixin.py:115} INFO - [2022-08-18 16:40:54,050] {dagbag.py:508} INFO - Filling up the DagBag from /opt/airflow/dags/dbConnector.py
[2022-08-18 16:40:54,354] {logging_mixin.py:115} INFO - [2022-08-18 16:40:54,353] {dagbag.py:321} ERROR - Failed to import: /opt/airflow/dags/dbConnector.py
Traceback (most recent call last):
  File "/home/airflow/.local/lib/python3.7/site-packages/airflow/models/dagbag.py", line 318, in parse
    loader.exec_module(new_module)
  File "<frozen importlib._bootstrap_external>", line 728, in exec_module
  File "<frozen importlib._bootstrap>", line 219, in _call_with_frames_removed
  File "/opt/airflow/dags/dbConnector.py", line 23, in <module>
    data = pd.read_json('/home/L/Programming/dataEng/spaceApp/airflow/dags/tempSatelliteData.json')
  File "/home/airflow/.local/lib/python3.7/site-packages/pandas/util/_decorators.py", line 207, in wrapper
    return func(*args, **kwargs)
  File "/home/airflow/.local/lib/python3.7/site-packages/pandas/util/_decorators.py", line 311, in wrapper
    return func(*args, **kwargs)
  File "/home/airflow/.local/lib/python3.7/site-packages/pandas/io/json/_json.py", line 614, in read_json
    return json_reader.read()
  File "/home/airflow/.local/lib/python3.7/site-packages/pandas/io/json/_json.py", line 748, in read
    obj = self._get_object_parser(self.data)
  File "/home/airflow/.local/lib/python3.7/site-packages/pandas/io/json/_json.py", line 770, in _get_object_parser
    obj = FrameParser(json, **kwargs).parse()
  File "/home/airflow/.local/lib/python3.7/site-packages/pandas/io/json/_json.py", line 885, in parse
    self._parse_no_numpy()
  File "/home/airflow/.local/lib/python3.7/site-packages/pandas/io/json/_json.py", line 1140, in _parse_no_numpy
    loads(json, precise_float=self.precise_float), dtype=None
ValueError: Expected object or value
[2022-08-18 16:40:54,354] {processor.py:653} WARNING - No viable dags retrieved from /opt/airflow/dags/dbConnector.py
[2022-08-18 16:40:54,387] {processor.py:161} INFO - Processing /opt/airflow/dags/dbConnector.py took 0.379 seconds
[2022-08-18 16:41:16,067] {processor.py:153} INFO - Started process (PID=1344) to work on /opt/airflow/dags/dbConnector.py
[2022-08-18 16:41:16,272] {processor.py:641} INFO - Processing file /opt/airflow/dags/dbConnector.py for tasks to queue
[2022-08-18 16:41:16,272] {logging_mixin.py:115} INFO - [2022-08-18 16:41:16,272] {dagbag.py:508} INFO - Filling up the DagBag from /opt/airflow/dags/dbConnector.py
[2022-08-18 16:41:16,513] {logging_mixin.py:115} INFO - [2022-08-18 16:41:16,512] {dagbag.py:321} ERROR - Failed to import: /opt/airflow/dags/dbConnector.py
Traceback (most recent call last):
  File "/home/airflow/.local/lib/python3.7/site-packages/airflow/models/dagbag.py", line 318, in parse
    loader.exec_module(new_module)
  File "<frozen importlib._bootstrap_external>", line 728, in exec_module
  File "<frozen importlib._bootstrap>", line 219, in _call_with_frames_removed
  File "/opt/airflow/dags/dbConnector.py", line 23, in <module>
    data = pd.read_json('/home/L/Programming/dataEng/spaceApp/airflow/dags/tempSatelliteData.json')
  File "/home/airflow/.local/lib/python3.7/site-packages/pandas/util/_decorators.py", line 207, in wrapper
    return func(*args, **kwargs)
  File "/home/airflow/.local/lib/python3.7/site-packages/pandas/util/_decorators.py", line 311, in wrapper
    return func(*args, **kwargs)
  File "/home/airflow/.local/lib/python3.7/site-packages/pandas/io/json/_json.py", line 614, in read_json
    return json_reader.read()
  File "/home/airflow/.local/lib/python3.7/site-packages/pandas/io/json/_json.py", line 748, in read
    obj = self._get_object_parser(self.data)
  File "/home/airflow/.local/lib/python3.7/site-packages/pandas/io/json/_json.py", line 770, in _get_object_parser
    obj = FrameParser(json, **kwargs).parse()
  File "/home/airflow/.local/lib/python3.7/site-packages/pandas/io/json/_json.py", line 885, in parse
    self._parse_no_numpy()
  File "/home/airflow/.local/lib/python3.7/site-packages/pandas/io/json/_json.py", line 1140, in _parse_no_numpy
    loads(json, precise_float=self.precise_float), dtype=None
ValueError: Expected object or value
[2022-08-18 16:41:16,514] {processor.py:653} WARNING - No viable dags retrieved from /opt/airflow/dags/dbConnector.py
[2022-08-18 16:41:16,546] {processor.py:161} INFO - Processing /opt/airflow/dags/dbConnector.py took 0.482 seconds
[2022-08-18 16:41:47,360] {processor.py:153} INFO - Started process (PID=1368) to work on /opt/airflow/dags/dbConnector.py
[2022-08-18 16:41:47,374] {processor.py:641} INFO - Processing file /opt/airflow/dags/dbConnector.py for tasks to queue
[2022-08-18 16:41:47,374] {logging_mixin.py:115} INFO - [2022-08-18 16:41:47,374] {dagbag.py:508} INFO - Filling up the DagBag from /opt/airflow/dags/dbConnector.py
[2022-08-18 16:41:47,584] {logging_mixin.py:115} INFO - [2022-08-18 16:41:47,583] {dagbag.py:321} ERROR - Failed to import: /opt/airflow/dags/dbConnector.py
Traceback (most recent call last):
  File "/home/airflow/.local/lib/python3.7/site-packages/airflow/models/dagbag.py", line 318, in parse
    loader.exec_module(new_module)
  File "<frozen importlib._bootstrap_external>", line 728, in exec_module
  File "<frozen importlib._bootstrap>", line 219, in _call_with_frames_removed
  File "/opt/airflow/dags/dbConnector.py", line 23, in <module>
    data = pd.read_json('/home/L/Programming/dataEng/spaceApp/airflow/dags/tempSatelliteData.json')
  File "/home/airflow/.local/lib/python3.7/site-packages/pandas/util/_decorators.py", line 207, in wrapper
    return func(*args, **kwargs)
  File "/home/airflow/.local/lib/python3.7/site-packages/pandas/util/_decorators.py", line 311, in wrapper
    return func(*args, **kwargs)
  File "/home/airflow/.local/lib/python3.7/site-packages/pandas/io/json/_json.py", line 614, in read_json
    return json_reader.read()
  File "/home/airflow/.local/lib/python3.7/site-packages/pandas/io/json/_json.py", line 748, in read
    obj = self._get_object_parser(self.data)
  File "/home/airflow/.local/lib/python3.7/site-packages/pandas/io/json/_json.py", line 770, in _get_object_parser
    obj = FrameParser(json, **kwargs).parse()
  File "/home/airflow/.local/lib/python3.7/site-packages/pandas/io/json/_json.py", line 885, in parse
    self._parse_no_numpy()
  File "/home/airflow/.local/lib/python3.7/site-packages/pandas/io/json/_json.py", line 1140, in _parse_no_numpy
    loads(json, precise_float=self.precise_float), dtype=None
ValueError: Expected object or value
[2022-08-18 16:41:47,585] {processor.py:653} WARNING - No viable dags retrieved from /opt/airflow/dags/dbConnector.py
[2022-08-18 16:41:47,612] {processor.py:161} INFO - Processing /opt/airflow/dags/dbConnector.py took 0.257 seconds
[2022-08-18 16:42:03,674] {processor.py:153} INFO - Started process (PID=1389) to work on /opt/airflow/dags/dbConnector.py
[2022-08-18 16:42:03,682] {processor.py:641} INFO - Processing file /opt/airflow/dags/dbConnector.py for tasks to queue
[2022-08-18 16:42:03,683] {logging_mixin.py:115} INFO - [2022-08-18 16:42:03,683] {dagbag.py:508} INFO - Filling up the DagBag from /opt/airflow/dags/dbConnector.py
[2022-08-18 16:42:04,485] {processor.py:653} WARNING - No viable dags retrieved from /opt/airflow/dags/dbConnector.py
[2022-08-18 16:42:04,571] {processor.py:161} INFO - Processing /opt/airflow/dags/dbConnector.py took 0.901 seconds
[2022-08-18 16:42:34,977] {processor.py:153} INFO - Started process (PID=1421) to work on /opt/airflow/dags/dbConnector.py
[2022-08-18 16:42:35,023] {processor.py:641} INFO - Processing file /opt/airflow/dags/dbConnector.py for tasks to queue
[2022-08-18 16:42:35,094] {logging_mixin.py:115} INFO - [2022-08-18 16:42:35,094] {dagbag.py:508} INFO - Filling up the DagBag from /opt/airflow/dags/dbConnector.py
[2022-08-18 16:42:55,894] {processor.py:653} WARNING - No viable dags retrieved from /opt/airflow/dags/dbConnector.py
[2022-08-18 16:42:55,913] {processor.py:161} INFO - Processing /opt/airflow/dags/dbConnector.py took 20.942 seconds
[2022-08-18 16:43:26,267] {processor.py:153} INFO - Started process (PID=1453) to work on /opt/airflow/dags/dbConnector.py
[2022-08-18 16:43:26,298] {processor.py:641} INFO - Processing file /opt/airflow/dags/dbConnector.py for tasks to queue
[2022-08-18 16:43:26,298] {logging_mixin.py:115} INFO - [2022-08-18 16:43:26,298] {dagbag.py:508} INFO - Filling up the DagBag from /opt/airflow/dags/dbConnector.py
[2022-08-18 16:43:26,540] {processor.py:653} WARNING - No viable dags retrieved from /opt/airflow/dags/dbConnector.py
[2022-08-18 16:43:26,554] {processor.py:161} INFO - Processing /opt/airflow/dags/dbConnector.py took 0.292 seconds
[2022-08-18 16:43:56,780] {processor.py:153} INFO - Started process (PID=1490) to work on /opt/airflow/dags/dbConnector.py
[2022-08-18 16:43:56,797] {processor.py:641} INFO - Processing file /opt/airflow/dags/dbConnector.py for tasks to queue
[2022-08-18 16:43:56,798] {logging_mixin.py:115} INFO - [2022-08-18 16:43:56,798] {dagbag.py:508} INFO - Filling up the DagBag from /opt/airflow/dags/dbConnector.py
[2022-08-18 16:43:57,019] {processor.py:653} WARNING - No viable dags retrieved from /opt/airflow/dags/dbConnector.py
[2022-08-18 16:43:57,036] {processor.py:161} INFO - Processing /opt/airflow/dags/dbConnector.py took 0.260 seconds
[2022-08-18 16:44:05,075] {processor.py:153} INFO - Started process (PID=1501) to work on /opt/airflow/dags/dbConnector.py
[2022-08-18 16:44:05,080] {processor.py:641} INFO - Processing file /opt/airflow/dags/dbConnector.py for tasks to queue
[2022-08-18 16:44:05,080] {logging_mixin.py:115} INFO - [2022-08-18 16:44:05,080] {dagbag.py:508} INFO - Filling up the DagBag from /opt/airflow/dags/dbConnector.py
[2022-08-18 16:44:05,102] {logging_mixin.py:115} INFO - [2022-08-18 16:44:05,081] {dagbag.py:321} ERROR - Failed to import: /opt/airflow/dags/dbConnector.py
Traceback (most recent call last):
  File "/home/airflow/.local/lib/python3.7/site-packages/airflow/models/dagbag.py", line 318, in parse
    loader.exec_module(new_module)
  File "<frozen importlib._bootstrap_external>", line 724, in exec_module
  File "<frozen importlib._bootstrap_external>", line 860, in get_code
  File "<frozen importlib._bootstrap_external>", line 791, in source_to_code
  File "<frozen importlib._bootstrap>", line 219, in _call_with_frames_removed
  File "/opt/airflow/dags/dbConnector.py", line 5
    def load_into_database(:
                           ^
SyntaxError: invalid syntax
[2022-08-18 16:44:05,103] {processor.py:653} WARNING - No viable dags retrieved from /opt/airflow/dags/dbConnector.py
[2022-08-18 16:44:05,155] {processor.py:161} INFO - Processing /opt/airflow/dags/dbConnector.py took 0.083 seconds
[2022-08-18 16:44:08,089] {processor.py:153} INFO - Started process (PID=1502) to work on /opt/airflow/dags/dbConnector.py
[2022-08-18 16:44:08,090] {processor.py:641} INFO - Processing file /opt/airflow/dags/dbConnector.py for tasks to queue
[2022-08-18 16:44:08,091] {logging_mixin.py:115} INFO - [2022-08-18 16:44:08,090] {dagbag.py:508} INFO - Filling up the DagBag from /opt/airflow/dags/dbConnector.py
[2022-08-18 16:44:08,326] {processor.py:653} WARNING - No viable dags retrieved from /opt/airflow/dags/dbConnector.py
[2022-08-18 16:44:08,355] {processor.py:161} INFO - Processing /opt/airflow/dags/dbConnector.py took 0.270 seconds
[2022-08-18 16:44:38,444] {processor.py:153} INFO - Started process (PID=1539) to work on /opt/airflow/dags/dbConnector.py
[2022-08-18 16:44:38,455] {processor.py:641} INFO - Processing file /opt/airflow/dags/dbConnector.py for tasks to queue
[2022-08-18 16:44:38,455] {logging_mixin.py:115} INFO - [2022-08-18 16:44:38,455] {dagbag.py:508} INFO - Filling up the DagBag from /opt/airflow/dags/dbConnector.py
[2022-08-18 16:44:38,677] {processor.py:653} WARNING - No viable dags retrieved from /opt/airflow/dags/dbConnector.py
[2022-08-18 16:44:38,691] {processor.py:161} INFO - Processing /opt/airflow/dags/dbConnector.py took 0.251 seconds
[2022-08-18 16:44:53,164] {processor.py:153} INFO - Started process (PID=1552) to work on /opt/airflow/dags/dbConnector.py
[2022-08-18 16:44:53,165] {processor.py:641} INFO - Processing file /opt/airflow/dags/dbConnector.py for tasks to queue
[2022-08-18 16:44:53,166] {logging_mixin.py:115} INFO - [2022-08-18 16:44:53,166] {dagbag.py:508} INFO - Filling up the DagBag from /opt/airflow/dags/dbConnector.py
[2022-08-18 16:44:53,393] {processor.py:653} WARNING - No viable dags retrieved from /opt/airflow/dags/dbConnector.py
[2022-08-18 16:44:53,404] {processor.py:161} INFO - Processing /opt/airflow/dags/dbConnector.py took 0.244 seconds
[2022-08-18 16:45:23,492] {processor.py:153} INFO - Started process (PID=1582) to work on /opt/airflow/dags/dbConnector.py
[2022-08-18 16:45:23,496] {processor.py:641} INFO - Processing file /opt/airflow/dags/dbConnector.py for tasks to queue
[2022-08-18 16:45:23,496] {logging_mixin.py:115} INFO - [2022-08-18 16:45:23,496] {dagbag.py:508} INFO - Filling up the DagBag from /opt/airflow/dags/dbConnector.py
[2022-08-18 16:45:23,724] {processor.py:653} WARNING - No viable dags retrieved from /opt/airflow/dags/dbConnector.py
[2022-08-18 16:45:23,743] {processor.py:161} INFO - Processing /opt/airflow/dags/dbConnector.py took 0.255 seconds
[2022-08-18 16:45:54,485] {processor.py:153} INFO - Started process (PID=1612) to work on /opt/airflow/dags/dbConnector.py
[2022-08-18 16:45:54,495] {processor.py:641} INFO - Processing file /opt/airflow/dags/dbConnector.py for tasks to queue
[2022-08-18 16:45:54,496] {logging_mixin.py:115} INFO - [2022-08-18 16:45:54,496] {dagbag.py:508} INFO - Filling up the DagBag from /opt/airflow/dags/dbConnector.py
[2022-08-18 16:45:54,734] {processor.py:653} WARNING - No viable dags retrieved from /opt/airflow/dags/dbConnector.py
[2022-08-18 16:45:54,750] {processor.py:161} INFO - Processing /opt/airflow/dags/dbConnector.py took 0.268 seconds
[2022-08-18 16:46:24,799] {processor.py:153} INFO - Started process (PID=1645) to work on /opt/airflow/dags/dbConnector.py
[2022-08-18 16:46:24,803] {processor.py:641} INFO - Processing file /opt/airflow/dags/dbConnector.py for tasks to queue
[2022-08-18 16:46:24,803] {logging_mixin.py:115} INFO - [2022-08-18 16:46:24,803] {dagbag.py:508} INFO - Filling up the DagBag from /opt/airflow/dags/dbConnector.py
[2022-08-18 16:46:25,035] {processor.py:653} WARNING - No viable dags retrieved from /opt/airflow/dags/dbConnector.py
[2022-08-18 16:46:25,049] {processor.py:161} INFO - Processing /opt/airflow/dags/dbConnector.py took 0.254 seconds
[2022-08-18 16:46:55,886] {processor.py:153} INFO - Started process (PID=1669) to work on /opt/airflow/dags/dbConnector.py
[2022-08-18 16:46:55,894] {processor.py:641} INFO - Processing file /opt/airflow/dags/dbConnector.py for tasks to queue
[2022-08-18 16:46:55,894] {logging_mixin.py:115} INFO - [2022-08-18 16:46:55,894] {dagbag.py:508} INFO - Filling up the DagBag from /opt/airflow/dags/dbConnector.py
[2022-08-18 16:46:56,118] {processor.py:653} WARNING - No viable dags retrieved from /opt/airflow/dags/dbConnector.py
[2022-08-18 16:46:56,133] {processor.py:161} INFO - Processing /opt/airflow/dags/dbConnector.py took 0.252 seconds
[2022-08-18 16:47:26,441] {processor.py:153} INFO - Started process (PID=1702) to work on /opt/airflow/dags/dbConnector.py
[2022-08-18 16:47:26,444] {processor.py:641} INFO - Processing file /opt/airflow/dags/dbConnector.py for tasks to queue
[2022-08-18 16:47:26,444] {logging_mixin.py:115} INFO - [2022-08-18 16:47:26,444] {dagbag.py:508} INFO - Filling up the DagBag from /opt/airflow/dags/dbConnector.py
[2022-08-18 16:47:26,647] {processor.py:653} WARNING - No viable dags retrieved from /opt/airflow/dags/dbConnector.py
[2022-08-18 16:47:26,660] {processor.py:161} INFO - Processing /opt/airflow/dags/dbConnector.py took 0.222 seconds
[2022-08-18 16:47:56,745] {processor.py:153} INFO - Started process (PID=1735) to work on /opt/airflow/dags/dbConnector.py
[2022-08-18 16:47:56,752] {processor.py:641} INFO - Processing file /opt/airflow/dags/dbConnector.py for tasks to queue
[2022-08-18 16:47:56,752] {logging_mixin.py:115} INFO - [2022-08-18 16:47:56,752] {dagbag.py:508} INFO - Filling up the DagBag from /opt/airflow/dags/dbConnector.py
[2022-08-18 16:47:56,985] {processor.py:653} WARNING - No viable dags retrieved from /opt/airflow/dags/dbConnector.py
[2022-08-18 16:47:57,003] {processor.py:161} INFO - Processing /opt/airflow/dags/dbConnector.py took 0.262 seconds
[2022-08-18 16:48:27,389] {processor.py:153} INFO - Started process (PID=1761) to work on /opt/airflow/dags/dbConnector.py
[2022-08-18 16:48:27,402] {processor.py:641} INFO - Processing file /opt/airflow/dags/dbConnector.py for tasks to queue
[2022-08-18 16:48:27,403] {logging_mixin.py:115} INFO - [2022-08-18 16:48:27,403] {dagbag.py:508} INFO - Filling up the DagBag from /opt/airflow/dags/dbConnector.py
[2022-08-18 16:48:27,659] {processor.py:653} WARNING - No viable dags retrieved from /opt/airflow/dags/dbConnector.py
[2022-08-18 16:48:27,676] {processor.py:161} INFO - Processing /opt/airflow/dags/dbConnector.py took 0.292 seconds
[2022-08-18 16:48:57,765] {processor.py:153} INFO - Started process (PID=1796) to work on /opt/airflow/dags/dbConnector.py
[2022-08-18 16:48:57,775] {processor.py:641} INFO - Processing file /opt/airflow/dags/dbConnector.py for tasks to queue
[2022-08-18 16:48:57,775] {logging_mixin.py:115} INFO - [2022-08-18 16:48:57,775] {dagbag.py:508} INFO - Filling up the DagBag from /opt/airflow/dags/dbConnector.py
[2022-08-18 16:48:57,991] {processor.py:653} WARNING - No viable dags retrieved from /opt/airflow/dags/dbConnector.py
[2022-08-18 16:48:58,004] {processor.py:161} INFO - Processing /opt/airflow/dags/dbConnector.py took 0.244 seconds
[2022-08-18 16:49:28,114] {processor.py:153} INFO - Started process (PID=1826) to work on /opt/airflow/dags/dbConnector.py
[2022-08-18 16:49:28,126] {processor.py:641} INFO - Processing file /opt/airflow/dags/dbConnector.py for tasks to queue
[2022-08-18 16:49:28,126] {logging_mixin.py:115} INFO - [2022-08-18 16:49:28,126] {dagbag.py:508} INFO - Filling up the DagBag from /opt/airflow/dags/dbConnector.py
[2022-08-18 16:49:28,364] {processor.py:653} WARNING - No viable dags retrieved from /opt/airflow/dags/dbConnector.py
[2022-08-18 16:49:28,380] {processor.py:161} INFO - Processing /opt/airflow/dags/dbConnector.py took 0.269 seconds
[2022-08-18 16:49:58,675] {processor.py:153} INFO - Started process (PID=1850) to work on /opt/airflow/dags/dbConnector.py
[2022-08-18 16:49:58,690] {processor.py:641} INFO - Processing file /opt/airflow/dags/dbConnector.py for tasks to queue
[2022-08-18 16:49:58,691] {logging_mixin.py:115} INFO - [2022-08-18 16:49:58,691] {dagbag.py:508} INFO - Filling up the DagBag from /opt/airflow/dags/dbConnector.py
[2022-08-18 16:49:58,936] {processor.py:653} WARNING - No viable dags retrieved from /opt/airflow/dags/dbConnector.py
[2022-08-18 16:49:58,954] {processor.py:161} INFO - Processing /opt/airflow/dags/dbConnector.py took 0.284 seconds
[2022-08-18 16:50:29,099] {processor.py:153} INFO - Started process (PID=1885) to work on /opt/airflow/dags/dbConnector.py
[2022-08-18 16:50:29,106] {processor.py:641} INFO - Processing file /opt/airflow/dags/dbConnector.py for tasks to queue
[2022-08-18 16:50:29,107] {logging_mixin.py:115} INFO - [2022-08-18 16:50:29,107] {dagbag.py:508} INFO - Filling up the DagBag from /opt/airflow/dags/dbConnector.py
[2022-08-18 16:50:29,324] {processor.py:653} WARNING - No viable dags retrieved from /opt/airflow/dags/dbConnector.py
[2022-08-18 16:50:29,342] {processor.py:161} INFO - Processing /opt/airflow/dags/dbConnector.py took 0.248 seconds
[2022-08-18 16:51:00,279] {processor.py:153} INFO - Started process (PID=1917) to work on /opt/airflow/dags/dbConnector.py
[2022-08-18 16:51:00,289] {processor.py:641} INFO - Processing file /opt/airflow/dags/dbConnector.py for tasks to queue
[2022-08-18 16:51:00,290] {logging_mixin.py:115} INFO - [2022-08-18 16:51:00,290] {dagbag.py:508} INFO - Filling up the DagBag from /opt/airflow/dags/dbConnector.py
[2022-08-18 16:51:00,528] {processor.py:653} WARNING - No viable dags retrieved from /opt/airflow/dags/dbConnector.py
[2022-08-18 16:51:00,539] {processor.py:161} INFO - Processing /opt/airflow/dags/dbConnector.py took 0.263 seconds
[2022-08-18 16:51:30,579] {processor.py:153} INFO - Started process (PID=1943) to work on /opt/airflow/dags/dbConnector.py
[2022-08-18 16:51:30,589] {processor.py:641} INFO - Processing file /opt/airflow/dags/dbConnector.py for tasks to queue
[2022-08-18 16:51:30,589] {logging_mixin.py:115} INFO - [2022-08-18 16:51:30,589] {dagbag.py:508} INFO - Filling up the DagBag from /opt/airflow/dags/dbConnector.py
[2022-08-18 16:51:30,832] {processor.py:653} WARNING - No viable dags retrieved from /opt/airflow/dags/dbConnector.py
[2022-08-18 16:51:30,847] {processor.py:161} INFO - Processing /opt/airflow/dags/dbConnector.py took 0.272 seconds
[2022-08-18 16:52:01,555] {processor.py:153} INFO - Started process (PID=1975) to work on /opt/airflow/dags/dbConnector.py
[2022-08-18 16:52:01,563] {processor.py:641} INFO - Processing file /opt/airflow/dags/dbConnector.py for tasks to queue
[2022-08-18 16:52:01,564] {logging_mixin.py:115} INFO - [2022-08-18 16:52:01,564] {dagbag.py:508} INFO - Filling up the DagBag from /opt/airflow/dags/dbConnector.py
[2022-08-18 16:52:01,784] {processor.py:653} WARNING - No viable dags retrieved from /opt/airflow/dags/dbConnector.py
[2022-08-18 16:52:01,799] {processor.py:161} INFO - Processing /opt/airflow/dags/dbConnector.py took 0.249 seconds
[2022-08-18 16:52:31,886] {processor.py:153} INFO - Started process (PID=1999) to work on /opt/airflow/dags/dbConnector.py
[2022-08-18 16:52:31,930] {processor.py:641} INFO - Processing file /opt/airflow/dags/dbConnector.py for tasks to queue
[2022-08-18 16:52:31,931] {logging_mixin.py:115} INFO - [2022-08-18 16:52:31,930] {dagbag.py:508} INFO - Filling up the DagBag from /opt/airflow/dags/dbConnector.py
[2022-08-18 16:52:32,167] {processor.py:653} WARNING - No viable dags retrieved from /opt/airflow/dags/dbConnector.py
[2022-08-18 16:52:32,184] {processor.py:161} INFO - Processing /opt/airflow/dags/dbConnector.py took 0.303 seconds
[2022-08-18 16:53:02,261] {processor.py:153} INFO - Started process (PID=2030) to work on /opt/airflow/dags/dbConnector.py
[2022-08-18 16:53:02,271] {processor.py:641} INFO - Processing file /opt/airflow/dags/dbConnector.py for tasks to queue
[2022-08-18 16:53:02,271] {logging_mixin.py:115} INFO - [2022-08-18 16:53:02,271] {dagbag.py:508} INFO - Filling up the DagBag from /opt/airflow/dags/dbConnector.py
[2022-08-18 16:53:02,491] {processor.py:653} WARNING - No viable dags retrieved from /opt/airflow/dags/dbConnector.py
[2022-08-18 16:53:02,502] {processor.py:161} INFO - Processing /opt/airflow/dags/dbConnector.py took 0.246 seconds
[2022-08-18 16:53:32,717] {processor.py:153} INFO - Started process (PID=2063) to work on /opt/airflow/dags/dbConnector.py
[2022-08-18 16:53:32,729] {processor.py:641} INFO - Processing file /opt/airflow/dags/dbConnector.py for tasks to queue
[2022-08-18 16:53:32,730] {logging_mixin.py:115} INFO - [2022-08-18 16:53:32,729] {dagbag.py:508} INFO - Filling up the DagBag from /opt/airflow/dags/dbConnector.py
[2022-08-18 16:53:32,965] {processor.py:653} WARNING - No viable dags retrieved from /opt/airflow/dags/dbConnector.py
[2022-08-18 16:53:32,978] {processor.py:161} INFO - Processing /opt/airflow/dags/dbConnector.py took 0.265 seconds
[2022-08-18 16:54:03,703] {processor.py:153} INFO - Started process (PID=2087) to work on /opt/airflow/dags/dbConnector.py
[2022-08-18 16:54:03,711] {processor.py:641} INFO - Processing file /opt/airflow/dags/dbConnector.py for tasks to queue
[2022-08-18 16:54:03,712] {logging_mixin.py:115} INFO - [2022-08-18 16:54:03,712] {dagbag.py:508} INFO - Filling up the DagBag from /opt/airflow/dags/dbConnector.py
[2022-08-18 16:54:03,929] {processor.py:653} WARNING - No viable dags retrieved from /opt/airflow/dags/dbConnector.py
[2022-08-18 16:54:03,947] {processor.py:161} INFO - Processing /opt/airflow/dags/dbConnector.py took 0.248 seconds
[2022-08-18 16:54:33,989] {processor.py:153} INFO - Started process (PID=2120) to work on /opt/airflow/dags/dbConnector.py
[2022-08-18 16:54:34,003] {processor.py:641} INFO - Processing file /opt/airflow/dags/dbConnector.py for tasks to queue
[2022-08-18 16:54:34,004] {logging_mixin.py:115} INFO - [2022-08-18 16:54:34,004] {dagbag.py:508} INFO - Filling up the DagBag from /opt/airflow/dags/dbConnector.py
[2022-08-18 16:54:34,222] {processor.py:653} WARNING - No viable dags retrieved from /opt/airflow/dags/dbConnector.py
[2022-08-18 16:54:34,238] {processor.py:161} INFO - Processing /opt/airflow/dags/dbConnector.py took 0.253 seconds
[2022-08-18 16:55:05,115] {processor.py:153} INFO - Started process (PID=2153) to work on /opt/airflow/dags/dbConnector.py
[2022-08-18 16:55:05,145] {processor.py:641} INFO - Processing file /opt/airflow/dags/dbConnector.py for tasks to queue
[2022-08-18 16:55:05,147] {logging_mixin.py:115} INFO - [2022-08-18 16:55:05,147] {dagbag.py:508} INFO - Filling up the DagBag from /opt/airflow/dags/dbConnector.py
[2022-08-18 16:55:05,377] {processor.py:653} WARNING - No viable dags retrieved from /opt/airflow/dags/dbConnector.py
[2022-08-18 16:55:05,395] {processor.py:161} INFO - Processing /opt/airflow/dags/dbConnector.py took 0.285 seconds
[2022-08-18 16:55:35,485] {processor.py:153} INFO - Started process (PID=2177) to work on /opt/airflow/dags/dbConnector.py
[2022-08-18 16:55:35,494] {processor.py:641} INFO - Processing file /opt/airflow/dags/dbConnector.py for tasks to queue
[2022-08-18 16:55:35,495] {logging_mixin.py:115} INFO - [2022-08-18 16:55:35,495] {dagbag.py:508} INFO - Filling up the DagBag from /opt/airflow/dags/dbConnector.py
[2022-08-18 16:55:35,700] {processor.py:653} WARNING - No viable dags retrieved from /opt/airflow/dags/dbConnector.py
[2022-08-18 16:55:35,714] {processor.py:161} INFO - Processing /opt/airflow/dags/dbConnector.py took 0.233 seconds
[2022-08-18 16:56:05,795] {processor.py:153} INFO - Started process (PID=2209) to work on /opt/airflow/dags/dbConnector.py
[2022-08-18 16:56:05,803] {processor.py:641} INFO - Processing file /opt/airflow/dags/dbConnector.py for tasks to queue
[2022-08-18 16:56:05,803] {logging_mixin.py:115} INFO - [2022-08-18 16:56:05,803] {dagbag.py:508} INFO - Filling up the DagBag from /opt/airflow/dags/dbConnector.py
[2022-08-18 16:56:06,026] {processor.py:653} WARNING - No viable dags retrieved from /opt/airflow/dags/dbConnector.py
[2022-08-18 16:56:06,039] {processor.py:161} INFO - Processing /opt/airflow/dags/dbConnector.py took 0.249 seconds
[2022-08-18 16:56:36,125] {processor.py:153} INFO - Started process (PID=2233) to work on /opt/airflow/dags/dbConnector.py
[2022-08-18 16:56:36,135] {processor.py:641} INFO - Processing file /opt/airflow/dags/dbConnector.py for tasks to queue
[2022-08-18 16:56:36,136] {logging_mixin.py:115} INFO - [2022-08-18 16:56:36,136] {dagbag.py:508} INFO - Filling up the DagBag from /opt/airflow/dags/dbConnector.py
[2022-08-18 16:56:36,396] {processor.py:653} WARNING - No viable dags retrieved from /opt/airflow/dags/dbConnector.py
[2022-08-18 16:56:36,417] {processor.py:161} INFO - Processing /opt/airflow/dags/dbConnector.py took 0.296 seconds
[2022-08-18 16:57:06,796] {processor.py:153} INFO - Started process (PID=2264) to work on /opt/airflow/dags/dbConnector.py
[2022-08-18 16:57:06,810] {processor.py:641} INFO - Processing file /opt/airflow/dags/dbConnector.py for tasks to queue
[2022-08-18 16:57:06,811] {logging_mixin.py:115} INFO - [2022-08-18 16:57:06,811] {dagbag.py:508} INFO - Filling up the DagBag from /opt/airflow/dags/dbConnector.py
[2022-08-18 16:57:07,039] {processor.py:653} WARNING - No viable dags retrieved from /opt/airflow/dags/dbConnector.py
[2022-08-18 16:57:07,055] {processor.py:161} INFO - Processing /opt/airflow/dags/dbConnector.py took 0.263 seconds
[2022-08-18 16:57:37,829] {processor.py:153} INFO - Started process (PID=2297) to work on /opt/airflow/dags/dbConnector.py
[2022-08-18 16:57:37,843] {processor.py:641} INFO - Processing file /opt/airflow/dags/dbConnector.py for tasks to queue
[2022-08-18 16:57:37,843] {logging_mixin.py:115} INFO - [2022-08-18 16:57:37,843] {dagbag.py:508} INFO - Filling up the DagBag from /opt/airflow/dags/dbConnector.py
[2022-08-18 16:57:38,056] {processor.py:653} WARNING - No viable dags retrieved from /opt/airflow/dags/dbConnector.py
[2022-08-18 16:57:38,074] {processor.py:161} INFO - Processing /opt/airflow/dags/dbConnector.py took 0.248 seconds
[2022-08-18 16:58:08,677] {processor.py:153} INFO - Started process (PID=2322) to work on /opt/airflow/dags/dbConnector.py
[2022-08-18 16:58:08,692] {processor.py:641} INFO - Processing file /opt/airflow/dags/dbConnector.py for tasks to queue
[2022-08-18 16:58:08,693] {logging_mixin.py:115} INFO - [2022-08-18 16:58:08,693] {dagbag.py:508} INFO - Filling up the DagBag from /opt/airflow/dags/dbConnector.py
[2022-08-18 16:58:08,912] {processor.py:653} WARNING - No viable dags retrieved from /opt/airflow/dags/dbConnector.py
[2022-08-18 16:58:08,930] {processor.py:161} INFO - Processing /opt/airflow/dags/dbConnector.py took 0.256 seconds
[2022-08-18 16:58:39,002] {processor.py:153} INFO - Started process (PID=2355) to work on /opt/airflow/dags/dbConnector.py
[2022-08-18 16:58:39,034] {processor.py:641} INFO - Processing file /opt/airflow/dags/dbConnector.py for tasks to queue
[2022-08-18 16:58:39,035] {logging_mixin.py:115} INFO - [2022-08-18 16:58:39,034] {dagbag.py:508} INFO - Filling up the DagBag from /opt/airflow/dags/dbConnector.py
[2022-08-18 16:58:39,276] {processor.py:653} WARNING - No viable dags retrieved from /opt/airflow/dags/dbConnector.py
[2022-08-18 16:58:39,288] {processor.py:161} INFO - Processing /opt/airflow/dags/dbConnector.py took 0.290 seconds
[2022-08-18 16:59:10,195] {processor.py:153} INFO - Started process (PID=2387) to work on /opt/airflow/dags/dbConnector.py
[2022-08-18 16:59:10,208] {processor.py:641} INFO - Processing file /opt/airflow/dags/dbConnector.py for tasks to queue
[2022-08-18 16:59:10,209] {logging_mixin.py:115} INFO - [2022-08-18 16:59:10,208] {dagbag.py:508} INFO - Filling up the DagBag from /opt/airflow/dags/dbConnector.py
[2022-08-18 16:59:10,419] {processor.py:653} WARNING - No viable dags retrieved from /opt/airflow/dags/dbConnector.py
[2022-08-18 16:59:10,438] {processor.py:161} INFO - Processing /opt/airflow/dags/dbConnector.py took 0.247 seconds
[2022-08-18 16:59:40,527] {processor.py:153} INFO - Started process (PID=2409) to work on /opt/airflow/dags/dbConnector.py
[2022-08-18 16:59:40,540] {processor.py:641} INFO - Processing file /opt/airflow/dags/dbConnector.py for tasks to queue
[2022-08-18 16:59:40,541] {logging_mixin.py:115} INFO - [2022-08-18 16:59:40,541] {dagbag.py:508} INFO - Filling up the DagBag from /opt/airflow/dags/dbConnector.py
[2022-08-18 16:59:40,901] {processor.py:653} WARNING - No viable dags retrieved from /opt/airflow/dags/dbConnector.py
[2022-08-18 16:59:40,918] {processor.py:161} INFO - Processing /opt/airflow/dags/dbConnector.py took 0.396 seconds
[2022-08-18 17:00:10,993] {processor.py:153} INFO - Started process (PID=2442) to work on /opt/airflow/dags/dbConnector.py
[2022-08-18 17:00:10,994] {processor.py:641} INFO - Processing file /opt/airflow/dags/dbConnector.py for tasks to queue
[2022-08-18 17:00:10,995] {logging_mixin.py:115} INFO - [2022-08-18 17:00:10,994] {dagbag.py:508} INFO - Filling up the DagBag from /opt/airflow/dags/dbConnector.py
[2022-08-18 17:00:11,238] {processor.py:653} WARNING - No viable dags retrieved from /opt/airflow/dags/dbConnector.py
[2022-08-18 17:00:11,250] {processor.py:161} INFO - Processing /opt/airflow/dags/dbConnector.py took 0.261 seconds
[2022-08-18 17:00:41,351] {processor.py:153} INFO - Started process (PID=2473) to work on /opt/airflow/dags/dbConnector.py
[2022-08-18 17:00:41,365] {processor.py:641} INFO - Processing file /opt/airflow/dags/dbConnector.py for tasks to queue
[2022-08-18 17:00:41,365] {logging_mixin.py:115} INFO - [2022-08-18 17:00:41,365] {dagbag.py:508} INFO - Filling up the DagBag from /opt/airflow/dags/dbConnector.py
[2022-08-18 17:00:41,620] {processor.py:653} WARNING - No viable dags retrieved from /opt/airflow/dags/dbConnector.py
[2022-08-18 17:00:41,630] {processor.py:161} INFO - Processing /opt/airflow/dags/dbConnector.py took 0.284 seconds
[2022-08-18 17:01:12,097] {processor.py:153} INFO - Started process (PID=2497) to work on /opt/airflow/dags/dbConnector.py
[2022-08-18 17:01:12,106] {processor.py:641} INFO - Processing file /opt/airflow/dags/dbConnector.py for tasks to queue
[2022-08-18 17:01:12,107] {logging_mixin.py:115} INFO - [2022-08-18 17:01:12,106] {dagbag.py:508} INFO - Filling up the DagBag from /opt/airflow/dags/dbConnector.py
[2022-08-18 17:01:12,455] {processor.py:653} WARNING - No viable dags retrieved from /opt/airflow/dags/dbConnector.py
[2022-08-18 17:01:12,474] {processor.py:161} INFO - Processing /opt/airflow/dags/dbConnector.py took 0.381 seconds
[2022-08-18 17:01:43,182] {processor.py:153} INFO - Started process (PID=2530) to work on /opt/airflow/dags/dbConnector.py
[2022-08-18 17:01:43,197] {processor.py:641} INFO - Processing file /opt/airflow/dags/dbConnector.py for tasks to queue
[2022-08-18 17:01:43,198] {logging_mixin.py:115} INFO - [2022-08-18 17:01:43,198] {dagbag.py:508} INFO - Filling up the DagBag from /opt/airflow/dags/dbConnector.py
[2022-08-18 17:01:43,414] {processor.py:653} WARNING - No viable dags retrieved from /opt/airflow/dags/dbConnector.py
[2022-08-18 17:01:43,432] {processor.py:161} INFO - Processing /opt/airflow/dags/dbConnector.py took 0.254 seconds
[2022-08-18 17:02:13,518] {processor.py:153} INFO - Started process (PID=2563) to work on /opt/airflow/dags/dbConnector.py
[2022-08-18 17:02:13,529] {processor.py:641} INFO - Processing file /opt/airflow/dags/dbConnector.py for tasks to queue
[2022-08-18 17:02:13,530] {logging_mixin.py:115} INFO - [2022-08-18 17:02:13,530] {dagbag.py:508} INFO - Filling up the DagBag from /opt/airflow/dags/dbConnector.py
[2022-08-18 17:02:13,760] {processor.py:653} WARNING - No viable dags retrieved from /opt/airflow/dags/dbConnector.py
[2022-08-18 17:02:13,774] {processor.py:161} INFO - Processing /opt/airflow/dags/dbConnector.py took 0.259 seconds
[2022-08-18 17:02:43,853] {processor.py:153} INFO - Started process (PID=2587) to work on /opt/airflow/dags/dbConnector.py
[2022-08-18 17:02:43,862] {processor.py:641} INFO - Processing file /opt/airflow/dags/dbConnector.py for tasks to queue
[2022-08-18 17:02:43,863] {logging_mixin.py:115} INFO - [2022-08-18 17:02:43,863] {dagbag.py:508} INFO - Filling up the DagBag from /opt/airflow/dags/dbConnector.py
[2022-08-18 17:02:44,391] {processor.py:653} WARNING - No viable dags retrieved from /opt/airflow/dags/dbConnector.py
[2022-08-18 17:02:44,421] {processor.py:161} INFO - Processing /opt/airflow/dags/dbConnector.py took 0.574 seconds
[2022-08-18 17:03:14,461] {processor.py:153} INFO - Started process (PID=2619) to work on /opt/airflow/dags/dbConnector.py
[2022-08-18 17:03:14,470] {processor.py:641} INFO - Processing file /opt/airflow/dags/dbConnector.py for tasks to queue
[2022-08-18 17:03:14,470] {logging_mixin.py:115} INFO - [2022-08-18 17:03:14,470] {dagbag.py:508} INFO - Filling up the DagBag from /opt/airflow/dags/dbConnector.py
[2022-08-18 17:03:14,717] {processor.py:653} WARNING - No viable dags retrieved from /opt/airflow/dags/dbConnector.py
[2022-08-18 17:03:14,729] {processor.py:161} INFO - Processing /opt/airflow/dags/dbConnector.py took 0.273 seconds
[2022-08-18 17:03:45,559] {processor.py:153} INFO - Started process (PID=2644) to work on /opt/airflow/dags/dbConnector.py
[2022-08-18 17:03:45,569] {processor.py:641} INFO - Processing file /opt/airflow/dags/dbConnector.py for tasks to queue
[2022-08-18 17:03:45,570] {logging_mixin.py:115} INFO - [2022-08-18 17:03:45,570] {dagbag.py:508} INFO - Filling up the DagBag from /opt/airflow/dags/dbConnector.py
[2022-08-18 17:03:45,819] {processor.py:653} WARNING - No viable dags retrieved from /opt/airflow/dags/dbConnector.py
[2022-08-18 17:03:45,833] {processor.py:161} INFO - Processing /opt/airflow/dags/dbConnector.py took 0.279 seconds
[2022-08-18 17:04:16,372] {processor.py:153} INFO - Started process (PID=2676) to work on /opt/airflow/dags/dbConnector.py
[2022-08-18 17:04:16,403] {processor.py:641} INFO - Processing file /opt/airflow/dags/dbConnector.py for tasks to queue
[2022-08-18 17:04:16,404] {logging_mixin.py:115} INFO - [2022-08-18 17:04:16,403] {dagbag.py:508} INFO - Filling up the DagBag from /opt/airflow/dags/dbConnector.py
[2022-08-18 17:04:16,953] {processor.py:653} WARNING - No viable dags retrieved from /opt/airflow/dags/dbConnector.py
[2022-08-18 17:04:16,970] {processor.py:161} INFO - Processing /opt/airflow/dags/dbConnector.py took 0.659 seconds
[2022-08-18 17:04:47,799] {processor.py:153} INFO - Started process (PID=2709) to work on /opt/airflow/dags/dbConnector.py
[2022-08-18 17:04:47,876] {processor.py:641} INFO - Processing file /opt/airflow/dags/dbConnector.py for tasks to queue
[2022-08-18 17:04:47,877] {logging_mixin.py:115} INFO - [2022-08-18 17:04:47,877] {dagbag.py:508} INFO - Filling up the DagBag from /opt/airflow/dags/dbConnector.py
[2022-08-18 17:04:48,099] {processor.py:653} WARNING - No viable dags retrieved from /opt/airflow/dags/dbConnector.py
[2022-08-18 17:04:48,114] {processor.py:161} INFO - Processing /opt/airflow/dags/dbConnector.py took 0.318 seconds
[2022-08-18 17:05:18,329] {processor.py:153} INFO - Started process (PID=2733) to work on /opt/airflow/dags/dbConnector.py
[2022-08-18 17:05:18,351] {processor.py:641} INFO - Processing file /opt/airflow/dags/dbConnector.py for tasks to queue
[2022-08-18 17:05:18,371] {logging_mixin.py:115} INFO - [2022-08-18 17:05:18,371] {dagbag.py:508} INFO - Filling up the DagBag from /opt/airflow/dags/dbConnector.py
[2022-08-18 17:05:19,129] {processor.py:653} WARNING - No viable dags retrieved from /opt/airflow/dags/dbConnector.py
[2022-08-18 17:05:19,146] {processor.py:161} INFO - Processing /opt/airflow/dags/dbConnector.py took 0.821 seconds
[2022-08-18 17:05:49,336] {processor.py:153} INFO - Started process (PID=2766) to work on /opt/airflow/dags/dbConnector.py
[2022-08-18 17:05:49,368] {processor.py:641} INFO - Processing file /opt/airflow/dags/dbConnector.py for tasks to queue
[2022-08-18 17:05:49,369] {logging_mixin.py:115} INFO - [2022-08-18 17:05:49,369] {dagbag.py:508} INFO - Filling up the DagBag from /opt/airflow/dags/dbConnector.py
[2022-08-18 17:05:49,575] {processor.py:653} WARNING - No viable dags retrieved from /opt/airflow/dags/dbConnector.py
[2022-08-18 17:05:49,592] {processor.py:161} INFO - Processing /opt/airflow/dags/dbConnector.py took 0.260 seconds
[2022-08-18 17:06:20,110] {processor.py:153} INFO - Started process (PID=2799) to work on /opt/airflow/dags/dbConnector.py
[2022-08-18 17:06:20,110] {processor.py:641} INFO - Processing file /opt/airflow/dags/dbConnector.py for tasks to queue
[2022-08-18 17:06:20,111] {logging_mixin.py:115} INFO - [2022-08-18 17:06:20,111] {dagbag.py:508} INFO - Filling up the DagBag from /opt/airflow/dags/dbConnector.py
[2022-08-18 17:06:20,338] {processor.py:653} WARNING - No viable dags retrieved from /opt/airflow/dags/dbConnector.py
[2022-08-18 17:06:20,351] {processor.py:161} INFO - Processing /opt/airflow/dags/dbConnector.py took 0.245 seconds
[2022-08-18 17:06:50,438] {processor.py:153} INFO - Started process (PID=2823) to work on /opt/airflow/dags/dbConnector.py
[2022-08-18 17:06:50,441] {processor.py:641} INFO - Processing file /opt/airflow/dags/dbConnector.py for tasks to queue
[2022-08-18 17:06:50,442] {logging_mixin.py:115} INFO - [2022-08-18 17:06:50,442] {dagbag.py:508} INFO - Filling up the DagBag from /opt/airflow/dags/dbConnector.py
[2022-08-18 17:06:50,658] {processor.py:653} WARNING - No viable dags retrieved from /opt/airflow/dags/dbConnector.py
[2022-08-18 17:06:50,675] {processor.py:161} INFO - Processing /opt/airflow/dags/dbConnector.py took 0.241 seconds
[2022-08-18 17:07:21,531] {processor.py:153} INFO - Started process (PID=2854) to work on /opt/airflow/dags/dbConnector.py
[2022-08-18 17:07:21,532] {processor.py:641} INFO - Processing file /opt/airflow/dags/dbConnector.py for tasks to queue
[2022-08-18 17:07:21,533] {logging_mixin.py:115} INFO - [2022-08-18 17:07:21,533] {dagbag.py:508} INFO - Filling up the DagBag from /opt/airflow/dags/dbConnector.py
[2022-08-18 17:07:21,758] {processor.py:653} WARNING - No viable dags retrieved from /opt/airflow/dags/dbConnector.py
[2022-08-18 17:07:21,776] {processor.py:161} INFO - Processing /opt/airflow/dags/dbConnector.py took 0.249 seconds
[2022-08-18 17:07:51,883] {processor.py:153} INFO - Started process (PID=2883) to work on /opt/airflow/dags/dbConnector.py
[2022-08-18 17:07:51,891] {processor.py:641} INFO - Processing file /opt/airflow/dags/dbConnector.py for tasks to queue
[2022-08-18 17:07:51,891] {logging_mixin.py:115} INFO - [2022-08-18 17:07:51,891] {dagbag.py:508} INFO - Filling up the DagBag from /opt/airflow/dags/dbConnector.py
[2022-08-18 17:07:52,136] {processor.py:653} WARNING - No viable dags retrieved from /opt/airflow/dags/dbConnector.py
[2022-08-18 17:07:52,153] {processor.py:161} INFO - Processing /opt/airflow/dags/dbConnector.py took 0.275 seconds
[2022-08-18 17:08:22,370] {processor.py:153} INFO - Started process (PID=2909) to work on /opt/airflow/dags/dbConnector.py
[2022-08-18 17:08:22,382] {processor.py:641} INFO - Processing file /opt/airflow/dags/dbConnector.py for tasks to queue
[2022-08-18 17:08:22,382] {logging_mixin.py:115} INFO - [2022-08-18 17:08:22,382] {dagbag.py:508} INFO - Filling up the DagBag from /opt/airflow/dags/dbConnector.py
[2022-08-18 17:08:22,589] {processor.py:653} WARNING - No viable dags retrieved from /opt/airflow/dags/dbConnector.py
[2022-08-18 17:08:22,602] {processor.py:161} INFO - Processing /opt/airflow/dags/dbConnector.py took 0.235 seconds
[2022-08-18 17:08:52,700] {processor.py:153} INFO - Started process (PID=2942) to work on /opt/airflow/dags/dbConnector.py
[2022-08-18 17:08:52,715] {processor.py:641} INFO - Processing file /opt/airflow/dags/dbConnector.py for tasks to queue
[2022-08-18 17:08:52,716] {logging_mixin.py:115} INFO - [2022-08-18 17:08:52,716] {dagbag.py:508} INFO - Filling up the DagBag from /opt/airflow/dags/dbConnector.py
[2022-08-18 17:08:52,959] {processor.py:653} WARNING - No viable dags retrieved from /opt/airflow/dags/dbConnector.py
[2022-08-18 17:08:52,976] {processor.py:161} INFO - Processing /opt/airflow/dags/dbConnector.py took 0.280 seconds
[2022-08-18 17:09:23,787] {processor.py:153} INFO - Started process (PID=2966) to work on /opt/airflow/dags/dbConnector.py
[2022-08-18 17:09:23,797] {processor.py:641} INFO - Processing file /opt/airflow/dags/dbConnector.py for tasks to queue
[2022-08-18 17:09:23,797] {logging_mixin.py:115} INFO - [2022-08-18 17:09:23,797] {dagbag.py:508} INFO - Filling up the DagBag from /opt/airflow/dags/dbConnector.py
[2022-08-18 17:09:24,013] {processor.py:653} WARNING - No viable dags retrieved from /opt/airflow/dags/dbConnector.py
[2022-08-18 17:09:24,030] {processor.py:161} INFO - Processing /opt/airflow/dags/dbConnector.py took 0.247 seconds
[2022-08-18 17:09:54,242] {processor.py:153} INFO - Started process (PID=3000) to work on /opt/airflow/dags/dbConnector.py
[2022-08-18 17:09:54,243] {processor.py:641} INFO - Processing file /opt/airflow/dags/dbConnector.py for tasks to queue
[2022-08-18 17:09:54,243] {logging_mixin.py:115} INFO - [2022-08-18 17:09:54,243] {dagbag.py:508} INFO - Filling up the DagBag from /opt/airflow/dags/dbConnector.py
[2022-08-18 17:09:54,459] {processor.py:653} WARNING - No viable dags retrieved from /opt/airflow/dags/dbConnector.py
[2022-08-18 17:09:54,476] {processor.py:161} INFO - Processing /opt/airflow/dags/dbConnector.py took 0.238 seconds
[2022-08-18 17:10:24,554] {processor.py:153} INFO - Started process (PID=3033) to work on /opt/airflow/dags/dbConnector.py
[2022-08-18 17:10:24,555] {processor.py:641} INFO - Processing file /opt/airflow/dags/dbConnector.py for tasks to queue
[2022-08-18 17:10:24,556] {logging_mixin.py:115} INFO - [2022-08-18 17:10:24,555] {dagbag.py:508} INFO - Filling up the DagBag from /opt/airflow/dags/dbConnector.py
[2022-08-18 17:10:24,796] {processor.py:653} WARNING - No viable dags retrieved from /opt/airflow/dags/dbConnector.py
[2022-08-18 17:10:24,811] {processor.py:161} INFO - Processing /opt/airflow/dags/dbConnector.py took 0.261 seconds
[2022-08-18 17:10:54,919] {processor.py:153} INFO - Started process (PID=3055) to work on /opt/airflow/dags/dbConnector.py
[2022-08-18 17:10:54,920] {processor.py:641} INFO - Processing file /opt/airflow/dags/dbConnector.py for tasks to queue
[2022-08-18 17:10:54,920] {logging_mixin.py:115} INFO - [2022-08-18 17:10:54,920] {dagbag.py:508} INFO - Filling up the DagBag from /opt/airflow/dags/dbConnector.py
[2022-08-18 17:10:55,125] {processor.py:653} WARNING - No viable dags retrieved from /opt/airflow/dags/dbConnector.py
[2022-08-18 17:10:55,138] {processor.py:161} INFO - Processing /opt/airflow/dags/dbConnector.py took 0.223 seconds
[2022-08-18 17:11:25,221] {processor.py:153} INFO - Started process (PID=3086) to work on /opt/airflow/dags/dbConnector.py
[2022-08-18 17:11:25,237] {processor.py:641} INFO - Processing file /opt/airflow/dags/dbConnector.py for tasks to queue
[2022-08-18 17:11:25,238] {logging_mixin.py:115} INFO - [2022-08-18 17:11:25,238] {dagbag.py:508} INFO - Filling up the DagBag from /opt/airflow/dags/dbConnector.py
[2022-08-18 17:11:25,487] {processor.py:653} WARNING - No viable dags retrieved from /opt/airflow/dags/dbConnector.py
[2022-08-18 17:11:25,506] {processor.py:161} INFO - Processing /opt/airflow/dags/dbConnector.py took 0.289 seconds
[2022-08-18 17:11:56,147] {processor.py:153} INFO - Started process (PID=3119) to work on /opt/airflow/dags/dbConnector.py
[2022-08-18 17:11:56,161] {processor.py:641} INFO - Processing file /opt/airflow/dags/dbConnector.py for tasks to queue
[2022-08-18 17:11:56,162] {logging_mixin.py:115} INFO - [2022-08-18 17:11:56,162] {dagbag.py:508} INFO - Filling up the DagBag from /opt/airflow/dags/dbConnector.py
[2022-08-18 17:11:56,386] {processor.py:653} WARNING - No viable dags retrieved from /opt/airflow/dags/dbConnector.py
[2022-08-18 17:11:56,403] {processor.py:161} INFO - Processing /opt/airflow/dags/dbConnector.py took 0.260 seconds
[2022-08-18 17:12:26,529] {processor.py:153} INFO - Started process (PID=3143) to work on /opt/airflow/dags/dbConnector.py
[2022-08-18 17:12:26,536] {processor.py:641} INFO - Processing file /opt/airflow/dags/dbConnector.py for tasks to queue
[2022-08-18 17:12:26,537] {logging_mixin.py:115} INFO - [2022-08-18 17:12:26,537] {dagbag.py:508} INFO - Filling up the DagBag from /opt/airflow/dags/dbConnector.py
[2022-08-18 17:12:27,094] {processor.py:653} WARNING - No viable dags retrieved from /opt/airflow/dags/dbConnector.py
[2022-08-18 17:12:27,112] {processor.py:161} INFO - Processing /opt/airflow/dags/dbConnector.py took 0.623 seconds
[2022-08-18 17:12:57,180] {processor.py:153} INFO - Started process (PID=3175) to work on /opt/airflow/dags/dbConnector.py
[2022-08-18 17:12:57,194] {processor.py:641} INFO - Processing file /opt/airflow/dags/dbConnector.py for tasks to queue
[2022-08-18 17:12:57,195] {logging_mixin.py:115} INFO - [2022-08-18 17:12:57,195] {dagbag.py:508} INFO - Filling up the DagBag from /opt/airflow/dags/dbConnector.py
[2022-08-18 17:12:57,637] {processor.py:653} WARNING - No viable dags retrieved from /opt/airflow/dags/dbConnector.py
[2022-08-18 17:12:57,656] {processor.py:161} INFO - Processing /opt/airflow/dags/dbConnector.py took 0.480 seconds
[2022-08-18 17:13:28,260] {processor.py:153} INFO - Started process (PID=3199) to work on /opt/airflow/dags/dbConnector.py
[2022-08-18 17:13:28,293] {processor.py:641} INFO - Processing file /opt/airflow/dags/dbConnector.py for tasks to queue
[2022-08-18 17:13:28,294] {logging_mixin.py:115} INFO - [2022-08-18 17:13:28,294] {dagbag.py:508} INFO - Filling up the DagBag from /opt/airflow/dags/dbConnector.py
[2022-08-18 17:13:28,562] {processor.py:653} WARNING - No viable dags retrieved from /opt/airflow/dags/dbConnector.py
[2022-08-18 17:13:28,578] {processor.py:161} INFO - Processing /opt/airflow/dags/dbConnector.py took 0.323 seconds
[2022-08-18 17:13:58,719] {processor.py:153} INFO - Started process (PID=3232) to work on /opt/airflow/dags/dbConnector.py
[2022-08-18 17:13:58,735] {processor.py:641} INFO - Processing file /opt/airflow/dags/dbConnector.py for tasks to queue
[2022-08-18 17:13:58,735] {logging_mixin.py:115} INFO - [2022-08-18 17:13:58,735] {dagbag.py:508} INFO - Filling up the DagBag from /opt/airflow/dags/dbConnector.py
[2022-08-18 17:13:58,959] {processor.py:653} WARNING - No viable dags retrieved from /opt/airflow/dags/dbConnector.py
[2022-08-18 17:13:58,976] {processor.py:161} INFO - Processing /opt/airflow/dags/dbConnector.py took 0.262 seconds
[2022-08-18 17:14:30,992] {processor.py:153} INFO - Started process (PID=3265) to work on /opt/airflow/dags/dbConnector.py
[2022-08-18 17:14:30,998] {processor.py:641} INFO - Processing file /opt/airflow/dags/dbConnector.py for tasks to queue
[2022-08-18 17:14:30,998] {logging_mixin.py:115} INFO - [2022-08-18 17:14:30,998] {dagbag.py:508} INFO - Filling up the DagBag from /opt/airflow/dags/dbConnector.py
[2022-08-18 17:14:31,235] {processor.py:653} WARNING - No viable dags retrieved from /opt/airflow/dags/dbConnector.py
[2022-08-18 17:14:31,254] {processor.py:161} INFO - Processing /opt/airflow/dags/dbConnector.py took 0.266 seconds
[2022-08-18 17:15:01,336] {processor.py:153} INFO - Started process (PID=3285) to work on /opt/airflow/dags/dbConnector.py
[2022-08-18 17:15:01,350] {processor.py:641} INFO - Processing file /opt/airflow/dags/dbConnector.py for tasks to queue
[2022-08-18 17:15:01,351] {logging_mixin.py:115} INFO - [2022-08-18 17:15:01,351] {dagbag.py:508} INFO - Filling up the DagBag from /opt/airflow/dags/dbConnector.py
[2022-08-18 17:15:01,548] {processor.py:653} WARNING - No viable dags retrieved from /opt/airflow/dags/dbConnector.py
[2022-08-18 17:15:01,564] {processor.py:161} INFO - Processing /opt/airflow/dags/dbConnector.py took 0.232 seconds
[2022-08-18 17:16:44,769] {processor.py:153} INFO - Started process (PID=51) to work on /opt/airflow/dags/dbConnector.py
[2022-08-18 17:16:44,782] {processor.py:641} INFO - Processing file /opt/airflow/dags/dbConnector.py for tasks to queue
[2022-08-18 17:16:44,782] {logging_mixin.py:115} INFO - [2022-08-18 17:16:44,782] {dagbag.py:508} INFO - Filling up the DagBag from /opt/airflow/dags/dbConnector.py
[2022-08-18 17:16:46,951] {processor.py:653} WARNING - No viable dags retrieved from /opt/airflow/dags/dbConnector.py
[2022-08-18 17:16:46,960] {processor.py:161} INFO - Processing /opt/airflow/dags/dbConnector.py took 2.194 seconds
[2022-08-18 17:17:17,209] {processor.py:153} INFO - Started process (PID=75) to work on /opt/airflow/dags/dbConnector.py
[2022-08-18 17:17:17,223] {processor.py:641} INFO - Processing file /opt/airflow/dags/dbConnector.py for tasks to queue
[2022-08-18 17:17:17,224] {logging_mixin.py:115} INFO - [2022-08-18 17:17:17,224] {dagbag.py:508} INFO - Filling up the DagBag from /opt/airflow/dags/dbConnector.py
[2022-08-18 17:17:18,742] {processor.py:653} WARNING - No viable dags retrieved from /opt/airflow/dags/dbConnector.py
[2022-08-18 17:17:18,762] {processor.py:161} INFO - Processing /opt/airflow/dags/dbConnector.py took 1.557 seconds
[2022-08-18 17:17:48,838] {processor.py:153} INFO - Started process (PID=99) to work on /opt/airflow/dags/dbConnector.py
[2022-08-18 17:17:48,906] {processor.py:641} INFO - Processing file /opt/airflow/dags/dbConnector.py for tasks to queue
[2022-08-18 17:17:48,907] {logging_mixin.py:115} INFO - [2022-08-18 17:17:48,907] {dagbag.py:508} INFO - Filling up the DagBag from /opt/airflow/dags/dbConnector.py
[2022-08-18 17:17:49,248] {processor.py:653} WARNING - No viable dags retrieved from /opt/airflow/dags/dbConnector.py
[2022-08-18 17:17:49,260] {processor.py:161} INFO - Processing /opt/airflow/dags/dbConnector.py took 0.426 seconds
[2022-08-18 17:18:19,602] {processor.py:153} INFO - Started process (PID=136) to work on /opt/airflow/dags/dbConnector.py
[2022-08-18 17:18:19,639] {processor.py:641} INFO - Processing file /opt/airflow/dags/dbConnector.py for tasks to queue
[2022-08-18 17:18:19,640] {logging_mixin.py:115} INFO - [2022-08-18 17:18:19,640] {dagbag.py:508} INFO - Filling up the DagBag from /opt/airflow/dags/dbConnector.py
[2022-08-18 17:18:37,844] {processor.py:653} WARNING - No viable dags retrieved from /opt/airflow/dags/dbConnector.py
[2022-08-18 17:18:37,970] {processor.py:161} INFO - Processing /opt/airflow/dags/dbConnector.py took 18.374 seconds
[2022-08-18 17:19:13,471] {processor.py:153} INFO - Started process (PID=160) to work on /opt/airflow/dags/dbConnector.py
[2022-08-18 17:19:13,555] {processor.py:641} INFO - Processing file /opt/airflow/dags/dbConnector.py for tasks to queue
[2022-08-18 17:19:13,556] {logging_mixin.py:115} INFO - [2022-08-18 17:19:13,555] {dagbag.py:508} INFO - Filling up the DagBag from /opt/airflow/dags/dbConnector.py
[2022-08-18 17:19:44,077] {logging_mixin.py:115} INFO - [2022-08-18 17:19:44,076] {timeout.py:67} ERROR - Process timed out, PID: 160
[2022-08-18 17:19:44,519] {logging_mixin.py:115} INFO - [2022-08-18 17:19:44,078] {dagbag.py:321} ERROR - Failed to import: /opt/airflow/dags/dbConnector.py
Traceback (most recent call last):
  File "/home/airflow/.local/lib/python3.7/site-packages/airflow/models/dagbag.py", line 318, in parse
    loader.exec_module(new_module)
  File "<frozen importlib._bootstrap_external>", line 728, in exec_module
  File "<frozen importlib._bootstrap>", line 219, in _call_with_frames_removed
  File "/opt/airflow/dags/dbConnector.py", line 1, in <module>
    import pandas as pd
  File "/home/airflow/.local/lib/python3.7/site-packages/pandas/__init__.py", line 50, in <module>
    from pandas.core.api import (
  File "/home/airflow/.local/lib/python3.7/site-packages/pandas/core/api.py", line 24, in <module>
    from pandas.core.algorithms import (
  File "/home/airflow/.local/lib/python3.7/site-packages/pandas/core/algorithms.py", line 75, in <module>
    from pandas.core.array_algos.take import take_nd
  File "/home/airflow/.local/lib/python3.7/site-packages/pandas/core/array_algos/take.py", line 25, in <module>
    from pandas.core.construction import ensure_wrapped_if_datetimelike
  File "<frozen importlib._bootstrap>", line 983, in _find_and_load
  File "<frozen importlib._bootstrap>", line 967, in _find_and_load_unlocked
  File "<frozen importlib._bootstrap>", line 677, in _load_unlocked
  File "<frozen importlib._bootstrap_external>", line 724, in exec_module
  File "<frozen importlib._bootstrap_external>", line 818, in get_code
  File "<frozen importlib._bootstrap_external>", line 917, in get_data
  File "/home/airflow/.local/lib/python3.7/site-packages/airflow/utils/timeout.py", line 68, in handle_timeout
    raise AirflowTaskTimeout(self.error_message)
airflow.exceptions.AirflowTaskTimeout: DagBag import timeout for /opt/airflow/dags/dbConnector.py after 30.0s.
Please take a look at these docs to improve your DAG import time:
* https://airflow.apache.org/docs/apache-airflow/2.3.3/best-practices.html#top-level-python-code
* https://airflow.apache.org/docs/apache-airflow/2.3.3/best-practices.html#reducing-dag-complexity, PID: 160
[2022-08-18 17:19:44,520] {processor.py:653} WARNING - No viable dags retrieved from /opt/airflow/dags/dbConnector.py
[2022-08-18 17:19:44,727] {processor.py:161} INFO - Processing /opt/airflow/dags/dbConnector.py took 31.548 seconds
[2022-08-18 17:20:15,150] {processor.py:153} INFO - Started process (PID=202) to work on /opt/airflow/dags/dbConnector.py
[2022-08-18 17:20:15,158] {processor.py:641} INFO - Processing file /opt/airflow/dags/dbConnector.py for tasks to queue
[2022-08-18 17:20:15,159] {logging_mixin.py:115} INFO - [2022-08-18 17:20:15,159] {dagbag.py:508} INFO - Filling up the DagBag from /opt/airflow/dags/dbConnector.py
[2022-08-18 17:20:15,569] {processor.py:653} WARNING - No viable dags retrieved from /opt/airflow/dags/dbConnector.py
[2022-08-18 17:20:15,701] {processor.py:161} INFO - Processing /opt/airflow/dags/dbConnector.py took 0.556 seconds
[2022-08-18 17:20:45,812] {processor.py:153} INFO - Started process (PID=235) to work on /opt/airflow/dags/dbConnector.py
[2022-08-18 17:20:45,849] {processor.py:641} INFO - Processing file /opt/airflow/dags/dbConnector.py for tasks to queue
[2022-08-18 17:20:45,851] {logging_mixin.py:115} INFO - [2022-08-18 17:20:45,851] {dagbag.py:508} INFO - Filling up the DagBag from /opt/airflow/dags/dbConnector.py
[2022-08-18 17:20:46,086] {processor.py:653} WARNING - No viable dags retrieved from /opt/airflow/dags/dbConnector.py
[2022-08-18 17:20:46,105] {processor.py:161} INFO - Processing /opt/airflow/dags/dbConnector.py took 0.297 seconds
[2022-08-18 17:21:16,768] {processor.py:153} INFO - Started process (PID=259) to work on /opt/airflow/dags/dbConnector.py
[2022-08-18 17:21:16,782] {processor.py:641} INFO - Processing file /opt/airflow/dags/dbConnector.py for tasks to queue
[2022-08-18 17:21:16,783] {logging_mixin.py:115} INFO - [2022-08-18 17:21:16,783] {dagbag.py:508} INFO - Filling up the DagBag from /opt/airflow/dags/dbConnector.py
[2022-08-18 17:21:16,997] {processor.py:653} WARNING - No viable dags retrieved from /opt/airflow/dags/dbConnector.py
[2022-08-18 17:21:17,014] {processor.py:161} INFO - Processing /opt/airflow/dags/dbConnector.py took 0.250 seconds
[2022-08-18 17:21:47,047] {processor.py:153} INFO - Started process (PID=292) to work on /opt/airflow/dags/dbConnector.py
[2022-08-18 17:21:47,085] {processor.py:641} INFO - Processing file /opt/airflow/dags/dbConnector.py for tasks to queue
[2022-08-18 17:21:47,086] {logging_mixin.py:115} INFO - [2022-08-18 17:21:47,086] {dagbag.py:508} INFO - Filling up the DagBag from /opt/airflow/dags/dbConnector.py
[2022-08-18 17:21:47,342] {processor.py:653} WARNING - No viable dags retrieved from /opt/airflow/dags/dbConnector.py
[2022-08-18 17:21:47,355] {processor.py:161} INFO - Processing /opt/airflow/dags/dbConnector.py took 0.313 seconds
[2022-08-18 17:22:17,436] {processor.py:153} INFO - Started process (PID=321) to work on /opt/airflow/dags/dbConnector.py
[2022-08-18 17:22:17,452] {processor.py:641} INFO - Processing file /opt/airflow/dags/dbConnector.py for tasks to queue
[2022-08-18 17:22:17,452] {logging_mixin.py:115} INFO - [2022-08-18 17:22:17,452] {dagbag.py:508} INFO - Filling up the DagBag from /opt/airflow/dags/dbConnector.py
[2022-08-18 17:22:17,691] {processor.py:653} WARNING - No viable dags retrieved from /opt/airflow/dags/dbConnector.py
[2022-08-18 17:22:17,707] {processor.py:161} INFO - Processing /opt/airflow/dags/dbConnector.py took 0.275 seconds
[2022-08-18 17:25:00,245] {processor.py:153} INFO - Started process (PID=51) to work on /opt/airflow/dags/dbConnector.py
[2022-08-18 17:25:00,316] {processor.py:641} INFO - Processing file /opt/airflow/dags/dbConnector.py for tasks to queue
[2022-08-18 17:25:00,316] {logging_mixin.py:115} INFO - [2022-08-18 17:25:00,316] {dagbag.py:508} INFO - Filling up the DagBag from /opt/airflow/dags/dbConnector.py
[2022-08-18 17:25:01,554] {processor.py:653} WARNING - No viable dags retrieved from /opt/airflow/dags/dbConnector.py
[2022-08-18 17:25:01,565] {processor.py:161} INFO - Processing /opt/airflow/dags/dbConnector.py took 1.323 seconds
[2022-08-18 17:25:31,871] {processor.py:153} INFO - Started process (PID=79) to work on /opt/airflow/dags/dbConnector.py
[2022-08-18 17:25:31,873] {processor.py:641} INFO - Processing file /opt/airflow/dags/dbConnector.py for tasks to queue
[2022-08-18 17:25:31,874] {logging_mixin.py:115} INFO - [2022-08-18 17:25:31,874] {dagbag.py:508} INFO - Filling up the DagBag from /opt/airflow/dags/dbConnector.py
[2022-08-18 17:25:32,152] {processor.py:653} WARNING - No viable dags retrieved from /opt/airflow/dags/dbConnector.py
[2022-08-18 17:25:32,173] {processor.py:161} INFO - Processing /opt/airflow/dags/dbConnector.py took 0.307 seconds
[2022-08-18 17:26:02,281] {processor.py:153} INFO - Started process (PID=113) to work on /opt/airflow/dags/dbConnector.py
[2022-08-18 17:26:02,323] {processor.py:641} INFO - Processing file /opt/airflow/dags/dbConnector.py for tasks to queue
[2022-08-18 17:26:02,324] {logging_mixin.py:115} INFO - [2022-08-18 17:26:02,323] {dagbag.py:508} INFO - Filling up the DagBag from /opt/airflow/dags/dbConnector.py
[2022-08-18 17:26:02,557] {processor.py:653} WARNING - No viable dags retrieved from /opt/airflow/dags/dbConnector.py
[2022-08-18 17:26:02,571] {processor.py:161} INFO - Processing /opt/airflow/dags/dbConnector.py took 0.294 seconds
[2022-08-18 17:26:32,598] {processor.py:153} INFO - Started process (PID=146) to work on /opt/airflow/dags/dbConnector.py
[2022-08-18 17:26:32,606] {processor.py:641} INFO - Processing file /opt/airflow/dags/dbConnector.py for tasks to queue
[2022-08-18 17:26:32,606] {logging_mixin.py:115} INFO - [2022-08-18 17:26:32,606] {dagbag.py:508} INFO - Filling up the DagBag from /opt/airflow/dags/dbConnector.py
[2022-08-18 17:26:32,827] {processor.py:653} WARNING - No viable dags retrieved from /opt/airflow/dags/dbConnector.py
[2022-08-18 17:26:32,839] {processor.py:161} INFO - Processing /opt/airflow/dags/dbConnector.py took 0.243 seconds
[2022-08-18 17:27:02,864] {processor.py:153} INFO - Started process (PID=174) to work on /opt/airflow/dags/dbConnector.py
[2022-08-18 17:27:02,874] {processor.py:641} INFO - Processing file /opt/airflow/dags/dbConnector.py for tasks to queue
[2022-08-18 17:27:02,875] {logging_mixin.py:115} INFO - [2022-08-18 17:27:02,875] {dagbag.py:508} INFO - Filling up the DagBag from /opt/airflow/dags/dbConnector.py
[2022-08-18 17:27:03,089] {processor.py:653} WARNING - No viable dags retrieved from /opt/airflow/dags/dbConnector.py
[2022-08-18 17:27:03,101] {processor.py:161} INFO - Processing /opt/airflow/dags/dbConnector.py took 0.242 seconds
