[2022-08-18 16:43:35,183] {taskinstance.py:1179} INFO - Dependencies all met for <TaskInstance: Satellite_Data.load_data manual__2022-08-18T16:43:27.921731+00:00 [queued]>
[2022-08-18 16:43:35,196] {taskinstance.py:1179} INFO - Dependencies all met for <TaskInstance: Satellite_Data.load_data manual__2022-08-18T16:43:27.921731+00:00 [queued]>
[2022-08-18 16:43:35,196] {taskinstance.py:1376} INFO - 
--------------------------------------------------------------------------------
[2022-08-18 16:43:35,196] {taskinstance.py:1377} INFO - Starting attempt 1 of 2
[2022-08-18 16:43:35,196] {taskinstance.py:1378} INFO - 
--------------------------------------------------------------------------------
[2022-08-18 16:43:35,222] {taskinstance.py:1397} INFO - Executing <Task(PythonOperator): load_data> on 2022-08-18 16:43:27.921731+00:00
[2022-08-18 16:43:35,230] {standard_task_runner.py:52} INFO - Started process 1848 to run task
[2022-08-18 16:43:35,233] {standard_task_runner.py:79} INFO - Running: ['***', 'tasks', 'run', 'Satellite_Data', 'load_data', 'manual__2022-08-18T16:43:27.921731+00:00', '--job-id', '79', '--raw', '--subdir', 'DAGS_FOLDER/data_loader.py', '--cfg-path', '/tmp/tmpn_qau0e9', '--error-file', '/tmp/tmpbszsxp78']
[2022-08-18 16:43:35,234] {standard_task_runner.py:80} INFO - Job 79: Subtask load_data
[2022-08-18 16:43:35,307] {task_command.py:371} INFO - Running <TaskInstance: Satellite_Data.load_data manual__2022-08-18T16:43:27.921731+00:00 [running]> on host b4db7d4790c9
[2022-08-18 16:43:35,480] {taskinstance.py:1591} INFO - Exporting the following env vars:
AIRFLOW_CTX_DAG_OWNER=***
AIRFLOW_CTX_DAG_ID=Satellite_Data
AIRFLOW_CTX_TASK_ID=load_data
AIRFLOW_CTX_EXECUTION_DATE=2022-08-18T16:43:27.921731+00:00
AIRFLOW_CTX_TRY_NUMBER=1
AIRFLOW_CTX_DAG_RUN_ID=manual__2022-08-18T16:43:27.921731+00:00
[2022-08-18 16:43:35,481] {taskinstance.py:1909} ERROR - Task failed with exception
Traceback (most recent call last):
  File "/home/airflow/.local/lib/python3.7/site-packages/airflow/operators/python.py", line 171, in execute
    return_value = self.execute_callable()
  File "/home/airflow/.local/lib/python3.7/site-packages/airflow/operators/python.py", line 189, in execute_callable
    return self.python_callable(*self.op_args, **self.op_kwargs)
TypeError: load_into_database() missing 1 required positional argument: 'data'
[2022-08-18 16:43:35,490] {taskinstance.py:1420} INFO - Marking task as UP_FOR_RETRY. dag_id=Satellite_Data, task_id=load_data, execution_date=20220818T164327, start_date=20220818T164335, end_date=20220818T164335
[2022-08-18 16:43:35,542] {standard_task_runner.py:97} ERROR - Failed to execute job 79 for task load_data (load_into_database() missing 1 required positional argument: 'data'; 1848)
[2022-08-18 16:43:35,565] {local_task_job.py:156} INFO - Task exited with return code 1
[2022-08-18 16:43:35,680] {local_task_job.py:273} INFO - 0 downstream tasks scheduled from follow-on schedule check
